Workbook
Name AuditFailsCommercial: [1]Audit!$G$12
Name AuditFailsStructural: [1]Audit!$G$11
Name AuditOK: [1]Audit!$G$13

Sheet APP
A2: =Study!CF1 -> القالب الموحّد الشامل لبنود دراسة الجدوى | Master Feasibility Template | B2: =Study!CG1 -> 0 | C2: =Study!CH1 -> 0 | D2: =Study!CI1 -> 0 | E2: =Study!CJ1 -> 0 | F2: =Study!CK1 -> 0
A3: =Study!CF2 -> قالب ثابت يشمل كل المكوّنات والأقسام (حتى الفارغة) | مراجع حية داخل ورقة Study | B3: =Study!CG2 -> 0 | C3: =Study!CH2 -> 0 | D3: =Study!CI2 -> 0 | E3: =Study!CJ2 -> 0 | F3: =Study!CK2 -> 0
A4: =Study!CF3 -> 0 | B4: =Study!CG3 -> 0 | C4: =Study!CH3 -> 0 | D4: =Study!CI3 -> 0 | E4: =Study!CJ3 -> 0 | F4: =Study!CK3 -> 0
A5: =Study!CF4 -> # | B5: =Study!CG4 -> اسم البند | C5: =Study!CH4 -> الناتج | D5: =Study!CI4 -> الفئة | E5: =Study!CJ4 -> مصدر الخلية | F5: =Study!CK4 -> ملاحظة / الوحدة
A6: =Study!CF5 -> ▌ معلومات المشروع | B6: =Study!CG5 -> 0 | C6: =Study!CH5 -> 0 | D6: =Study!CI5 -> 0 | E6: =Study!CJ5 -> 0 | F6: =Study!CK5 -> 0
A7: =Study!CF6 -> 1 | B7: =Study!CG6 -> اسم المشروع | C7: درة الغدير | D7: =Study!CI6 -> معلومات المشروع | E7: =Study!CJ6 -> F2 | F7: =Study!CK6 -> هوية المشروع
A8: =Study!CF7 -> 2 | B8: =Study!CG7 -> موقع المشروع | C8: الرياض | D8: =Study!CI7 -> معلومات المشروع | E8: =Study!CJ7 -> F3 | F8: =Study!CK7 -> 0
A9: =Study!CF8 -> ▌ ملخص الدراسة | B9: =Study!CG8 -> 0 | C9: =Study!CH8 -> 0 | D9: =Study!CI8 -> 0 | E9: =Study!CJ8 -> 0 | F9: =Study!CK8 -> 0
A10: =Study!CF9 -> 3 | B10: =Study!CG9 -> إجمالي الإيرادات | C10: =Study!CH9 -> 3.1318259e+08 | D10: =Study!CI9 -> ملخص الدراسة | E10: =Study!CJ9 -> C17 | F10: =Study!CK9 -> ريال سعودي
A11: =Study!CF10 -> 4 | B11: =Study!CG10 -> إجمالي تكلفة الأرض | C11: =Study!CH10 -> 91847824 | D11: =Study!CI10 -> ملخص الدراسة | E11: =Study!CJ10 -> C18 | F11: =Study!CK10 -> ريال سعودي
A12: =Study!CF11 -> 5 | B12: =Study!CG11 -> إجمالي تكلفة البناء | C12: =Study!CH11 -> 78265608 | D12: =Study!CI11 -> ملخص الدراسة | E12: =Study!CJ11 -> C19 | F12: =Study!CK11 -> ريال سعودي
A13: =Study!CF12 -> 6 | B13: =Study!CG12 -> إجمالي التكاليف الأخرى | C13: =Study!CH12 -> 21170058 | D13: =Study!CI12 -> ملخص الدراسة | E13: =Study!CJ12 -> C20 | F13: =Study!CK12 -> ريال سعودي
A14: =Study!CF13 -> 7 | B14: =Study!CG13 -> إجمالي رسوم الصندوق | C14: =Study!CH13 -> 22314657 | D14: =Study!CI13 -> ملخص الدراسة | E14: =Study!CJ13 -> C21 | F14: =Study!CK13 -> ريال سعودي
A15: =Study!CF14 -> 8 | B15: =Study!CG14 -> فوائد التمويل | C15: =Study!CH14 -> 7141903.3 | D15: =Study!CI14 -> ملخص الدراسة | E15: =Study!CJ14 -> C22 | F15: =Study!CK14 -> ريال سعودي
A16: =Study!CF15 -> 9 | B16: =Study!CG15 -> التمويل البنكي | C16: =Study!CH15 -> 0 | D16: =Study!CI15 -> ملخص الدراسة | E16: =Study!CJ15 -> C23 | F16: =Study!CK15 -> ريال سعودي
A17: =Study!CF16 -> 10 | B17: =Study!CG16 -> إجمالي التكاليف الرأسمالية (CapEx) | C17: =Study!CH16 -> 2.2074005e+08 | D17: =Study!CI16 -> ملخص الدراسة | E17: =Study!CJ16 -> C24 | F17: =Study!CK16 -> ريال سعودي
A18: =Study!CF17 -> 11 | B18: =Study!CG17 -> إجمالي التكاليف التشغيلية (OpEx) | C18: =Study!CH17 -> 6529315.6 | D18: =Study!CI17 -> ملخص الدراسة | E18: =Study!CJ17 -> C25 | F18: =Study!CK17 -> ريال سعودي
A19: =Study!CF18 -> 12 | B19: =Study!CG18 -> صافي الدخل | C19: =Study!CH18 -> 85913221 | D19: =Study!CI18 -> ملخص الدراسة | E19: =Study!CJ18 -> C26 | F19: =Study!CK18 -> ريال سعودي
A20: =Study!CF19 -> 13 | B20: =Study!CG19 -> مدة المشروع المتوقعة (سنوات) | C20: =Study!CH19 -> 5 | D20: =Study!CI19 -> ملخص الدراسة | E20: =Study!CJ19 -> C27 | F20: =Study!CK19 -> سنة
... A653: =Study!CF652 -> 576 | B653: =Study!CG652 -> صافي الدخل (تدفقات) | C653: =Study!CH652 -> 85913221 | D653: =Study!CI652 -> التدفقات النقدية | E653: =Study!CJ652 -> C221 | F653: =Study!CK652 -> ريال سعودي
A654: =Study!CF653 -> 577 | B654: =Study!CG653 -> الاطار الزمني (ربع سنوي) | C654: =Study!CH653 -> Q1 | D654: =Study!CI653 -> Q2 | E654: =Study!CJ653 -> Q3 | F654: =Study!CK653 -> Q4 | G654: =Study!CL653 -> Q5 | H654: =Study!CM653 -> Q6 | ... Z654: =Study!DE653 -> Q24
A655: =Study!CF654 -> 578 | B655: =Study!CG654 -> التاريخ | C655: =Study!CH654 -> 46388 | D655: =Study!CI654 -> 46478 | E655: =Study!CJ654 -> 46569 | F655: =Study!CK654 -> 46661 | G655: =Study!CL654 -> 46753 | H655: =Study!CM654 -> 46844 | ... Z655: =Study!DE654 -> 48488
A656: =Study!CF655 -> 579 | B656: =Study!CG655 -> الحفر والمسح والاختبار (Excavation, surveying, and testing) | C656: =Study!CH655 -> -89728000 | D656: =Study!CI655 -> 0 | E656: =Study!CJ655 -> 0 | F656: =Study!CK655 -> 0 | G656: =Study!CL655 -> 0 | H656: =Study!CM655 -> 0 | ... Z656: =Study!DE655 -> 0
A657: =Study!CF656 -> 580 | B657: =Study!CG656 -> أثاث الوحدات الفندقية (Apartment furniture) | C657: =Study!CH656 -> 0 | D657: =Study!CI656 -> 0 | E657: =Study!CJ656 -> -945120 | F657: =Study!CK656 -> -945120 | G657: =Study!CL656 -> -945120 | H657: =Study!CM656 -> 0 | ... Z657: =Study!DE656 -> 0
A658: =Study!CF657 -> 581 | B658: =Study!CG657 -> رسوم الماء وصرف الصحي (Water and sewer fees) | C658: =Study!CH657 -> -652213.4 | D658: =Study!CI657 -> -652213.4 | E658: =Study!CJ657 -> -652213.4 | F658: =Study!CK657 -> -652213.4 | G658: =Study!CL657 -> -652213.4 | H658: =Study!CM657 -> -652213.4 | ... Z658: =Study!DE657 -> 0
A659: =Study!CF658 -> 582 | B659: =Study!CG658 -> الرخصة (License) | C659: =Study!CH658 -> 0 | D659: =Study!CI658 -> 0 | E659: =Study!CJ658 -> 0 | F659: =Study!CK658 -> 0 | G659: =Study!CL658 -> 0 | H659: =Study!CM658 -> -5478592.6 | ... Z659: =Study!DE658 -> 0
A660: =Study!CF659 -> 583 | B660: =Study!CG659 -> الايراد (Revenue) | C660: =Study!CH659 -> 0 | D660: =Study!CI659 -> 0 | E660: =Study!CJ659 -> 0 | F660: =Study!CK659 -> 0 | G660: =Study!CL659 -> 0 | H660: =Study!CM659 -> 0 | ... Z660: =Study!DE659 -> 0
A661: =Study!CF660 -> 584 | B661: =Study!CG660 -> ضريبة التصرفات العقارية + السعي + ضريبة السعي - (RETT + Commission + Commission tax) | C661: =Study!CH660 -> 0 | D661: =Study!CI660 -> 0 | E661: =Study!CJ660 -> 0 | F661: =Study!CK660 -> 0 | G661: =Study!CL660 -> 0 | H661: =Study!CM660 -> 0 | ... Z661: =Study!DE660 -> 0
A662: =Study!CF661 -> 585 | B662: =Study!CG661 -> اجمالي التكاليف | C662: =Study!CH661 -> -97189235 | D662: =Study!CI661 -> -1316551.4 | E662: =Study!CJ661 -> -1719623.4 | F662: =Study!CK661 -> -2261671.4 | G662: =Study!CL661 -> -2266273.2 | H662: =Study!CM661 -> -7827467.3 | ... Z662: =Study!DE661 -> 0
A663: =Study!CF662 -> 586 | B663: =Study!CG662 -> البيع على الخارطة | C663: =Study!CH662 -> 0 | D663: =Study!CI662 -> 0 | E663: =Study!CJ662 -> 0 | F663: =Study!CK662 -> 0 | G663: =Study!CL662 -> 1304347.8 | H663: =Study!CM662 -> 2305043.5 | ... Z663: =Study!DE662 -> 0
A664: =Study!CF663 -> 586 | B664: =Study!CG663 -> اجمالي الايراد | C664: =Study!CH663 -> 0 | D664: =Study!CI663 -> 0 | E664: =Study!CJ663 -> 0 | F664: =Study!CK663 -> 0 | G664: =Study!CL663 -> 0 | H664: =Study!CM663 -> 0 | ... Z664: =Study!DE663 -> 0

Sheet Cover Page
H1: Legal Disclaimer and Warning: This financial model is confidential property of Rasf Investment, and all rights are fully reserved. It has been shared with you for a specific and authorized purpose only. Any copying, sharing, modification, or use of this file for any other purpose without prior written consent from Rasf Investment is strictly prohibited. If such unauthorized use occurs, legal action will be taken against you in a court of law.
A16: تفاصيل الدراسة (Study Details) | I16: درة الغدير - مشروع مختلط (Mix Use Development - RASF - Alghadeer)
D19: ------------------------------------ | L19: ------------------------------------
A20: التاريخ (Date) | I20: 46147
D23: ------------------------------------ | L23: ------------------------------------
A24: محتويات الدراسة (Study Contents) | I24: Study

Sheet Study
CF1: القالب الموحّد الشامل لبنود دراسة الجدوى | Master Feasibility Template
AE2: توزيع تكاليف المشروع على مكونات البيع المباشر و التأجير السنوي و اليومي | BH2: جدول المؤشرات العامة للمشروع | General Project Indicators Table | BL2: الحدود المرجعية أو المثلى للمؤشرات (Reference Ranges for Indicators) | BN2: سعر المتر بناءً على فترة الاسترداد - (التأجير السنوي) | BQ2: سعر المتر بناءً على فترة الاسترداد - (التأجير اليومي) | BV2: اسم المشروع | BW2: برج جدة | CA2: حالة المشروع | CB2: تاريخ الانتهاء المتوقع | CF2: قالب ثابت يشمل كل المكوّنات والأقسام (حتى الفارغة) | مراجع حية داخل ورقة Study
AE3: المكون | AF3: توزيع تكاليف الأرض | AG3: جزء من تكاليف البناء | AH3: نسبة توزيع تكاليف اللاندسكيب | AI3: توزيع تكاليف اللاندسكيب | AJ3: توزيع تكاليف البوديم و القبو | AK3: توزيع تكاليف الحفر والمسح و الاختبار | AL3: توزيع تكاليف المساحات الحركية والخدمية | AM3: نسب التكاليف السابقة من التكاليف الموجودة بالجدول | AN3: نسب التكاليف السابقة من التكاليف الكلية | AO3: نسب المكون من البيع المباشر أو المخارجة من الإجمالي | AP3: توزيع التكاليف الأخرى | AQ3: توزيع تكاليف أخرى إضافية | AR3: توزيع تكاليف التمويل | AS3: توزيع تكاليف الصندوق | AT3: توزيع التكاليف التشغيلية | AU3: إجمالي تكاليف كل مكون | AV3: توزيع التكلفة على الأمتار البيعية | AW3: نسبة تكاليف كل مكون من إجمالي المشروع | AX3: إجمالي إيراد كل مكون | AY3: صافي العائد لكل م² بيعي | AZ3: صافي دخل كل مكون | BA3: العائد النسبي للمكون | BB3: هامش الربح من إجمالي الإرادات | BC3: نسبة صافي دخل كل مكون من إجمالي صافي دخل المشروع | BD3: نسبة صافي دخل كل مكون | BN3: المكون (Component) | BO3: سعر المتر | BP3: فترة الأسترداد - بالسنوات | BQ3: المكون (Component) | BR3: سعر المتر | BS3: فترة الأسترداد - بالسنوات | BV3: اسم الصندوق (fund Name) | BW3: إتقان | CA3: مرحلة توقيع العقود | CB3: ?
AE4: سكني | AF4: =I45 -> 15362564 | AG4: =J61*AO4 -> 7800408 | AH4: 0 | AI4: =($J$73*AH4)*AO4 -> 0 | AL4: =(((D61-F61)/$I$59)*$J$71)*AO4 -> 0 | AM4: =SUM(AF4:AG4,AI4:AL4)/$AM$14 -> 0.14502019 | AN4: =SUM(AF4:AG4,AI4:AL4)/$AN$14 -> 0.11361589 | AO4: =D129 -> 1 | AP4: =(AN4*SUM($C$86,$C$88:$C$89,$C$96:$C$97))+((H147+X147)/($H$157+$X$157))*$C$99+(SUM($D$93:$D$95)*G61*AO4) -> 749188.5 | AQ4: =(($A$92+$C$98)*AM4)+((C90+C101)*15%) -> 887297.5 | AR4: =AM4*$C$119 -> 1035720.2 | AS4: =AN4*$C$107 -> 2535299.6 | AT4: =SUM(I147,Y147) -> 123565.55 | AU4: =SUM(AF4:AG4,AI4:AL4,AP4:AT4) -> 28494043 | AV4: =IFERROR((AU4-AT4)/E129, "0") -> 9413.5425 | AW4: =(AU4-AT4)/($C$23) -> 0.12852438 | AX4: =SUM(J129,H147,O129,X147) -> 31818130 | AY4: =IFERROR(AZ4/E129, "0.00") -> 1102.9575 | AZ4: =AX4-AU4 -> 3324086.8 | BA4: =IFERROR(BD4/AW4, "0.00") -> 0.91163333 | BB4: =IFERROR(AZ4/AX4, "0.00%") -> 0.10447147 | BC4: =AZ4/$C$25 -> 0.038691214 | BD4: =IFERROR(AZ4/(AU4-AT4), "0.00%") -> 0.11716711 | BE4: سكني | BN4: سكني (Apartments) | BO4: =IFERROR((AU4-AT4) / (C147 * D147 * G147 * (1 - $I$158) * BP4), 0) -> 0 | BQ4: سكني (Apartments) | BR4: =IFERROR((AU4-AT4) / ((R147 * S147 * (1 - $Y$158) * 365 * BS4) * (1 + W147)), 0) -> 0 | BV4: =B19 -> إجمالي تكلفة البناء (Total Construction Cost) | BW4: =J76 -> 78265608 | CF4: # | CG4: اسم البند | CH4: الناتج | CI4: الفئة | CJ4: مصدر الخلية | CK4: ملاحظة / الوحدة
AE5: فلل | AF5: =I46 -> 27351260 | AG5: =J62*AO5 -> 0 | AH5: 0 | AI5: =($J$73*AH5)*AO5 -> 0 | AJ5: =((K62/$L$76)*($J$74+$J$75))*AO5 -> 0 | AK5: =((K62/$L$76)*$C$87)*AO5 -> 0 | AL5: =(((D62-F62)/$I$59)*$J$71)*AO5 -> 0 | AM5: =SUM(AF5:AG5,AI5:AL5)/$AM$14 -> 0.17124249 | AN5: =SUM(AF5:AG5,AI5:AL5)/$AN$14 -> 0.13415971 | AO5: =D130 -> 0 | AP5: =(AN5*SUM($C$86,$C$88:$C$89,$C$96:$C$97))+((H148+X148)/($H$157+$X$157))*$C$99+(SUM($D$93:$D$95)*G62*AO5) -> 456192.67 | AQ5: =(($A$92+$C$98)*AM5)+((C90+C101)*15%) -> 888528.77 | AR5: =AM5*$C$119 -> 1222997.3 | AS5: =AN5*$C$107 -> 2993728 | AT5: =SUM(I148,Y148) -> 0 | AU5: =SUM(AF5:AG5,AI5:AL5,AP5:AT5) -> 32912707 | AV5: =IFERROR((AU5-AT5)/E130, "0") -> 9854.1038 | AW5: =(AU5-AT5)/($C$23) -> 0.14910165 | AX5: =SUM(J130,H148,O130,X148) -> 0 | AY5: =IFERROR(AZ5/E130, "0.00") -> -9854.1038 | AZ5: =AX5-AU5 -> -32912707 | BA5: =IFERROR(BD5/AW5, "0.00") -> -6.7068337 | BB5: =IFERROR(AZ5/AX5, "0.00%") -> 0.00% | BC5: =AZ5/$C$25 -> -0.38309246 | BD5: =IFERROR(AZ5/(AU5-AT5), "0.00%") -> -1 | BE5: فلل | BH5: مؤشرات التكاليف والكفاءة (Costs & Efficiency Indicators) | BN5: فلل (Villas) | BO5: =IFERROR((AU5-AT5) / (C148 * D148 * G148 * (1 - $I$158) * BP5), 0) -> 0 | BQ5: فلل (Villas) | BR5: =IFERROR((AU5-AT5) / ((R148 * S148 * (1 - $Y$158) * 365 * BS5) * (1 + W148)), 0) -> 0 | BV5: =B23 -> إجمالي التكاليف الرأسمالية للمشروع (Total Capital Expenditures) | BW5: =C23 -> 2.2074005e+08 | CF5: ▌ معلومات المشروع
AE6: تاون هاوس | AF6: =((F63/$J$59)*$I$49)*AO6 -> 0 | AG6: =J63*AO6 -> 0 | AH6: 0 | AI6: =($J$73*AH6)*AO6 -> 0 | AJ6: =((K63/$L$76)*($J$74+$J$75))*AO6 -> 0 | AK6: =((K63/$L$76)*$C$87)*AO6 -> 0 | AL6: =(((D63-F63)/$I$59)*$J$71)*AO6 -> 0 | AM6: =SUM(AF6:AG6,AI6:AL6)/$AM$14 -> 0 | AN6: =SUM(AF6:AG6,AI6:AL6)/$AN$14 -> 0 | AO6: =D131 -> 1 | AP6: =(AN6*SUM($C$86,$C$88:$C$90,$C$96:$C$97,$C$101))+((H149+X149)/($H$157+$X$157))*$C$99+(SUM($D$93:$D$95)*G63*AO6) -> 0 | AQ6: =(($A$92+$C$98)*AM6) -> 0 | AR6: =AM6*$C$119 -> 0 | AS6: =AN6*$C$107 -> 0 | AT6: =SUM(I149,Y149) -> 0 | AU6: =SUM(AF6:AG6,AI6:AL6,AP6:AT6) -> 0 | AV6: =IFERROR((AU6-AT6)/E131, "0") -> 0 | AW6: =(AU6-AT6)/($C$23) -> 0 | AX6: =SUM(J131,H149,O131,X149) -> 0 | AY6: =IFERROR(AZ6/E131, "0.00") -> 0.00 | AZ6: =AX6-AU6 -> 0 | BA6: =IFERROR(BD6/AW6, "0.00") -> 0.00 | BB6: =IFERROR(AZ6/AX6, "0.00%") -> 0.00% | BC6: =AZ6/$C$25 -> 0 | BD6: =IFERROR(AZ6/(AU6-AT6), "0.00%") -> 0.00% | BE6: تاون هاوس | BH6: التكلفة لكل م² من إجمالي المساحات التطويرية (Cost per m² of Total Built-Up Area) | BI6: =C23/G59 -> 6941.5896 | BL6: - | BN6: تاون هاوس (Townhouse) | BO6: =IFERROR((AU6-AT6) / (C149 * D149 * G149 * (1 - $I$158) * BP6), 0) -> 0 | BQ6: تاون هاوس (Townhouse) | BR6: =IFERROR((AU6-AT6) / ((R149 * S149 * (1 - $Y$158) * 365 * BS6) * (1 + W149)), 0) -> 0 | BV6: =B17 -> إجمالي الإيرادات (Total Revenue) | BW6: =C17 -> 3.1318259e+08 | CF6: 1 | CG6: اسم المشروع | CH6: =F2 -> 0 | CI6: معلومات المشروع | CJ6: F2 | CK6: هوية المشروع
AE7: أدوار | AF7: =((F64/$J$59)*$I$49)*AO7 -> 0 | AG7: =J64*AO7 -> 0 | AH7: 0 | AI7: =($J$73*AH7)*AO7 -> 0 | AJ7: =((K64/$L$76)*($J$74+$J$75))*AO7 -> 0 | AK7: =((K64/$L$76)*$C$87)*AO7 -> 0 | AL7: =(((D64-F64)/$I$59)*$J$71)*AO7 -> 0 | AM7: =SUM(AF7:AG7,AI7:AL7)/$AM$14 -> 0 | AN7: =SUM(AF7:AG7,AI7:AL7)/$AN$14 -> 0 | AO7: =D132 -> 1 | AP7: =(AN7*SUM($C$86,$C$88:$C$90,$C$96:$C$97,$C$101))+((H150+X150)/($H$157+$X$157))*$C$99+(SUM($D$93:$D$95)*G64*AO7) -> 0 | AQ7: =(($A$92+$C$98)*AM7) -> 0 | AR7: =AM7*$C$119 -> 0 | AS7: =AN7*$C$107 -> 0 | AT7: =SUM(I150,Y150) -> 0 | AU7: =SUM(AF7:AG7,AI7:AL7,AP7:AT7) -> 0 | AV7: =IFERROR((AU7-AT7)/E132, "0") -> 0 | AW7: =(AU7-AT7)/($C$23) -> 0 | AX7: =SUM(J132,H150,O132,X150) -> 0 | AY7: =IFERROR(AZ7/E132, "0.00") -> 0.00 | AZ7: =AX7-AU7 -> 0 | BA7: =IFERROR(BD7/AW7, "0.00") -> 0.00 | BB7: =IFERROR(AZ7/AX7, "0.00%") -> 0.00% | BC7: =AZ7/$C$25 -> 0 | BD7: =IFERROR(AZ7/(AU7-AT7), "0.00%") -> 0.00% | BE7: أدوار | BH7: التكلفة لكل م² من إجمالي المساحات القابلة للبيع (Cost per m² of Saleable Area) | BI7: =C23/J59 -> 22250.24 | BL7: - | BN7: أدوار (Floors) | BO7: =IFERROR((AU7-AT7) / (C150 * D150 * G150 * (1 - $I$158) * BP7), 0) -> 0 | BQ7: أدوار (Floors) | BR7: =IFERROR((AU7-AT7) / ((R150 * S150 * (1 - $Y$158) * 365 * BS7) * (1 + W150)), 0) -> 0 | BV7: =B34 -> العائد على الملكية السنوي (ROE Annually) | BW7: =C32 -> 0.7924872 | CF7: 2 | CG7: موقع المشروع | CH7: =F3 -> 0 | CI7: معلومات المشروع | CJ7: F3
AE8: أستوديوهات | AF8: =((F65/$J$59)*$I$49)*AO8 -> 0 | AG8: =J65*AO8 -> 0 | AH8: 0 | AI8: =($J$73*AH8)*AO8 -> 0 | AJ8: =((K65/$L$76)*($J$74+$J$75))*AO8 -> 0 | AK8: =((K65/$L$76)*$C$87)*AO8 -> 0 | AL8: =(((D65-F65)/$I$59)*$J$71)*AO8 -> 0 | AM8: =SUM(AF8:AG8,AI8:AL8)/$AM$14 -> 0 | AN8: =SUM(AF8:AG8,AI8:AL8)/$AN$14 -> 0 | AO8: =D133 -> 1 | AP8: =(AN8*SUM($C$86,$C$88:$C$90,$C$96:$C$97,$C$101))+((H151+X151)/($H$157+$X$157))*$C$99+(SUM($D$93:$D$95)*G65*AO8) -> 0 | AQ8: =(($A$92+$C$98)*AM8) -> 0 | AR8: =AM8*$C$119 -> 0 | AS8: =AN8*$C$107 -> 0 | AT8: =SUM(I151,Y151) -> 0 | AU8: =SUM(AF8:AG8,AI8:AL8,AP8:AT8) -> 0 | AV8: =IFERROR((AU8-AT8)/E133, "0") -> 0 | AW8: =(AU8-AT8)/($C$23) -> 0 | AX8: =SUM(J133,H151,O133,X151) -> 0 | AY8: =IFERROR(AZ8/E133, "0.00") -> 0.00 | AZ8: =AX8-AU8 -> 0 | BA8: =IFERROR(BD8/AW8, "0.00") -> 0.00 | BB8: =IFERROR(AZ8/AX8, "0.00%") -> 0.00% | BC8: =AZ8/$C$25 -> 0 | BD8: =IFERROR(AZ8/(AU8-AT8), "0.00%") -> 0.00% | BE8: أستوديوهات | BH8: إجمالي التكاليف الصلبة (Total Hard Costs) | BI8: =-SUM(C196:C198,C202:C203) -> 87785008 | BJ8: =BI8/($C$23+$C$24) -> 0.38625975 | BL8: - | BN8: أستوديوهات (Studios) | BO8: =IFERROR((AU8-AT8) / (C151 * D151 * G151 * (1 - $I$158) * BP8), 0) -> 0 | BQ8: أستوديوهات (Studios) | BR8: =IFERROR((AU8-AT8) / ((R151 * S151 * (1 - $Y$158) * 365 * BS8) * (1 + W151)), 0) -> 0 | CA8: - | CF8: ▌ ملخص الدراسة
AE9: مكتبي | AF9: =((F66/$J$59)*$I$49)*AO9 -> 0 | AG9: =J66*AO9 -> 0 | AI9: =($J$73*AH9)*AO9 -> 0 | AJ9: =((K66/$L$76)*($J$74+$J$75))*AO9 -> 0 | AK9: =((K66/$L$76)*$C$87)*AO9 -> 0 | AL9: =(((D66-F66)/$I$59)*$J$71)*AO9 -> 0 | AM9: =SUM(AF9:AG9,AI9:AL9)/$AM$14 -> 0 | AN9: =SUM(AF9:AG9,AI9:AL9)/$AN$14 -> 0 | AO9: =D134 -> 1 | AP9: =(AN9*SUM($C$86,$C$88:$C$90,$C$96:$C$97,$C$101))+((H152+X152)/($H$157+$X$157))*$C$99+(SUM($D$93:$D$95)*G66*AO9) -> 0 | AQ9: =(($A$92+$C$98)*AM9) -> 0 | AR9: =AM9*$C$119 -> 0 | AS9: =AN9*$C$107 -> 0 | AT9: =SUM(I152,Y152) -> 0 | AU9: =SUM(AF9:AG9,AI9:AL9,AP9:AT9) -> 0 | AV9: =IFERROR((AU9-AT9)/E134, "0") -> 0 | AW9: =(AU9-AT9)/($C$23) -> 0 | AX9: =SUM(J134,H152,O134,X152) -> 0 | AY9: =IFERROR(AZ9/E134, "0.00") -> 0.00 | AZ9: =AX9-AU9 -> 0 | BA9: =IFERROR(BD9/AW9, "0.00") -> 0.00 | BB9: =IFERROR(AZ9/AX9, "0.00%") -> 0.00% | BC9: =AZ9/$C$25 -> 0 | BD9: =IFERROR(AZ9/(AU9-AT9), "0.00%") -> 0.00% | BE9: مكتبي | BH9: إجمالي التكاليف اللينة (Total Soft Costs) | BI9: =-SUM(C199:C201,C204:C207,C209:C212,C214:C216) -> 32791331 | BJ9: =BI9/($C$23+$C$24) -> 0.14428399 | BL9: - | BN9: مكتبي (Office) | BO9: =IFERROR((AU9-AT9) / (C152 * D152 * G152 * (1 - $I$158) * BP9), 0) -> 0 | BQ9: مكتبي (Office) | BR9: =IFERROR((AU9-AT9) / ((R152 * S152 * (1 - $Y$158) * 365 * BS9) * (1 + W152)), 0) -> 0 | BV9: اشتراكات رصف | BW9: نسبة الحصة | BX9: مبلغ الاشتراك | BY9: الآلية | BZ9: صافي الربح | CA9: مبلغ الاشتراك + صافي الربح | CB9: ملاحظات | CF9: 3 | CG9: إجمالي الإيرادات | CH9: =C17 -> 3.1318259e+08 | CI9: ملخص الدراسة | CJ9: C17 | CK9: ريال سعودي
AE10: تجاري | AF10: =((F67/$J$59)*$I$49)*AO10 -> 0 | AG10: =J67*AO10 -> 0 | AI10: =($J$73*AH10)*AO10 -> 0 | AJ10: =((K67/$L$76)*($J$74+$J$75))*AO10 -> 0 | AK10: =((K67/$L$76)*$C$87)*AO10 -> 0 | AL10: =(((D67-F67)/$I$59)*$J$71)*AO10 -> 0 | AM10: =SUM(AF10:AG10,AI10:AL10)/$AM$14 -> 0 | AN10: =SUM(AF10:AG10,AI10:AL10)/$AN$14 -> 0 | AO10: =D135 -> 1 | AP10: =(AN10*SUM($C$86,$C$88:$C$90,$C$96:$C$97,$C$101))+((H153+X153)/($H$157+$X$157))*$C$99+(SUM($D$93:$D$95)*G67*AO10) -> 0 | AQ10: =(($A$92+$C$98)*AM10) -> 0 | AR10: =AM10*$C$119 -> 0 | AS10: =AN10*$C$107 -> 0 | AT10: =SUM(I153,Y153) -> 0 | AU10: =SUM(AF10:AG10,AI10:AL10,AP10:AT10) -> 0 | AV10: =IFERROR((AU10-AT10)/E135, "0") -> 0 | AW10: =(AU10-AT10)/($C$23) -> 0 | AX10: =SUM(J135,H153,O135,X153) -> 0 | AY10: =IFERROR(AZ10/E135, "0.00") -> 0.00 | AZ10: =AX10-AU10 -> 0 | BA10: =IFERROR(BD10/AW10, "0.00") -> 0.00 | BB10: =IFERROR(AZ10/AX10, "0.00%") -> 0.00% | BC10: =AZ10/$C$25 -> 0 | BD10: =IFERROR(AZ10/(AU10-AT10), "0.00%") -> 0.00% | BE10: تجاري | BH10: إجمالي التكاليف التي لا تندرج كصلبة أو لينة (Total costs that do not fall under hard or soft costs) | BI10: =-SUM(E192:E193,C194:C195,C208,C213) -> 1.0669303e+08 | BJ10: =BI10/($C$23+$C$24) -> 0.46945626 | BL10: - | BN10: تجاري (Retail) | BO10: =IFERROR((AU10-AT10) / (C153 * D153 * G153 * (1 - $I$158) * BP10), 0) -> 0 | BQ10: تجاري (Retail) | BR10: =IFERROR((AU10-AT10) / ((R153 * S153 * (1 - $Y$158) * 365 * BS10) * (1 + W153)), 0) -> 0 | BV10: الحصة العينية من التطوير | BW10: 1 | BX10: =H22*BW10 -> 0 | BY10: استثمار عيني | BZ10: =BX10*$BW$7 -> 0 | CA10: =BZ10+BX10 -> 0 | CB10: - | CF10: 4 | CG10: إجمالي تكلفة الأرض | CH10: =C18 -> 91847824 | CI10: ملخص الدراسة | CJ10: C18 | CK10: ريال سعودي
AE11: فندقي | AF11: =I44 -> 49134000 | AG11: =J68*AO11 -> 36900000 | AH11: 1 | AI11: =($J$73*AH11)*AO11 -> 6162000 | AJ11: =J74 -> 14176800 | AK11: =C87 -> 2835360 | AL11: =(((D68-F68)/$I$59)*$J$71)*AO11 -> 0 | AM11: =SUM(AF11:AG11,AI11:AL11)/$AM$14 -> 0.68373732 | AN11: =SUM(AF11:AG11,AI11:AL11)/$AN$14 -> 0.53567315 | AO11: =D136 -> 1 | AP11: =(AN11*SUM($C$86,$C$88:$C$89,$C$96:$C$97))+((H154+X154)/($H$157+$X$157))*$C$99+((SUM($D$94:$D$95)*G68*AO11)+(D93*G68/2*AO11)) -> 4250586.9 | AQ11: =(((($C$98)*AM11))+C91)+((C90+C101)*70%) -> 10291049 | AR11: =AM11*$C$119 -> 4883185.8 | AS11: =AN11*$C$107 -> 11953363 | AT11: =SUM(I154,Y154) -> 6405750 | AU11: =SUM(AF11:AG11,AI11:AL11,AP11:AT11) -> 1.4699209e+08 | AV11: =IFERROR((AU11-AT11)/E136, "0") -> 39413.049 | AW11: =(AU11-AT11)/($C$23) -> 0.63688644 | AX11: =SUM(J136,H154,O136,X154) -> 2.348775e+08 | AY11: =IFERROR(AZ11/E136, "0.00") -> 24638.465 | AZ11: =AX11-AU11 -> 87885405 | BA11: =IFERROR(BD11/AW11, "0.00") -> 0.98154817 | BB11: =IFERROR(AZ11/AX11, "0.00%") -> 0.3741755 | BC11: =AZ11/$C$25 -> 1.0229555 | BD11: =IFERROR(AZ11/(AU11-AT11), "0.00%") -> 0.62513472 | BE11: فندقي | BH11: إجمالي التكاليف المباشرة (Total Direct Costs) | BI11: =-SUM(C194:C198,C202:C206,C213) -> 1.8807665e+08 | BJ11: =BI11/($C$23+$C$24) -> 0.82754949 | BL11: غالبًا تمثل 70% – 85% من إجمالي التكاليف | BN11: فندقي (Hotel) | BO11: =IFERROR((AU11-AT11) / (C154 * D154 * G154 * (1 - $I$158) * BP11), 0) -> 0 | BQ11: فندقي (Hotel) | BR11: =IFERROR((AU11-AT11) / ((R154 * S154 * (1 - $Y$158) * 365 * BS11) * (1 + W154)), 0) -> 0 | BV11: الحصة من التطوير | BW11: 0 | BX11: - | BY11: - | BZ11: =H22*BW11 -> 0 | CA11: =BZ11 -> 0 | CB11: - | CF11: 5 | CG11: إجمالي تكلفة البناء | CH11: =C19 -> 78265608 | CI11: ملخص الدراسة | CJ11: C19 | CK11: ريال سعودي
AE12: صحي | AF12: =((F69/$J$59)*$I$49)*AO12 -> 0 | AG12: =J69*AO12 -> 0 | AI12: =($J$73*AH12)*AO12 -> 0 | AJ12: =((K69/$L$76)*($J$74+$J$75))*AO12 -> 0 | AK12: =((K69/$L$76)*$C$87)*AO12 -> 0 | AL12: =(((D69-F69)/$I$59)*$J$71)*AO12 -> 0 | AM12: =SUM(AF12:AG12,AI12:AL12)/$AM$14 -> 0 | AN12: =SUM(AF12:AG12,AI12:AL12)/$AN$14 -> 0 | AO12: =D137 -> 1 | AP12: =(AN12*SUM($C$86,$C$88:$C$90,$C$96:$C$97,$C$101))+((H155+X155)/($H$157+$X$157))*$C$99+(SUM($D$93:$D$95)*G69*AO12) -> 0 | AQ12: =(($A$92+$C$98)*AM12) -> 0 | AR12: =AM12*$C$119 -> 0 | AS12: =AN12*$C$107 -> 0 | AT12: =SUM(I155,Y155) -> 0 | AU12: =SUM(AF12:AG12,AI12:AL12,AP12:AT12) -> 0 | AV12: =IFERROR((AU12-AT12)/E137, "0") -> 0 | AW12: =(AU12-AT12)/($C$23) -> 0 | AX12: =SUM(J137,H155,O137,X155) -> 0 | AY12: =IFERROR(AZ12/E137, "0.00") -> 0.00 | AZ12: =AX12-AU12 -> 0 | BA12: =IFERROR(BD12/AW12, "0.00") -> 0.00 | BB12: =IFERROR(AZ12/AX12, "0.00%") -> 0.00% | BC12: =AZ12/$C$25 -> 0 | BD12: =IFERROR(AZ12/(AU12-AT12), "0.00%") -> 0.00% | BE12: صحي | BH12: إجمالي التكاليف غير المباشرة (Total Indirect Costs) | BI12: =-SUM(E192:E193,C199:C201,C207:C212,C214:C216) -> 39192718 | BJ12: =BI12/($C$23+$C$24) -> 0.17245051 | BL12: من 15% إلى 25% من إجمالي التكاليف غالبًا | BN12: صحي (health) | BO12: =IFERROR((AU12-AT12) / (C155 * D155 * G155 * (1 - $I$158) * BP12), 0) -> 0 | BQ12: صحي (health) | BR12: =IFERROR((AU12-AT12) / ((R155 * S155 * (1 - $Y$158) * 365 * BS12) * (1 + W155)), 0) -> 0 | BV12: الحصة العينية من المقاولات | BW12: 1 | BX12: =(E103*C195)*BW12 -> 0 | BY12: - | BZ12: =BX12*$BW$7 -> 0 | CA12: =BZ12+BX12 -> 0 | CB12: - | CF12: 6 | CG12: إجمالي التكاليف الأخرى | CH12: =C20 -> 21170058 | CI12: ملخص الدراسة | CJ12: C20 | CK12: ريال سعودي
AE13: شاليهات | AF13: =((F70/$J$59)*$I$49)*AO13 -> 0 | AG13: =J70*AO13 -> 0 | AI13: =($J$73*AH13)*AO13 -> 0 | AJ13: =((K70/$L$76)*($J$74+$J$75))*AO13 -> 0 | AK13: =((K70/$L$76)*$C$87)*AO13 -> 0 | AL13: =(((D70-F70)/$I$59)*$J$71)*AO13 -> 0 | AM13: =SUM(AF13:AG13,AI13:AL13)/$AM$14 -> 0 | AN13: =SUM(AF13:AG13,AI13:AL13)/$AN$14 -> 0 | AO13: =D138 -> 1 | AP13: =(AN13*SUM($C$86,$C$88:$C$90,$C$96:$C$97,$C$101))+((H156+X156)/($H$157+$X$157))*$C$99+(SUM($D$93:$D$95)*G70*AO13) -> 0 | AQ13: =(($A$92+$C$98)*AM13) -> 0 | AR13: =AM13*$C$119 -> 0 | AS13: =AN13*$C$107 -> 0 | AT13: =SUM(I156,Y156) -> 0 | AU13: =SUM(AF13:AG13,AI13:AL13,AP13:AT13) -> 0 | AV13: =IFERROR((AU13-AT13)/E138, "0") -> 0 | AW13: =(AU13-AT13)/($C$23) -> 0 | AX13: =SUM(J138,H156,O138,X156) -> 0 | AY13: =IFERROR(AZ13/E138, "0.00") -> 0.00 | AZ13: =AX13-AU13 -> 0 | BA13: =IFERROR(BD13/AW13, "0.00") -> 0.00 | BB13: =IFERROR(AZ13/AX13, "0.00%") -> 0.00% | BC13: =AZ13/$C$25 -> 0 | BD13: =IFERROR(AZ13/(AU13-AT13), "0.00%") -> 0.00% | BE13: شاليهات | BH13: إجمالي التكاليف التشغيلية (Total Operating Costs) | BI13: =C24 -> 6529315.6 | BJ13: =BI13/SUM(C23:C24) -> 0.028729413 | BL13: - | BN13: شاليهات (Chalets) | BO13: =IFERROR((AU13-AT13) / (C156 * D156 * G156 * (1 - $I$158) * BP13), 0) -> 0 | BQ13: شاليهات (Chalets) | BR13: =IFERROR((AU13-AT13) / ((R156 * S156 * (1 - $Y$158) * 365 * BS13) * (1 + W156)), 0) -> 0 | BV13: الحصة من المقاولات | BW13: 0 | BX13: - | BY13: - | BZ13: =(E104*C196)*BW13 -> 0 | CA13: =BZ13 -> 0 | CB13: - | CF13: 7 | CG13: إجمالي رسوم الصندوق | CH13: =C21 -> 22314657 | CI13: ملخص الدراسة | CJ13: C21 | CK13: ريال سعودي
AE14: الإجمالي | AF14: =SUMIF(AF4:AF13, "<>#DIV/0!") -> 91847824 | AG14: =SUMIF(AG4:AG13, "<>#DIV/0!") -> 44700408 | AH14: =SUM(AH4:AH13) -> 1 | AI14: =SUM(AI4:AI13) -> 6162000 | AJ14: =SUMIF(AJ4:AJ13, "<>#DIV/0!") -> 14176800 | AK14: =SUMIF(AK4:AK13, "<>#DIV/0!") -> 2835360 | AL14: =SUM(AL4:AL13) -> 0 | AM14: =SUM(AF14:AG14,AI14:AL14) -> 159722392 | AN14: =SUM(AF4:AG13,AI4:AL13,AF22:AG31,AI22:AL31) -> 2.0387089e+08 | AO14: - | AP14: =SUM(AP4:AQ13) -> 17522844 | AR14: =SUMIF(AR4:AR13, "<>#DIV/0!") -> 7141903.3 | AS14: =SUMIF(AS4:AS13, "<>#DIV/0!") -> 17482390 | AT14: =SUM(AT4:AT13) -> 6529315.6 | AU14: =SUM(AU4:AU13) -> 2.0839884e+08 | AV14: =IFERROR(AU14/E139, "0") -> 21006.267 | AW14: =SUMIF(AW4:AW13, "<>#DIV/0!") -> 0.91451247 | AX14: =SUMIF(AX4:AX13, "<>#DIV/0!") -> 2.6669563e+08 | AY14: =AZ14/E139 -> 5876.2217 | AZ14: =SUMIF(AZ4:AZ13, "<>#DIV/0!") -> 58296785 | BA14: - | BB14: =IFERROR(AZ14/AX14, "0.00%") -> 0.2185892 | BC14: =SUM(BC4:BC13) -> 0.6785543 | BD14: =IFERROR(AZ14/AU14, "0.00%") -> 0.27973661 | BH14: إجمالي قيمة ونسبة تكاليف الأرض من إجمالي تكاليف المشروع (Land Cost as Value and % of Total Project Cost) | BI14: =I49 -> 91847824 | BJ14: =BI14/$C$23 -> 0.41609044 | BL14: من 10% إلى 25% غالبًا | BV14: العمولات 2.5% من المبيعات | BW14: 0.025 | BX14: - | BY14: بيع على الخارطة + بيع مباشر + مخارجة | BZ14: =BW14*(J139+AC139+O139) -> 7233969.4 | CA14: =BZ14 -> 7233969.4 | CB14: - | CF14: 8 | CG14: فوائد التمويل | CH14: =C22 -> 7141903.3 | CI14: ملخص الدراسة | CJ14: C22 | CK14: ريال سعودي
B15: Feasibility Study Summary | ملخص دراسة الجدوى | G15: Financial Structuring | الهيكلة المالية | AF15: =IF(ABS(SUM(Study!AF14,Study!AF32)-SUM(Study!I49))<=0.00000001,"TRUE",SUM(Study!AF14,Study!AF32)-SUM(Study!I49)) -> 30922095 | AG15: =IF(ABS(SUM(Study!AG14,Study!AG32)-SUM(J61:J71))<=0.00000001,"TRUE",SUM(Study!AG14,Study!AG32)-SUM(J61:J71)) -> TRUE | AH15: =IF(ABS(SUM(Study!AH14)-SUM(1))<=0.00000001,"TRUE",SUM(Study!AH14)-SUM(1)) -> TRUE | AI15: =IF(ABS(SUM(Study!AI14,Study!AI32)-SUM(Study!J73))<=0.00000001,"TRUE",SUM(Study!AI14,Study!AI32)-SUM(Study!J73)) -> TRUE | AJ15: =IF(ABS(SUM(Study!AJ14,Study!AJ32)-SUM(J74:J75))<=0.00000001,"TRUE",SUM(Study!AJ14,Study!AJ32)-SUM(J74:J75)) -> TRUE | AK15: =IF(ABS(SUM(Study!AK14,Study!AK32)-SUM(Study!C87))<=0.00000001,"TRUE",SUM(Study!AK14,Study!AK32)-SUM(Study!C87)) -> TRUE | AL15: =IF(ABS(SUM(Study!AL14,Study!AL32)-SUM(Study!J71))<=0.00000001,"TRUE",SUM(Study!AL14,Study!AL32)-SUM(Study!J71)) -> TRUE | AM15: =IF(ABS(SUM(Study!AM4:AM13)-SUM(1))<=0.00000001,"TRUE",SUM(Study!AM4:AM13)-SUM(1)) -> TRUE | AN15: =IF(ABS(SUM(Study!AN4:AN13,Study!AN22:AN31)-SUM(1))<=0.00000001,"TRUE",SUM(Study!AN4:AN13,Study!AN22:AN31)-SUM(1)) -> TRUE | AO15: =IF(ABS(SUM(Study!AO4:AO13,Study!AO22:AO31)-SUM(10))<=0.00000001,"TRUE",SUM(Study!AO4:AO13,Study!AO22:AO31)-SUM(10)) -> TRUE | AP15: =IF(ABS(SUM(Study!AP4:AQ13,Study!AP22:AQ31)-SUM(Study!C86,Study!C88:C101))<=0.1,"TRUE",SUM(Study!AP4:AQ13,Study!AP22:AQ31)-SUM(Study!C86,Study!C88:C101)) -> 1437638.7 | AR15: =IF(ABS(SUM(Study!AR14)-SUM(Study!C119))<=0.00000001,"TRUE",SUM(Study!AR14)-SUM(Study!C119)) -> TRUE | AS15: =IF(ABS(SUM(Study!AS14,Study!AS32)-SUM(Study!C107))<=1,"TRUE",SUM(Study!AS14,Study!AS32)-SUM(Study!C107)) -> TRUE | AT15: =IF(ABS(SUM(Study!AT14)-SUM(Study!C24))<=0.01,"TRUE",SUM(Study!AT14)-SUM(Study!C24)) -> TRUE | AU15: =IF(ABS(SUM(Study!AU14,Study!AU32)-SUM(Study!C23:C24))<=0.25,"TRUE",SUM(Study!AU14,Study!AU32)-SUM(Study!C23:C24)) -> -18870521 | AV15: =AV14=AV14 -> TRUE | AW15: =IF(ABS(SUM(Study!AW14,Study!AW32)-SUM(1))<=0.01,"TRUE",SUM(Study!AW14,Study!AW32)-SUM(1)) -> -0.085487528 | AX15: =IF(ABS(SUM(Study!AX14,Study!AX32)-SUM(Study!C17))<=0.01,"TRUE",SUM(Study!AX14,Study!AX32)-SUM(Study!C17)) -> TRUE | AY15: =AY14=AY14 -> TRUE | AZ15: =IF(ABS(SUM(Study!AZ14,Study!AZ32)-SUM(Study!C25))<=0.2,"TRUE",SUM(Study!AZ14,Study!AZ32)-SUM(Study!C25)) -> -27616435 | BA15: =BA14=BA14 -> TRUE | BB15: =BB14=BB14 -> TRUE | BC15: =IF(ABS(SUM(Study!BC14,Study!BC32)-SUM(1))<=0.01,"TRUE",SUM(Study!BC14,Study!BC32)-SUM(1)) -> -0.3214457 | BD15: =BD14=BD14 -> TRUE | BH15: إجمالي قيمة ونسبة تكاليف البناء من إجمالي تكاليف المشروع (Construction Cost as Value and % of Total Project Cost) | BI15: =J76 -> 78265608 | BJ15: =BI15/$C$23 -> 0.35456007 | BL15: المتوسط غالبًا بين 45% إلى 65% | BV15: نسبة رصف من المستثمرين | BW15: 0 | BX15: =BW15*H21 -> 0 | BY15: - | BZ15: =BX15*$BW$7 -> 0 | CA15: =BZ15+BX15 -> 0 | CB15: - | CF15: 9 | CG15: التمويل البنكي | CI15: ملخص الدراسة | CJ15: C23 | CK15: ريال سعودي
B16: البند (Item) | C16: القيمة (Value) | G16: رأس المال - (capital) | BH16: إجمالي قيمة ونسبة التكاليف الأخرى من إجمالي تكاليف المشروع (Other Costs as % of Total Project Cost) | BI16: =C102 -> 21170058 | BJ16: =BI16/$C$23 -> 0.095904925 | BL16: غالبًا بين 10% – 20% | BV16: الحصة من فارق قيمة الأرض | BW16: 1 | BX16: =K23*BW16 -> 0 | BY16: - | BZ16: =BX16*$BW$7 -> 0 | CA16: =BZ16+BX16 -> 0 | CB16: - | CF16: 10 | CG16: إجمالي التكاليف الرأسمالية (CapEx) | CH16: =C23 -> 2.2074005e+08 | CI16: ملخص الدراسة | CJ16: C24 | CK16: ريال سعودي
B17: إجمالي الإيرادات (Total Revenue) | C17: =SUM(C184:C188) -> 3.1318259e+08 | G17: المصدر (Source) | H17: SAR | I17: % | BH17: إجمالي قيمة ونسبة تكاليف فوائد التمويل من إجمالي تكاليف المشروع (Financing Interest as Value and % of Total Project Cost) | BI17: =C119 -> 7141903.3 | BJ17: =BI17/$C$23 -> 0.032354361 | BL17: من 5% – 12% حسب مدة التمويل والفوائد | BV17: اشتراكات نقدية / مصاريف سابقة | BW17: 0 | BX17: =H19*BW17 -> 0 | BY17: - | BZ17: =BX17*$BW$7 -> 0 | CA17: =BZ17+BX17 -> 0 | CB17: - | CF17: 11 | CG17: إجمالي التكاليف التشغيلية (OpEx) | CH17: =C24 -> 6529315.6 | CI17: ملخص الدراسة | CJ17: C25 | CK17: ريال سعودي
B18: إجمالي تكلفة الأرض (Total Land Cost) | C18: =I49 -> 91847824 | G18: (Equity) - الملكية | BH18: إجمالي قيمة ونسبة تكاليف الصندوق من إجمالي تكاليف المشروع (Fund Management Cost as Value and % of Total Project Cost) | BI18: =C107 -> 22314657 | BJ18: =BI18/$C$23 -> 0.10109021 | BL18: تتراوح من 1% – 7% حسب شروط الصندوق | CF18: 12 | CG18: صافي الدخل | CH18: =C25 -> 85913221 | CI18: ملخص الدراسة | CJ18: C26 | CK18: ريال سعودي
B19: إجمالي تكلفة البناء (Total Construction Cost) | C19: =J76 -> 78265608 | G19: الاشتراكات النقدية (Cash Subscription) | H19: 34500000 | I19: =H19/$H$34 -> 0.15629244 | BH19: مؤشرات الإيرادات والربحية | Revenue & Profitability Indicators | BL19: - | BV19: إجمالي رصف | BX19: =SUM(BX10:BX17) -> 0 | BY19: - | BZ19: =SUM(BZ10:BZ17) -> 7233969.4 | CA19: =SUM(CA10:CA17) -> 7233969.4 | CB19: - | CF19: 13 | CG19: مدة المشروع المتوقعة (سنوات) | CH19: =C27 -> 5 | CI19: ملخص الدراسة | CJ19: C27 | CK19: سنة
B20: إجمالي التكاليف الأخرى (Total Other cost) | C20: =C102 -> 21170058 | G20: الاشتراك من مدير الصندوق (fund manager's Subscription) | I20: =H20/$H$34 -> 0 | AE20: توزيع تكاليف مكونات البيع على الخارطة | BH20: متوسط سعر بيع الأمتار البيعية (Average Selling Price per Sellable m²) | BI20: =SUM(C184,C187:C188)/J59 -> 29166.897 | BL20: - | BV20: مستثمرين رصف | BX20: 0 | BY20: 0.7 | BZ20: =BX20*BW7*BY20 -> 0 | CA20: =BZ20+BX20 -> 0 | CB20: - | CF20: ▌ المؤشرات المالية
B21: إجمالي رسوم الصندوق (Total Fund Fees) | C21: =C107 -> 22314657 | G21: الأشتراك النقدي من المطور (Cash Subscription from Developer) | H21: 11100000 | I21: =H21/$H$34 -> 0.050285392 | J21: =H34*5% -> 11037003 | AE21: المكون | AF21: توزيع تكاليف الأرض | AG21: تكاليف البناء | AH21: نسبة تزيع تكاليف اللاند سكيب | AI21: توزيع تكاليف اللاندسكيب | AJ21: توزيع تكاليف البوديم و القبو | AK21: توزيع تكاليف الحفر والمسح و الاختبار | AL21: توزيع تكاليف المساحات الحركية والخدمية | AM21: نسب التكاليف السابقة من التكاليف الموجودة بالجدول | AN21: نسب التكاليف السابقة من التكاليف الكلية | AO21: نسبة بيع المكون على الخارطة من الإجمالي | AP21: توزيع التكاليف الأخرى | AQ21: توزيع تكاليف أخرى إضافية | AR21: توزيع تكاليف التمويل | AS21: توزيع تكاليف الصندوق | AT21: تكاليف بيع الخارطة | AU21: إجمالي تكاليف كل مكون | AV21: توزيع التكلفة على الأمتار البيعية | AW21: نسبة تكاليف كل مكون من إجمالي المشروع | AX21: إجمالي إيراد كل مكون | AY21: صافي العائد لكل م² بيعي | AZ21: صافي دخل كل مكون | BA21: العائد النسبي للمكون | BB21: هامش الربح من إجمالي الإرادات | BC21: نسبة صافي دخل كل مكون من إجمالي صافي دخل المشروع | BD21: نسبة صافي دخل كل مكون | BH21: متوسط قيمة و نسبة الربح لكل م² (Average Profit Value and % per m²) | BI21: =BI20-BI7 -> 6916.6566 | BJ21: =BI21/BI7 -> 0.31085761 | BL21: - | BV21: الاجمالي | BX21: =SUM(BX19:BX20) -> 0 | BY21: - | BZ21: =SUM(BZ19:BZ20) -> 7233969.4 | CA21: =BZ21+BX21 -> 7233969.4 | CB21: - | CF21: 14 | CG21: معدل العائد الداخلي (IRR) | CH21: =C28 -> 0.13308131 | CI21: المؤشرات المالية | CJ21: C28 | CK21: نسبة مئوية
B22: فوائد التمويل (Interest) | C22: =C119 -> 7141903.3 | G22: الأشتراك العيني من المطور (In-Kind Subscription from Developer) | H22: =J22*((D104+E104)*-E196) -> 0 | I22: =H22/$H$34 -> 0 | J22: 0 | AE22: سكني (بيع على الخارطة) | AF22: =((F61/$J$59)*$I$49)*AO22 -> 0 | AG22: =J61*AO22 -> 0 | AH22: 0.15 | AI22: =($J$73*AH22)*AO22 -> 0 | AJ22: =((K61/$L$76)*($J$74+$J$75))*AO22 -> 0 | AK22: =((K61/$L$76)*$C$87)*AO22 -> 0 | AL22: =(((D61-F61)/$I$59)*$J$71)*AO22 -> 0 | AN22: =SUM(AF22:AG22,AI22:AL22)/$AN$32 -> 0 | AO22: =S129 -> 0 | AP22: =(AN22*SUM($C$86,$C$88:$C$90,$C$96:$C$97,$C$101))+(SUM($D$93:$D$95)*G61*AO22) -> 0 | AR22: لا يــــنــطــبــق | AS22: =AN22*$C$107 -> 0 | AT22: لا يــــنــطــبــق | AV22: =IFERROR((AU22)/T129, "0") -> 0 | AX22: =AC129 -> 0 | AY22: =IFERROR(AZ22/T129, "0.00") -> 0.00 | BA22: =IFERROR(BD22/AW22, "0.00") -> 0.00 | BB22: =IFERROR(AZ22/AX22, "0.00%") -> 0.00% | BD22: =IFERROR(AZ22/(AU22), "0.00%") -> 0.00% | BE22: سكني | BH22: العائد على المتر البيعي (شامل عوائد الإيجار) (Total Return per Saleable m² including Rental Income) | BI22: =C25/F76 -> 8659.9138 | BJ22: =BI22/BI7 -> 0.3892054 | BL22: - | CF22: 15 | CG22: العائد على الاستثمار (ROI) | CH22: =C30 -> 0.3892054 | CI22: المؤشرات المالية | CJ22: C30 | CK22: نسبة مئوية
B23: إجمالي التكاليف الرأسمالية للمشروع (Total Capital Expenditures) | C23: =SUM(C18:C22) -> 2.2074005e+08 | G23: الإشتراك العيني من مالك الأرض (In-Kind Subscription from Landowner) | H23: =(J23*E49)+K23 -> 62809600 | I23: =H23/$H$34 -> 0.28454102 | J23: 0.7 | AE23: فلل (بيع على الخارطة) | AF23: =((F62/$J$59)*$I$49)*AO23 -> 30922095 | AG23: =J62*AO23 -> 13226400 | AH23: 0 | AI23: =($J$73*AH23)*AO23 -> 0 | AJ23: =((K62/$L$76)*($J$74+$J$75))*AO23 -> 0 | AK23: =((K62/$L$76)*$C$87)*AO23 -> 0 | AL23: =(((D62-F62)/$I$59)*$J$71)*AO23 -> 0 | AN23: =SUM(AF23:AL23)/$AN$32 -> 0.21655125 | AO23: =S130 -> 1 | AP23: =(AN23*SUM($C$86,$C$88:$C$90,$C$96:$C$97,$C$101))+(SUM($D$93:$D$95)*G62*AO23) -> 2249493 | AR23: لا يــــنــطــبــق | AS23: =AN23*$C$107 -> 4832266.8 | AT23: لا يــــنــطــبــق | AV23: =IFERROR((AU23-AT23)/T130, "0") -> 0 | AX23: =AC130 -> 46486957 | AY23: =IFERROR(AZ23/T130, "0.00") -> 0 | BA23: =IFERROR(BD23/AW23, "0.00") -> 0.00 | BB23: =IFERROR(AZ23/AX23, "0.00%") -> 0 | BD23: =IFERROR(AZ23/(AU23), "0.00%") -> 0.00% | BE23: فلل | BH23: نسبة صافي الربح من الإيرادات (Net Profit as % of Revenues) | BI23: =C25/C17 -> 0.27432311 | BL23: مثالي إن كان بين 20% إلى 35% (أقل من 15% يُعد ضعيف، وأكثر من 40% نادر وممتاز) | CF23: 16 | CG23: العائد على الملكية (ROE) | CH23: =C32 -> 0.7924872 | CI23: المؤشرات المالية | CJ23: C32 | CK23: نسبة مئوية
B24: إجمالي التكاليف التشغيلية (Total Operating Expenses) | C24: =-SUM(E213) -> 6529315.6 | G24: إجمالي الملكية (Total Equity) | H24: =SUM(H19:H23) -> 108409600 | I24: =H24/$H$34 -> 0.49111885 | AE24: تاون هاوس (بيع على الخارطة) | AF24: =((F63/$J$59)*$I$49)*AO24 -> 0 | AG24: =J63*AO24 -> 0 | AH24: 0 | AI24: =($J$73*AH24)*AO24 -> 0 | AJ24: =((K63/$L$76)*($J$74+$J$75))*AO24 -> 0 | AK24: =((K63/$L$76)*$C$87)*AO24 -> 0 | AL24: =(((D63-F63)/$I$59)*$J$71)*AO24 -> 0 | AN24: =SUM(AF24:AL24)/$AN$32 -> 0 | AO24: =S131 -> 0.00% | AP24: =(AN24*SUM($C$86,$C$88:$C$90,$C$96:$C$97,$C$101))+(SUM($D$93:$D$95)*G63*AO24) -> 0 | AR24: لا يــــنــطــبــق | AS24: =AN24*$C$107 -> 0 | AT24: لا يــــنــطــبــق | AV24: =IFERROR((AU24-AT24)/T131, "0") -> 0 | AX24: =AC131 -> 0 | AY24: =IFERROR(AZ24/T131, "0.00") -> 0.00 | BA24: =IFERROR(BD24/AW24, "0.00") -> 0.00 | BB24: =IFERROR(AZ24/AX24, "0.00%") -> 0.00% | BD24: =IFERROR(AZ24/(AU24), "0.00%") -> 0.00% | BE24: تاون هاوس | BH24: نقطة التعادل - عدد الأمتار البيعية اللازمة لتغطية التكاليف (Sellable Area Required for Cost Recovery) | BI24: =C23/BI20 -> 7568.1706 | BJ24: =BI24/F76 -> 0.76285936 | BL24: - | CF24: 17 | CG24: العائد على الملكية السنوي | CH24: =C34 -> 0.15849744 | CI24: المؤشرات المالية | CJ24: C34 | CK24: نسبة مئوية
B25: صافي الدخل (Net Income) | C25: =C17-(C23+C24) -> 85913221 | G25: التمويل البنكي - (Bank Financing) | AE25: أدوار (بيع على الخارطة) | AF25: =((F64/$J$59)*$I$49)*AO25 -> 0 | AG25: =J64*AO25 -> 0 | AH25: 0 | AI25: =($J$73*AH25)*AO25 -> 0 | AJ25: =((K64/$L$76)*($J$74+$J$75))*AO25 -> 0 | AK25: =((K64/$L$76)*$C$87)*AO25 -> 0 | AL25: =(((D64-F64)/$I$59)*$J$71)*AO25 -> 0 | AN25: =SUM(AF25:AL25)/$AN$32 -> 0 | AO25: =S132 -> 0.00% | AP25: =(AN25*SUM($C$86,$C$88:$C$90,$C$96:$C$97,$C$101))+(SUM($D$93:$D$95)*G64*AO25) -> 0 | AR25: لا يــــنــطــبــق | AS25: =AN25*$C$107 -> 0 | AT25: لا يــــنــطــبــق | AV25: =IFERROR((AU25-AT25)/T132, "0") -> 0 | AX25: =AC132 -> 0 | AY25: =IFERROR(AZ25/T132, "0.00") -> 0.00 | BA25: =IFERROR(BD25/AW25, "0.00") -> 0.00 | BB25: =IFERROR(AZ25/AX25, "0.00%") -> 0.00% | BD25: =IFERROR(AZ25/(AU25), "0.00%") -> 0.00% | BE25: أدوار | BH25: مؤشرات التمويل والمخاطر | Financing & Risk Indicators | BJ25: 0 | BL25: - | CF25: ▌ الهيكلة المالية
B26: أهــــــــــــــــــم مؤشــــــــرات الدراســــــــــة | G26: إجمالي التمويل البنكي (Total Bank Financing) | H26: =E189 -> 54352006 | I26: =H26/$H$34 -> 0.2462263 | AE26: استديوهات (بيع على الخارطة) | AF26: =((F65/$J$59)*$I$49)*AO26 -> 0 | AG26: =J65*AO26 -> 0 | AH26: 0 | AI26: =($J$73*AH26)*AO26 -> 0 | AJ26: =((K65/$L$76)*($J$74+$J$75))*AO26 -> 0 | AK26: =((K65/$L$76)*$C$87)*AO26 -> 0 | AL26: =(((D65-F65)/$I$59)*$J$71)*AO26 -> 0 | AN26: =SUM(AF26:AL26)/$AN$32 -> 0 | AO26: =S133 -> 0.00% | AP26: =(AN26*SUM($C$86,$C$88:$C$90,$C$96:$C$97,$C$101))+(SUM($D$93:$D$95)*G65*AO26) -> 0 | AR26: لا يــــنــطــبــق | AS26: =AN26*$C$107 -> 0 | AT26: لا يــــنــطــبــق | AV26: =IFERROR((AU26-AT26)/T133, "0") -> 0 | AX26: =AC133 -> 0 | AY26: =IFERROR(AZ26/T133, "0.00") -> 0.00 | BA26: =IFERROR(BD26/AW26, "0.00") -> 0.00 | BB26: =IFERROR(AZ26/AX26, "0.00%") -> 0.00% | BD26: =IFERROR(AZ26/(AU26), "0.00%") -> 0.00% | BE26: أستوديوهات | BH26: القيم والنسب الخاصة بالتمويل البنكي (Bank Financing Limits & Conditions) | BI26: =(BJ28+BJ27)-H26 -> 53513192 | BJ26: =H26/(BJ28+BJ27) -> 0.50388825 | BL26: - | CF26: 18 | CG26: الاشتراكات النقدية | CH26: =H19 -> 34500000 | CI26: الهيكلة المالية | CJ26: H19 | CK26: ريال سعودي
B27: مدة المشروع المتوقعة - سنوي (Estimated Project Duration - Years) | C27: =B122 -> 5 | AE27: مكتبي (بيع على الخارطة) | AF27: =((F66/$J$59)*$I$49)*AO27 -> 0 | AG27: =J66*AO27 -> 0 | AH27: 0.35 | AI27: =($J$73*AH27)*AO27 -> 0 | AJ27: =((K66/$L$76)*($J$74+$J$75))*AO27 -> 0 | AK27: =((K66/$L$76)*$C$87)*AO27 -> 0 | AL27: =(((D66-F66)/$I$59)*$J$71)*AO27 -> 0 | AN27: =SUM(AF27:AL27)/$AN$32 -> 1.7167728e-09 | AO27: =S134 -> 0.00% | AP27: =(AN27*SUM($C$86,$C$88:$C$90,$C$96:$C$97,$C$101))+(SUM($D$93:$D$95)*G66*AO27) -> 0.015914983 | AR27: لا يــــنــطــبــق | AS27: =AN27*$C$107 -> 0.038309197 | AT27: لا يــــنــطــبــق | AV27: =IFERROR((AU27-AT27)/T134, "0") -> 0 | AX27: =AC134 -> 0 | AY27: =IFERROR(AZ27/T134, "0.00") -> 0.00 | BA27: =IFERROR(BD27/AW27, "0.00") -> 0.00 | BB27: =IFERROR(AZ27/AX27, "0.00%") -> 0.00% | BD27: =IFERROR(AZ27/(AU27), "0.00%") -> 0.00% | BE27: مكتبي | BI27: 0.6 | BJ27: =(I49*80%)*BI27 -> 44086956 | BL27: - | CF27: 19 | CG27: نسبة الاشتراكات النقدية | CH27: =I19 -> 0.15629244 | CI27: الهيكلة المالية | CJ27: I19 | CK27: نسبة مئوية
B28: معدل العائد الداخلي (IRR) | C28: =C223 -> 0.13308131 | G28: تمويل تشغيلي خارج هيكل رأس المال - (Off-Capital-Structure Operational Financing) | AE28: تجاري (بيع على الخارطة) | AF28: =((F67/$J$59)*$I$49)*AO28 -> 0 | AG28: =J67*AO28 -> 0 | AH28: 0.35 | AI28: =($J$73*AH28)*AO28 -> 0 | AJ28: =((K67/$L$76)*($J$74+$J$75))*AO28 -> 0 | AK28: =((K67/$L$76)*$C$87)*AO28 -> 0 | AL28: =(((D67-F67)/$I$59)*$J$71)*AO28 -> 0 | AN28: =SUM(AF28:AL28)/$AN$32 -> 1.7167728e-09 | AO28: =S135 -> 0.00% | AP28: =(AN28*SUM($C$86,$C$88:$C$90,$C$96:$C$97,$C$101))+(SUM($D$93:$D$95)*G67*AO28) -> 0.015914983 | AR28: لا يــــنــطــبــق | AS28: =AN28*$C$107 -> 0.038309197 | AT28: لا يــــنــطــبــق | AV28: =IFERROR((AU28-AT28)/T135, "0") -> 0 | AX28: =AC135 -> 0 | AY28: =IFERROR(AZ28/T135, "0.00") -> 0.00 | BA28: =IFERROR(BD28/AW28, "0.00") -> 0.00 | BB28: =IFERROR(AZ28/AX28, "0.00%") -> 0.00% | BD28: =IFERROR(AZ28/(AU28), "0.00%") -> 0.00% | BE28: تجاري | BI28: 0.7 | BJ28: =SUM(J76,C86:C90,C93:C95,C96:C96,C101)*BI28 -> 63778242 | BL28: - | CF28: 20 | CG28: الاشتراك من مدير الصندوق | CH28: =H20 -> 0 | CI28: الهيكلة المالية | CJ28: H20 | CK28: ريال سعودي
G29: البيع على الخارطة (Off-Plan Sales) | H29: =K29*J29 -> 46486957 | I29: =H29/$H$34 -> 0.21059593 | J29: =AC139 -> 46486957 | K29: 1 | L29: =-H35/J29 -> 0 | AE29: فندقي (بيع على الخارطة) | AF29: =((F68/$J$59)*$I$49)*AO29 -> 0 | AG29: =J68*AO29 -> 0 | AH29: 0.15 | AI29: =($J$73*AH29)*AO29 -> 0 | AJ29: =((K68/$L$76)*($J$74+$J$75))*AO29 -> 0 | AK29: =((K68/$L$76)*$C$87)*AO29 -> 0 | AL29: =(((D68-F68)/$I$59)*$J$71)*AO29 -> 0 | AN29: =SUM(AF29:AL29)/$AN$32 -> 7.3575979e-10 | AO29: =S136 -> 0 | AP29: =(AN29*SUM($C$86,$C$88:$C$90,$C$96:$C$97,$C$101))+((SUM($D$94:$D$95)*G68*AO29)+(D93*G68/2*AO29)) -> 0.006820707 | AR29: لا يــــنــطــبــق | AS29: =AN29*$C$107 -> 0.016418227 | AT29: لا يــــنــطــبــق | AV29: =IFERROR((AU29-AT29)/T136, "0") -> 0 | AX29: =AC136 -> 0 | AY29: =IFERROR(AZ29/T136, "0.00") -> 0.00 | BA29: =IFERROR(BD29/AW29, "0.00") -> 0.00 | BB29: =IFERROR(AZ29/AX29, "0.00%") -> 0.00% | BD29: =IFERROR(AZ29/(AU29), "0.00%") -> 0.00% | BE29: فندقي | BI29: =BJ29/D119 -> 0.039885606 | BJ29: =BI30/H26 -> 0.13140091 | BL29: - | CF29: 21 | CG29: الاشتراك النقدي من المطور | CH29: =H21 -> 11100000 | CI29: الهيكلة المالية | CJ29: H21 | CK29: ريال سعودي
B30: العائد على الإستثمار (ROI) | C30: =C25/C23 -> 0.3892054 | G30: مصادر أخرى (Other Sources) | H30: =K30*J30 -> 11491488 | I30: =H30/$H$34 -> 0.052058917 | J30: =SUM(J139,M157,AC157) -> 17294496 | K30: 0.66445927 | L30: =-H35/J30 -> 0 | AE30: صحي (بيع على الخارطة) | AF30: =((F69/$J$59)*$I$49)*AO30 -> 0 | AG30: =J69*AO30 -> 0 | AH30: =AH12 -> 0 | AI30: =($J$73*AH30)*AO30 -> 0 | AJ30: =((K69/$L$76)*($J$74+$J$75))*AO30 -> 0 | AK30: =((K69/$L$76)*$C$87)*AO30 -> 0 | AL30: =(((D69-F69)/$I$59)*$J$71)*AO30 -> 0 | AN30: =SUM(AF30:AL30)/$AN$32 -> 0 | AO30: =S137 -> 0.00% | AP30: =(AN30*SUM($C$86,$C$88:$C$90,$C$96:$C$97,$C$101))+(SUM($D$93:$D$95)*G69*AO30) -> 0 | AR30: لا يــــنــطــبــق | AS30: =AN30*$C$107 -> 0 | AT30: لا يــــنــطــبــق | AV30: =IFERROR((AU30-AT30)/T137, "0") -> 0 | AX30: =AC137 -> 0 | AY30: =IFERROR(AZ30/T137, "0.00") -> 0.00 | BA30: =IFERROR(BD30/AW30, "0.00") -> 0.00 | BB30: =IFERROR(AZ30/AX30, "0.00%") -> 0.00% | BD30: =IFERROR(AZ30/(AU30), "0.00%") -> 0.00% | BE30: صحي | BI30: =C22 -> 7141903.3 | BL30: - | CF30: 22 | CG30: الاشتراك العيني من المطور | CH30: =H22 -> 0 | CI30: الهيكلة المالية | CJ30: H22 | CK30: ريال سعودي
G31: إجمالي التمويل التشغيلي (Total Operational Financing) | H31: =SUM(H29:H30) -> 57978444 | I31: =H31/$H$34 -> 0.26265485 | AE31: شاليهات (بيع على الخارطة) | AF31: =((F70/$J$59)*$I$49)*AO31 -> 0 | AG31: =J70*AO31 -> 0 | AH31: =AH13 -> 0 | AI31: =($J$73*AH31)*AO31 -> 0 | AJ31: =((K70/$L$76)*($J$74+$J$75))*AO31 -> 0 | AK31: =((K70/$L$76)*$C$87)*AO31 -> 0 | AL31: =(((D70-F70)/$I$59)*$J$71)*AO31 -> 0 | AN31: =SUM(AF31:AL31)/$AN$32 -> 0 | AO31: =S138 -> 0.00% | AP31: =(AN31*SUM($C$86,$C$88:$C$90,$C$96:$C$97,$C$101))+(SUM($D$93:$D$95)*G70*AO31) -> 0 | AR31: لا يــــنــطــبــق | AS31: =AN31*$C$107 -> 0 | AT31: لا يــــنــطــبــق | AV31: =IFERROR((AU31-AT31)/T138, "0") -> 0 | AX31: =AC138 -> 0 | AY31: =IFERROR(AZ31/T138, "0.00") -> 0.00 | BA31: =IFERROR(BD31/AW31, "0.00") -> 0.00 | BB31: =IFERROR(AZ31/AX31, "0.00%") -> 0.00% | BD31: =IFERROR(AZ31/(AU31), "0.00%") -> 0.00% | BE31: شاليهات | BH31: نسبة المخاطرة التمويلية (Loan to Value Ratio - LTV) | BI31: =H26/(SUM(C184:C188)) -> 0.17354734 | BJ31: =1-BI31 -> 0.82645266 | BL31: بين (50%) و (70%) = طبيعي أقل من (50%) = منخفض (اعتماد كبير على تمويل ذاتي) أكثر من (70%) = مرتفع (مخاطرة عالية على البنك) | CF31: 23 | CG31: نسبة الاشتراك العيني من المطور | CH31: =I22 -> 0 | CI31: الهيكلة المالية | CJ31: I22 | CK31: نسبة مئوية
B32: العائد على الملكية (ROE) | C32: =(C25/H24) -> 0.7924872 | G32: الإجمالي - (Total) | AE32: الإجمالي | AF32: =SUM(AF22:AF31) -> 30922095 | AG32: =SUM(AG22:AG31) -> 13226400 | AH32: =SUM(AH22:AH31) -> 1 | AI32: =SUM(AI22:AI31) -> 0 | AJ32: =SUM(AJ22:AJ31) -> 0 | AK32: =SUM(AK22:AK31) -> 0 | AL32: =SUM(AL22:AL31) -> 0 | AM32: =SUM(AF32:AG32,AI32:AL32) -> 44148495 | AN32: =SUM(AF4:AG13,AI4:AL13,AF22:AG31,AI22:AL31) -> 2.0387089e+08 | AO32: - | AR32: - | AS32: =SUM(AS22:AS31) -> 4832266.9 | AT32: =SUM(AT22:AT31) -> 0 | AV32: =IFERROR(AU32/T139, "0") -> 0 | AX32: =SUM(AX22:AX31) -> 46486957 | AY32: =AZ32/T139 -> 0 | AZ32: =SUMIF(AZ22:AZ31, "<>#DIV/0!") -> 0 | BA32: - | BB32: =IFERROR(AZ32/AX32, "0.00%") -> 0 | BD32: =IFERROR(AZ32/AU32, "0.00%") -> 0.00% | BH32: مؤشر المخاطر التمويلية (Leverage Risk Indicator) | BI32: =H26/H24 -> 0.50135787 | BL32: يفضل أن يكون ≤ 1.5 (كلما ارتفع زادت المخاطرة) | CF32: 24 | CG32: الاشتراك العيني من مالك الأرض | CH32: =H23 -> 62809600 | CI32: الهيكلة المالية | CJ32: H23 | CK32: ريال سعودي
G33: إجمالي مصادر التمويل (Total Financing Sources) | H33: =H24+H26+H31 -> 2.2074005e+08 | I33: =IF(ABS(SUM(1)-SUM(Study!I24,Study!I26,Study!I31))<=0.001,"TRUE",SUM(1)-SUM(Study!I24,Study!I26,Study!I31)) -> TRUE | AF33: =I49-AF14=AF32 -> FALSE | AG33: =SUM(J61:J71)-AG14=AG32 -> TRUE | AH33: =SUM(AH22:AH31)=AH32 -> TRUE | AI33: =ABS((J73 - AI14) - AI32) <= 0.9 -> TRUE | AJ33: =(J74+J75)-AJ14=AJ32 -> TRUE | AK33: =ABS((C87 - AK14) - AK32) <= 0.9 -> TRUE | AL33: =J71-AL14=AL32 -> TRUE | AM33: =SUM(AF22:AG31,AI22:AL31)=AM32 -> TRUE | AN33: =SUM(AI22:AL31,AF22:AG31,AF4:AG13,AI4:AL13)=AN32 -> TRUE | AO33: =SUM(AO4:AO13,AO22:AO31)=1000% -> TRUE | AR33: =AR32=AR32 -> TRUE | AS33: =ABS((C107 - AS14) - AS32) <= 0.9 -> TRUE | AT33: =AT32=AT32 -> TRUE | AV33: =AV32=AV32 -> TRUE | AX33: =AX32=AC139 -> TRUE | AY33: =AY32=AY32 -> TRUE | AZ33: =AZ32=AZ32 -> TRUE | BA33: =BA32=BA32 -> TRUE | BB33: =BB32=BB32 -> TRUE | BD33: =BD32=BD32 -> TRUE | BH33: قيمة ونسبة تمويل مبيعات الخارطة من تكاليف المشروع خلال فترة البيع (Value and % of Off-Plan Sales Financing for Project Costs During Sales Period) | BI33: =AX22 -> 0 | BJ33: =C184/-(SUM(G192:S216)) -> 0.49384503 | BL33: من 30% إلى 60% من التكاليف أثناء البيع يعتبر جيد جداً | CF33: 25 | CG33: نسبة الاشتراك العيني من مالك الأرض | CH33: =I23 -> 0.28454102 | CI33: الهيكلة المالية | CJ33: I23 | CK33: نسبة مئوية
B34: العائد على الملكية السنوي (ROE Annually) | C34: =C32/C27 -> 0.15849744 | G34: إجمالي التكاليف الرأسمالية للمشروع (Total Capital Expenditures) | H34: =C23 -> 2.2074005e+08 | BH34: هامش الأمان (Safety Margin) | BI34: =(C17-C23)/C17 -> 0.29517138 | BL34: المستهدف الجيد ≥ 20% (بمعنى أن القيمة السوقية أعلى بـ 20% من التكلفة) | CF34: 26 | CG34: إجمالي الملكية | CH34: =H24 -> 108409600 | CI34: الهيكلة المالية | CJ34: H24 | CK34: ريال سعودي
G35: الفرق (Difference) | H35: =H33-H34 -> 0 | BH35: مؤشرات الأرض والزمن | Land & Time Indicators | BJ35: 0 | BL35: - | CF35: 27 | CG35: نسبة إجمالي الملكية | CH35: =I24 -> 0.49111885 | CI35: الهيكلة المالية | CJ35: I24 | CK35: نسبة مئوية
BH36: تكلفة متر الأرض شاملة الضريبة والسعي (Land Cost per m² - Including Tax and Commission) | BI36: =I49/C49 -> 11179.141 | BJ36: =D49 -> 10921.13 | BL36: - | CF36: 28 | CG36: إجمالي التمويل البنكي | CH36: =H26 -> 54352006 | CI36: الهيكلة المالية | CJ36: H26 | CK36: ريال سعودي
BH37: سعر متر الأرض عند البيع (Land Price per m² at Sale) | BI37: =((I49/C23)*C17)/C49 -> 15860.793 | BL37: - | CF37: 29 | CG37: نسبة التمويل البنكي | CH37: =I26 -> 0.2462263 | CI37: الهيكلة المالية | CJ37: I26 | CK37: نسبة مئوية
AE38: إجمالي توزيع التكاليف على جميع المكونات | BH38: قيمة ارتفاع سعر متر الأرض عند البيع (Land Price Appreciation Value) | BI38: =BI37-BI36 -> 4681.6523 | BL38: - | CF38: 30 | CG38: البيع على الخارطة (هيكلة) | CH38: =H29 -> 46486957 | CI38: الهيكلة المالية | CJ38: H29 | CK38: ريال سعودي
AE39: المكون | AF39: توزيع تكاليف الأرض | AG39: تكاليف البناء | AH39: نسبة تزيع تكاليف اللاند سكيب | AI39: توزيع تكاليف اللاندسكيب | AJ39: توزيع تكاليف البوديم و القبو | AK39: توزيع تكاليف الحفر والمسح و الاختبار | AL39: توزيع تكاليف المساحات الحركية والخدمية | AM39: نسب التكاليف السابقة من التكاليف الموجودة بالجدول | AN39: نسب التكاليف السابقة من التكاليف الكلية | AO39: نسب المكونات من البيع المباشر أو المخارجة من الإجمالي | AP39: توزيع التكاليف الأخرى | AQ39: توزيع تكاليف أخرى إضافية | AR39: توزيع تكاليف التمويل | AS39: توزيع تكاليف الصندوق | AT39: توزيع التكاليف التشغيلية | AU39: إجمالي تكاليف كل مكون | AV39: توزيع التكلفة على المساحات الصافية القابلة للبيع | AW39: نسبة تكاليف كل مكون من إجمالي المشروع | AX39: إجمالي إيراد كل مكون | AY39: صافي العائد لكل م² بيعي | AZ39: صافي دخل كل مكون | BA39: العائد النسبي للمكون | BB39: هامش الربح من إجمالي الإرادات | BC39: نسبة صافي دخل كل مكون من إجمالي صافي دخل المشروع | BD39: نسبة صافي دخل كل مكون | BH39: نسبة ارتفاع سعر متر الأرض (Land Price Appreciation Rate) | BI39: =BI38/BI36 -> 0.41878461 | BL39: من 10% إلى 40% خلال 3–5 سنوات يعتبر جيد | CF39: 31 | CG39: نسبة البيع على الخارطة | CH39: =I29 -> 0.21059593 | CI39: الهيكلة المالية | CJ39: I29 | CK39: نسبة مئوية
AE40: سكني | AF40: =SUM(AF4,AF22) -> 15362564 | AG40: =SUM(AG4,AG22) -> 7800408 | AH40: =AH4 -> 0 | AI40: =SUM(AI4,AI22) -> 0 | AJ40: =SUM(AJ4,AJ22) -> 0 | AK40: =SUM(AK4,AK22) -> 0 | AL40: =SUM(AL4,AL22) -> 0 | AM40: - | AN40: =SUM(AN4,AN22) -> 0.11361589 | AO40: =SUM(AO4,AO22) -> 1 | AP40: =SUM(AP4,AP22) -> 749188.5 | AQ40: =SUM(AQ4,AQ22) -> 887297.5 | AR40: =SUM(AR4,AR22) -> 1035720.2 | AS40: =SUM(AS4,AS22) -> 2535299.6 | AT40: =SUM(AT4,AT22) -> 123565.55 | AU40: =SUM(AU4,AU22) -> 28494043 | AV40: =IFERROR((AU40-AT40)/F61, "0") -> 9413.5425 | AW40: =SUM(AW4,AW22) -> 0.12852438 | AX40: =SUM(AX22,AX4) -> 31818130 | AY40: =IFERROR(AZ40/F61, "0.00") -> 1102.9575 | AZ40: =SUM(AZ22,AZ4) -> 3324086.8 | BA40: =IFERROR(BD40/AW40, "0.00") -> 0.91163333 | BB40: =IFERROR(AZ40/AX40, "0.00%") -> 0.10447147 | BC40: =AZ40/$C$25 -> 0.038691214 | BD40: =IFERROR(AZ40/(AU40-AT40), "0.00%") -> 0.11716711 | BE40: سكني | BH40: كفاءة المساحة البيعية من المساحات المبنية فوق الأرض (Saleable Efficiency Ratio of Above-Ground Built-Up Area) | BI40: =F76/I59 -> 0.63159036 | BL40: المستهدف المثالي ≥ 70% (الممتاز يتجاوز 75–80%) | CF40: 32 | CG40: مصادر أخرى | CH40: =H30 -> 11491488 | CI40: الهيكلة المالية | CJ40: H30 | CK40: ريال سعودي
...

Sheet Summary
B1: رصف للاستثمار | RASF Investment
B6: Values shown are SAR except where stated | القيم المعروضة هي بالريال سعودي باستثناء ما هو مذكور | E6: NSA.m² | Net Sellable Area|TDA.m² | Total Development Area|LA.m² | Total Land Area NSA.m² | المساحات الصافية القابلة للبيع |TDA.m² | إجمالي المساحة التطويرية | LA.m² | مساحة الأرض الإجمالية
C10: Summary | ملخص
I12: (Area) - المساحة | J12: (SR/m²) - ر.س/م² | K12: الإجمالي - (Total)
C13: تكلفة شراء الأرض - باستثناء الضرائب والعمولات (Land purchase cost - except taxes & commissions) | I13: =Study!C49 -> 8216 | J13: =Study!D49 -> 10921.13 | K13: =I13*J13 -> 89728000
C14: التكلفة الإجمالية للمشروع (Total project cost) | I14: =Study!G59 -> 31799.64 | J14: =K14/I14 -> 6941.5896 | K14: =Study!C23 -> 2.2074005e+08
C15: إجمالي الإيرادات (Total Revenue) | I15: =Study!J59 -> 9920.794 | J15: =K15/I15 -> 31568.299 | K15: =Study!C17 -> 3.1318259e+08
C17: نمو قيمة الأرض للمتر - Land Value Uplift per SQM | I17: وقت الشراء | J17: وقت البيع | K17: الفارق
I19: =K95/I13 -> 5980.2824 | J19: =((K95/K14)*K15)/I13 -> 8484.7326 | K19: =J19-I19 -> 2504.4502
C21: المؤشرات المالية | Financial Indicators | H21: معدل العائد الداخلي IRR | I21: العائد على الإستثمار ROI | J21: العائد على الملكية ROE | K21: العائد على الملكية سنوياَ ROE Annualy
H24: =Study!C28 -> 0.13308131 | I24: =Study!C30 -> 0.3892054 | J24: =Study!C32 -> 0.7924872 | K24: =Study!C34 -> 0.15849744
C27: التفاصيل الفنية و المالية لجميع للمكونات | Technical and Financial Details For All Components | D27: عدد الوحدات (Number of Units) | E27: مساحة الوحدة (One Unit Area) | H27: إجمالي تكاليف كل مكون (Total cost per component) | I27: صافي العائد لكل م² بيعي (Net return per NSA.m²) | J27: صافي دخل كل مكون (Net Income per Component) | K27: نسبة عائد كل مكون (Return % per Component)
C29: سكني (Apartments) | D29: =Study!G61 -> 12 | E29: =Study!H61 -> 251.1495 | H29: =Study!AU40 -> 28494043 | I29: =Study!AY4 -> 1102.9575 | J29: =Study!AZ4 -> 3324086.8 | K29: =Study!BD4 -> 0.11716711
C30: فلل (Villas) | D30: =Study!G62 -> 11 | E30: =Study!H62 -> 303.63636 | H30: =Study!AU41 -> 32912707 | I30: =Study!AY5 -> -9854.1038 | J30: =Study!AZ5 -> -32912707 | K30: =Study!BD5 -> -1
C31: تاون هاوس (Townhouse) | D31: =Study!G63 -> 0 | E31: =Study!H63 -> 0.00 | H31: =Study!AU42 -> 0 | I31: =Study!AY6 -> 0.00 | J31: =Study!AZ6 -> 0 | K31: =Study!BD6 -> 0.00%
C32: أدوار (Floors) | D32: =Study!G64 -> 0 | E32: =Study!H64 -> 0.00 | H32: =Study!AU43 -> 0 | I32: =Study!AY7 -> 0.00 | J32: =Study!AZ7 -> 0 | K32: =Study!BD7 -> 0.00%
C33: أستوديوهات (Studios) | D33: =Study!G65 -> 0 | E33: =Study!H65 -> 0.00 | H33: =Study!AU44 -> 0 | I33: =Study!AY8 -> 0.00 | J33: =Study!AZ8 -> 0 | K33: =Study!BD8 -> 0.00%
C34: مكتبي (Office) | D34: =Study!G66 -> 0 | E34: =Study!H66 -> 0.00 | H34: =Study!AU45 -> 0 | I34: =Study!AY9 -> 0.00 | J34: =Study!AZ9 -> 0 | K34: =Study!BD9 -> 0.00%
C35: تجاري (Retail) | D35: =Study!G67 -> 0 | E35: =Study!H67 -> 0.00 | H35: =Study!AU46 -> 0 | I35: =Study!AY10 -> 0.00 | J35: =Study!AZ10 -> 0 | K35: =Study!BD10 -> 0.00%
C36: فندقي (Hotel) | D36: =Study!G68 -> 100 | E36: =Study!H68 -> 35.67 | H36: =Study!AU47 -> 1.4699209e+08 | I36: =Study!AY11 -> 24638.465 | J36: =Study!AZ11 -> 87885405 | K36: =Study!BD11 -> 0.62513472
C37: صحي (health) | D37: =Study!G69 -> 0 | E37: =Study!H69 -> 0.00 | H37: =Study!AU48 -> 0 | I37: =Study!AY12 -> 0.00 | J37: =Study!AZ12 -> 0 | K37: =Study!BD12 -> 0.00%
C38: شاليهات (Chalets) | D38: =Study!G70 -> 0 | E38: =Study!H70 -> 0.00 | H38: =Study!AU49 -> 0 | I38: =Study!AY13 -> 0.00 | J38: =Study!AZ13 -> 0 | K38: =Study!BD13 -> 0.00%
E40: 1 | F40: 2 | G40: 3 | H40: 4 | I40: 5 | J40: 6 | K40: =Study!B122 -> 5
C42: رخصة البناء و التصميم (Design & License) | D42: =Study!C344 -> 46388 | E42: =IF(ABS(SUM(OFFSET(Study!$F$200,0,(COLUMN()-COLUMN($E$42))*4,2,4)))<0.01,"",SUM(OFFSET(Study!$F$200,0,(COLUMN()-COLUMN($E$42))*4,2,4))) -> -2608853.6 | F42: =IF(ABS(SUM(OFFSET(Study!$F$200,0,(COLUMN()-COLUMN($E$42))*4,2,4)))<0.01,"",SUM(OFFSET(Study!$F$200,0,(COLUMN()-COLUMN($E$42))*4,2,4))) -> -1367257.4 | G42: =IF(ABS(SUM(OFFSET(Study!$F$200,0,(COLUMN()-COLUMN($E$42))*4,2,4)))<0.01,"",SUM(OFFSET(Study!$F$200,0,(COLUMN()-COLUMN($E$42))*4,2,4))) | H42: =IF(ABS(SUM(OFFSET(Study!$F$200,0,(COLUMN()-COLUMN($E$42))*4,2,4)))<0.01,"",SUM(OFFSET(Study!$F$200,0,(COLUMN()-COLUMN($E$42))*4,2,4))) | I42: =IF(ABS(SUM(OFFSET(Study!$F$200,0,(COLUMN()-COLUMN($E$42))*4,2,4)))<0.01,"",SUM(OFFSET(Study!$F$200,0,(COLUMN()-COLUMN($E$42))*4,2,4))) | J42: =IF(ABS(SUM(OFFSET(Study!$F$200,0,(COLUMN()-COLUMN($E$42))*4,2,4)))<0.01,"",SUM(OFFSET(Study!$F$200,0,(COLUMN()-COLUMN($E$42))*4,2,4))) | K42: =Study!H344 -> 46934
C43: -------------------------------------------
C44: فوائد التمويل (Interest) | D44: =Study!C345 -> 47027 | E44: =IF(ABS(SUM(OFFSET(Study!$F$192,0,(COLUMN()-COLUMN($E$44))*4,2,4)))<0.0001,"",SUM(OFFSET(Study!$F$192,0,(COLUMN()-COLUMN($E$44))*4,2,4))) -> -271760.03 | F44: =IF(ABS(SUM(OFFSET(Study!$F$192,0,(COLUMN()-COLUMN($E$44))*4,2,4)))<0.0001,"",SUM(OFFSET(Study!$F$192,0,(COLUMN()-COLUMN($E$44))*4,2,4))) -> -46574.109 | G44: =IF(ABS(SUM(OFFSET(Study!$F$192,0,(COLUMN()-COLUMN($E$44))*4,2,4)))<0.0001,"",SUM(OFFSET(Study!$F$192,0,(COLUMN()-COLUMN($E$44))*4,2,4))) -> -551296.44 | H44: =IF(ABS(SUM(OFFSET(Study!$F$192,0,(COLUMN()-COLUMN($E$44))*4,2,4)))<0.0001,"",SUM(OFFSET(Study!$F$192,0,(COLUMN()-COLUMN($E$44))*4,2,4))) -> -2381771.4 | I44: =IF(ABS(SUM(OFFSET(Study!$F$192,0,(COLUMN()-COLUMN($E$44))*4,2,4)))<0.0001,"",SUM(OFFSET(Study!$F$192,0,(COLUMN()-COLUMN($E$44))*4,2,4))) -> -3890501.3 | J44: =IF(ABS(SUM(OFFSET(Study!$F$192,0,(COLUMN()-COLUMN($E$44))*4,2,4)))<0.0001,"",SUM(OFFSET(Study!$F$192,0,(COLUMN()-COLUMN($E$44))*4,2,4))) | K44: =Study!H345 -> 48213
C45: -------------------------------------------
C46: تكاليف البناء (Construction Costs) | D46: =Study!C346 -> 46844 | E46: =IF(ABS(SUM(OFFSET(Study!$F$196,0,(COLUMN()-COLUMN($E$46))*4,1,4)))<0.0001,"",SUM(OFFSET(Study!$F$196,0,(COLUMN()-COLUMN($E$46))*4,1,4))) | F46: =IF(ABS(SUM(OFFSET(Study!$F$196,0,(COLUMN()-COLUMN($E$46))*4,1,4)))<0.0001,"",SUM(OFFSET(Study!$F$196,0,(COLUMN()-COLUMN($E$46))*4,1,4))) -> -16435778 | G46: =IF(ABS(SUM(OFFSET(Study!$F$196,0,(COLUMN()-COLUMN($E$46))*4,1,4)))<0.0001,"",SUM(OFFSET(Study!$F$196,0,(COLUMN()-COLUMN($E$46))*4,1,4))) -> -39915460 | H46: =IF(ABS(SUM(OFFSET(Study!$F$196,0,(COLUMN()-COLUMN($E$46))*4,1,4)))<0.0001,"",SUM(OFFSET(Study!$F$196,0,(COLUMN()-COLUMN($E$46))*4,1,4))) -> -21914370 | I46: =IF(ABS(SUM(OFFSET(Study!$F$196,0,(COLUMN()-COLUMN($E$46))*4,1,4)))<0.0001,"",SUM(OFFSET(Study!$F$196,0,(COLUMN()-COLUMN($E$46))*4,1,4))) | J46: =IF(ABS(SUM(OFFSET(Study!$F$196,0,(COLUMN()-COLUMN($E$46))*4,1,4)))<0.0001,"",SUM(OFFSET(Study!$F$196,0,(COLUMN()-COLUMN($E$46))*4,1,4))) | K46: =Study!H346 -> 47848
C47: -------------------------------------------
C48: الخدمات (Infrastructure services) | D48: =Study!C347 -> 47757 | E48: =IF(ABS(SUM(OFFSET(Study!$F$204,0,(COLUMN()-COLUMN($E$48))*4,3,4)))<0.0001,"",SUM(OFFSET(Study!$F$204,0,(COLUMN()-COLUMN($E$48))*4,3,4))) | F48: =IF(ABS(SUM(OFFSET(Study!$F$204,0,(COLUMN()-COLUMN($E$48))*4,3,4)))<0.0001,"",SUM(OFFSET(Study!$F$204,0,(COLUMN()-COLUMN($E$48))*4,3,4))) | G48: =IF(ABS(SUM(OFFSET(Study!$F$204,0,(COLUMN()-COLUMN($E$48))*4,3,4)))<0.0001,"",SUM(OFFSET(Study!$F$204,0,(COLUMN()-COLUMN($E$48))*4,3,4))) | H48: =IF(ABS(SUM(OFFSET(Study!$F$204,0,(COLUMN()-COLUMN($E$48))*4,3,4)))<0.0001,"",SUM(OFFSET(Study!$F$204,0,(COLUMN()-COLUMN($E$48))*4,3,4))) -> -1914500 | I48: =IF(ABS(SUM(OFFSET(Study!$F$204,0,(COLUMN()-COLUMN($E$48))*4,3,4)))<0.0001,"",SUM(OFFSET(Study!$F$204,0,(COLUMN()-COLUMN($E$48))*4,3,4))) | J48: =IF(ABS(SUM(OFFSET(Study!$F$204,0,(COLUMN()-COLUMN($E$48))*4,3,4)))<0.0001,"",SUM(OFFSET(Study!$F$204,0,(COLUMN()-COLUMN($E$48))*4,3,4))) | K48: =Study!H347 -> 47848
C49: -------------------------------------------
