Workbook

Sheet الدراسة
E1: السدحان 2025-04-20 | AE1: كود الوان الحدود | AF1: الاكواد
E2: الموقع | AE2: #DAD2CC | AF2: #A4907E | AG2: العناوين | AH2: 0 | AI2: الجميع بدون حساب رموز الأخطاء | AJ2: المتوسط الحسابي بدون حساب القيم الصفرية و رموز الأخطاء | AK2: إزالة رموز الخطاء من القسمة
AE3: حجم خط العناوين 10 | AF3: بدون تعبئة | AG3: شكل 1 | AH3: 0 | AI3: =SUMIF(AO1:AO7, "<>#DIV/0!") -> 0 | AJ3: =AVERAGEIFS(AS1:AS7, AS1:AS7, "<>0", AS1:AS7, "<>#DIV/0!") -> #DIV/0! | AK3: {=IFERROR(AN3:AN5/AM3:AM5, "0")} -> 0
AE4: حجم خط الخلايا العادية 8 | AF4: #F0EAE4 | AG4: شكل 2 | AH4: 0 | AK4: 0
AE5: حجم خط الخلايا المنبثقة 7 | AF5: #EDE4D6 | AG5: خلايا الأدخال و الخلايا المتغيرة | AH5: 0 | AK5: 0
AE6: في حالات نادرة يكون حجم الخلايا العادية 7 او 6 بحال عدم وجود مساحة | AF6: اول لون بدرجات الأخضر | AG6: تعقيب | AH6: 0
B15: Feasibility Study Summary | ملخص دراسة الجدوى | F15: Financial Structuring | الهيكلة المالية
B16: البند (Item) | C16: القيمة (Value) | F16: رأس المال - (capital)
B17: إجمالي الإيرادات (Total Revenue) | C17: =SUM(E183:E186) -> 667316475 | F17: المصدر (Source) | G17: SAR | H17: %
B18: إجمالي تكلفة الأرض (Total Land Cost) | C18: =I49 -> 223256250 | F18: (Equity) - الملكية
B19: إجمالي تكلفة البناء (Total Construction Cost) | C19: =J76 -> 181440000 | F19: الاشتراكات النقدية (Cash Subscription) | H19: =G19/$G$34 -> 0
B20: إجمالي التكاليف الأخرى (Total Other cost) | C20: =C101 -> 28577512 | F20: الاشتراك من مدير الصندوق (fund manager's Subscription) | H20: =G20/$G$34 -> 0
B21: إجمالي رسوم الصندوق (Total Fund Fees) | C21: =C106 -> 29224428 | F21: الأشتراك النقدي من المطور (Cash Subscription from Developer) | H21: =G21/$G$34 -> 0
B22: فوائد التمويل (Interest) | C22: =C117 -> 42134525 | F22: الأشتراك العيني من المطور (In-Kind Subscription from Developer) | G22: 0 | H22: =G22/$G$34 -> 0 | I22: 1
B23: التمويل البنكي (Bank Financing) | C23: =G26 -> 259300000 | F23: الإشتراك العيني من مالك الأرض (In-Kind Subscription from Landowner) | G23: =I23*E49 -> 220500000 | H23: =G23/$G$34 -> 0.43695146 | I23: 1
B24: إجمالي تكاليف المشروع (Total project cost) | C24: =SUM(C18:C22) -> 5.0463272e+08 | F24: إجمالي الملكية (Total Equity) | G24: =SUM(G19:G23) -> 220500000 | H24: =G24/$G$34 -> 0.43695146
B25: صافي الدخل (Net Income) | C25: =C17-C24 -> 1.6268376e+08 | F25: التمويل - (Finance)
B26: مدة المشروع المتوقعة - سنوي (Estimated Project Duration - Years) | C26: =D120 -> 3.7863014 | F26: التمويل البنكي (Bank Financing) | G26: =E187 -> 259300000 | H26: =G26/$G$34 -> 0.51383906
B27: معدل العائد الداخلي (IRR) | C27: =C219 -> 0.14642063
B28: العائد على الإستثمار (ROI) | C28: =C25/C24 -> 0.32238053 | F28: تمويل المبيعات - (Sales Financing)
B29: العائد على الملكية (ROE) | C29: =C25/G24 -> 0.73779483 | F29: البيع على الخارطة (Off-Plan Sales) | G29: =J29*I29 -> 0 | H29: =G29/$G$34 -> 0 | I29: =AA140 -> 0 | J29: 1 | K29: =-G35/I29 -> #DIV/0!
B30: العائد على الملكية السنوي (ROE Annually) | C30: =C29/C26 -> 0.19485898 | F30: مصادر أخرى (Other Sources) | G30: =I30*J30 -> 24832715 | H30: =G30/$G$34 -> 0.049209484 | I30: =SUM(J139,L157,AE157) -> 34601595 | J30: 0.71767545 | K30: =-G35/I30 -> 0
F31: إجمالي تمويل المبيعات (Total Sales Financing) | G31: =G30+G29 -> 24832715 | H31: =G31/$G$34 -> 0.049209484
F32: الإجمالي - (Total)
F33: إجمالي مصادر التمويل (Total Financing Sources) | G33: =G24+G26+G31 -> 5.0463272e+08 | H33: =100%=SUM(H24,H26,H31) -> TRUE
F34: إجمالي تكاليف المشروع (Total project cost) | G34: =C113 -> 5.0463272e+08
F35: الفرق (Difference) | G35: =G33-G34 -> 0
B42: تفاصيل الأرض | Land Details
B43: رقم الأرض (Land Number) | C43: المساحة الأرض (Land Area) | D43: التكلفة للمتر (Cost per SQM) | E43: تكلفة الأرض قبل الضرائب (Land Cost Before Taxes) | F43: ضريبة التصرفات العقارية (RETT) | G43: السعي (Commission) | H43: ضريبة السعي (Commission tax) | I43: إجمالي تكلفة الأرض بعد الضرائب (Total Land Cost After Taxes) | J43: معامل البناء (FAR) | K43: إجمالي مسطحات البناء فوق الأرض (Above Grade Gross Building Area)
B44: 1 | C44: 10500 | D44: 21000 | E44: =D44*C44 -> 220500000 | F44: =(E44*$F$50)*$F$51 -> 0 | G44: =(E44*$G$50)*$G$51 -> 2756250 | H44: =(G44*$H$50)*$H$51 -> 0 | I44: =SUM(E44:H44) -> 223256250 | J44: 4 | K44: =J44*C44 -> 42000
B45: 2 | E45: =D45*C45 -> 0 | F45: =(E45*$F$50)*$F$51 -> 0 | G45: =(E45*$G$50)*$G$51 -> 0 | H45: =(G45*$H$50)*$H$51 -> 0 | I45: =SUM(E45:H45) -> 0 | K45: =J45*C45 -> 0
B46: 3 | E46: =D46*C46 -> 0 | F46: =(E46*$F$50)*$F$51 -> 0 | G46: =(E46*$G$50)*$G$51 -> 0 | H46: =(G46*$H$50)*$H$51 -> 0 | I46: =SUM(E46:H46) -> 0 | K46: =J46*C46 -> 0
B47: 4 | E47: =D47*C47 -> 0 | F47: =(E47*$F$50)*$F$51 -> 0 | G47: =(E47*$G$50)*$G$51 -> 0 | H47: =(G47*$H$50)*$H$51 -> 0 | I47: =SUM(E47:H47) -> 0 | K47: =J47*C47 -> 0
B48: 5 | E48: =D48*C48 -> 0 | F48: =(E48*$F$50)*$F$51 -> 0 | G48: =(E48*$G$50)*$G$51 -> 0 | H48: =(G48*$H$50)*$H$51 -> 0 | I48: =SUM(E48:H48) -> 0 | K48: =J48*C48 -> 0
B49: الإجمالي (Total) | C49: =SUM(C44:C48) -> 10500 | D49: =E49/C49 -> 21000 | E49: =SUM(E44:E48) -> 220500000 | F49: =SUM(F44:F48) -> 0 | G49: =SUM(G44:G48) -> 2756250 | H49: =SUM(H44:H48) -> 0 | I49: =SUM(I44:I48) -> 223256250 | J49: =K49/C49 -> 4 | K49: =SUM(K44:K48) -> 42000
F50: 0.05 | G50: 0.025 | H50: 0.15 | K50: =SUM(D61:D71)=K49 -> TRUE
F51: 0 | G51: 0.5 | H51: 0
B57: Construction Details and Costs | تفاصيل البناء و تكاليفة
B58: طول الأرض على الشارع (Land Frontage) | C58: عمق الأرض (Land Depth) | D58: معامل البناء (FAR) | E58: إجمالي المساحة التطويرية (Total Development Area) | F58: إجمالي المساحة المبنية (Gross Built-Up Area) | H58: إجمالي المساحة البنائية فوق مستوى الأرض (Above Grade Gross Building Area) | J58: إجمالي المساحات القابلة للبيع (Net Sellable Area) | K58: المواقف (Parking) | L58: معيار المواقف (Parking Standards)
B59: 0 | C59: 0 | D59: =J49 -> 4 | E59: =SUM(D61:D75) -> 68250 | F59: =SUM(D61:D71,D74:D75) -> 63000 | H59: =SUM(D61:D71) -> 42000 | J59: =F76 -> 35385 | P59: توزيع تكاليف المشروع على المكونات | Cost Breakdown by Component
...

Sheet الملخص
B7: شركة رصف للاستثمار | J7: RASF Investment Co.
B8: =الدراسة!E1 -> السدحان 2025-04-20 | I8: =B8 -> السدحان 2025-04-20
B9: Units shown are SAR except where stated | الوحدات المعروضة هي بالريال سعودي باستثناء ما هو مذكور | D9: NSA.m² : Net Sellable Area|TDA.m² : Total Development Area|LA.m² : Total Land Area NSA.m² | المساحات الصافية القابلة للبيع | TDA.m² : إجمالي المساحة التطويرية | LA.m² : مساحة الأرض الإجمالية
B13: Summary | ملخص
H14: (Area) - المساحة | I14: (SR/m²) - ر.س/م² | J14: الإجمالي - (Total)
B15: Land purchase cost - base price (excl. taxes & commissions) - تكلفة شراء الأرض - السعر الأساسي (باستثناء الضرائب والعمولات) | H15: =الدراسة!C49 -> 10500 | I15: =الدراسة!D49 -> 21000 | J15: =الدراسة!E49 -> 220500000
B16: (Total project cost - including land, works, overheads and fees) - التكلفة الإجمالية للمشروع - بما في ذلك الأرض والأعمال والنفقات العامة والرسوم | H16: =الدراسة!E59 -> 68250 | I16: =J16/H16 -> 7393.8859 | J16: =الدراسة!C24 -> 5.0463272e+08
B17: إجمالي الإيرادات - (Total Revenue) | H17: =الدراسة!J59 -> 35385 | I17: =J17/H17 -> 18858.739 | J17: =الدراسة!C17 -> 667316475
B19: نمو قيمة الأرض - Land Value Uplift | H19: وقت الشراء | I19: وقت البيع | J19: الفارق
H21: =J69/H15 -> 21262.5 | I21: =((J69/J114)*J17)/H15 -> 28117.116 | J21: =I21-H21 -> 6854.6159
B23: المؤشرات المالية | Financial Indicators | C23: معدل العائد الداخلي IRR | E23: العائد على الإستثمار ROI | G23: العائد على الملكية ROE | I23: العائد على الملكية سنوياَ ROE Annualy
C26: =الدراسة!C27 -> 0.14642063 | E26: =الدراسة!C28 -> 0.32238053 | G26: =الدراسة!C29 -> 0.73779483 | I26: =الدراسة!C30 -> 0.19485898
C29: عدد الوحدات (Number of Units) | D29: مساحة الوحدة (Unit Area) | G29: =الدراسة!Q60 -> إجمالي تكاليف كل مكون (Total Cost per Component) | H29: =الدراسة!T60 -> العائد لكل م² (Return per m²) | I29: صافي دخل كل مكون (Net Income per Component) | J29: نسبة عائد كل مكون (Return % per Component)
B30: التفاصيل الفنية و المالية لجميع للمكونات | Technical and Financial Details For All Components
B31: (Apartments) - سكني | C31: =الدراسة!H61 -> 200 | D31: =الدراسة!G61 -> 100.8 | G31: =الدراسة!Q61 -> 2.8294018e+08 | H31: =الدراسة!T61 -> 14917.5 | I31: =الدراسة!U61 -> 17796625 | J31: =الدراسة!V61 -> 0.062898896
B32: مكتبي - (Office) | C32: =الدراسة!H66 -> 17 | D32: =الدراسة!G66 -> 555.88235 | G32: =الدراسة!Q66 -> 1.4056472e+08 | H32: =الدراسة!T66 -> 23760 | I32: =الدراسة!U66 -> 83967275 | J32: =الدراسة!V66 -> 0.59735666
B33: تجاري - (Retail) | C33: =الدراسة!H67 -> 21 | D33: =الدراسة!G67 -> 190 | G33: =الدراسة!Q67 -> 52464567 | H33: =الدراسة!T67 -> 23220 | I33: =الدراسة!U67 -> 40183233 | J33: =الدراسة!V67 -> 0.76591184
B34: صحي - (health) | C34: =الدراسة!H69 -> 2 | D34: =الدراسة!G69 -> 892.5 | G34: =الدراسة!Q69 -> 28728536 | H34: =الدراسة!T69 -> 27675 | I34: =الدراسة!U69 -> 20671339 | J34: =الدراسة!V69 -> 0.71954029
B37: الإطار الزمني (بالسنوات) - Time frame (Years) | C37: 1 | D37: 2 | E37: 3 | F37: 4 | I37: =الدراسة!D120 -> 3.7863014
B38: التكاليف الأخرى - ( Other costs) | C38: =SUM(الدراسة!F195:I208) -> -12153960 | D38: =SUM(الدراسة!J195:M208) -> -4250880 | E38: =SUM(الدراسة!N195:Q208) -> -9601994.6 | F38: =SUM(الدراسة!R195:U208) -> -2570677.3 | G38: =SUM(الدراسة!V195:Y208) -> 0 | H38: =SUM(الدراسة!Z195:AC208) -> 0
B39: تكاليف البناء - (Construction cost) | C39: =SUM(الدراسة!F194:I194) -> -27216000 | D39: =SUM(الدراسة!J194:M194) -> -72576000 | E39: =SUM(الدراسة!N194:Q194) -> -81648000 | F39: =SUM(الدراسة!R194:U194) -> 0 | G39: =SUM(الدراسة!V194:Y194) -> 0 | H39: =SUM(الدراسة!Z194:AC194) -> 0
B40: (Lease-up and wholesale) - التأجير والبيع | C40: =SUM(الدراسة!F183:I185) -> 0 | D40: =SUM(الدراسة!J183:M185) -> 0 | E40: =SUM(الدراسة!N183:Q185) -> 9886170 | F40: =SUM(الدراسة!R183:U185) -> 39544680 | G40: =SUM(الدراسة!V183:Y185) -> 0 | H40: =SUM(الدراسة!Z183:AC185) -> 0
B43: Capital Structure | هيكل رأس المال | I43: % | J43: SR
B44: الإشتراك العيني من مالك الأرض - (In-Kind Subscription from Landowner) | I44: =J44/$J$47 -> 0.43695146 | J44: =الدراسة!G23 -> 220500000
B45: التمويل البنكي - (Bank Financing) | I45: =J45/$J$47 -> 0.51383906 | J45: =الدراسة!G26 -> 259300000
B46: مصادر أخرى - (Other Sources) | I46: =J46/$J$47 -> 0.049209484 | J46: =الدراسة!G30 -> 24832715
B47: Total Funding الإجمالي | I47: =SUM(I44:I46) -> 1 | J47: =SUM(J44:J46) -> 5.0463272e+08
AA67: مصادر أخرى | AB67: =SUM(J46:J46) -> 24832715 | AC67: =AB67/$J$47 -> 0.049209484 | AD67: =الدراسة!B192 -> تكلفة الأرض (Land Cost) | AE67: =-الدراسة!C192 -> 220500000
B68: Cost Breakdown | توزيع التكلفة | I68: SR/TDA.m² | J68: SR | AA68: التمويل | AB68: =J45 -> 259300000 | AC68: =AB68/$J$47 -> 0.51383906 | AD68: =الدراسة!B194 -> تكاليف مسطحات البناء (Construction Costs) | AE68: =-الدراسة!C194 -> 181440000
B69: إجمالي تكلفة الأرض بعد الضرائب - (Tota Land Cost After TAX) | I69: =I70+I71 -> 3271.1538 | J69: =J70+J71 -> 223256250 | AD69: =الدراسة!B195 -> التسوير (Fence - surrounding the land) | AE69: =-الدراسة!C195 -> 525000
B70: (Land Cost Before TAX) - تكلفة الأرض قبل الضرائب | I70: =J70/$H$16 -> 3230.7692 | J70: =الدراسة!E44 -> 220500000 | AA70: اشتراكات نقدية من مالك الأرض | AB70: =+J44 -> 220500000 | AC70: =AB70/J47 -> 0.43695146 | AD70: =الدراسة!B196 -> الحفر والمسح والاختبار (Excavation, surveying, and testing) | AE70: =-الدراسة!C196 -> 3024000
B71: (Commissions) - العمولة | I71: =J71/$H$16 -> 40.384615 | J71: =الدراسة!G44 -> 2756250 | AD71: =الدراسة!B197 -> التأمين (Insurance) | AE71: =-الدراسة!C197 -> 3084480
AA72: =AA67 -> مصادر أخرى | AB72: =AB67 -> 24832715 | AD72: =الدراسة!B200 -> أثاث الوحدات الفندقية (Apartment furniture) | AE72: =-الدراسة!C200 -> 0
B73: (Development) - التطوير | I73: =I74+I75+I76 -> 3359.0386 | J73: =J74+J75+J76 -> 2.2925438e+08 | AA73: =AA68 -> التمويل | AB73: =AB68 -> 259300000 | AD73: =الدراسة!B201 -> أثاث الوحدات (Apartment furniture) | AE73: =-الدراسة!C201 -> 0
B74: (Hard Cost - Construction) - تكلفة البناء | I74: =J74/$H$16 -> 2658.4615 | J74: =الدراسة!C19 -> 181440000 | AA74: الملكية | AB74: =AB69+AB70 -> 220500000 | AD74: =الدراسة!B202 -> رسوم كهرباء (Electricity fees) | AE74: =-الدراسة!C202 -> 2676000
B75: Soft Costs (Fees,Consultants, Insurance, Permits, Overheads etc) - التكاليف الأخرى | I75: =J75/$H$16 -> 408.57846 | J75: =الدراسة!C101-الدراسة!C98-الدراسة!C99 -> 27885480 | AD75: =الدراسة!B203 -> رسوم الماء وصرف الصحي (Water and sewer fees) | AE75: =-الدراسة!C203 -> 1440000
B76: 0.12 | I76: =J76/$H$16 -> 291.99858 | J76: =الدراسة!C103 -> 19928903 | AD76: =الدراسة!B204 -> الفرز (Sorting) | AE76: =-الدراسة!C204 -> 240000
AD77: =الدراسة!B205 -> الصيانة و التشغيل (Maintenance and Operation) | AE77: =-الدراسة!C205 -> 3120000
B78: Marketing (RASF) - التسويق | I78: =J78/H16 -> 10.139662 | J78: =الدراسة!C98+الدراسة!C99 -> 692031.9 | AD78: =الدراسة!B206 -> الاحتياطي (Contingency) | AE78: =-الدراسة!C206 -> 3628800
AD79: =الدراسة!B207 -> التسويق المبيعات والتأجير (Sales and Leasing Marketing) | AE79: =-الدراسة!C207 -> 692031.9
...
