Workbook
Name AuditFailsCommercial: [1]Audit!$G$12
Name AuditFailsStructural: [1]Audit!$G$11
Name AuditOK: [1]Audit!$G$13

Sheet Study
AE1: توزيع تكاليف المشروع على مكونات البيع المباشر و التأجير السنوي و اليومي | BH1: جدول المؤشرات العامة للمشروع | General Project Indicators Table | BK1: الحدود المرجعية أو المثلى للمؤشرات (Reference Ranges for Indicators) | BN1: سعر المتر بناءً على فترة الاسترداد - (التأجير السنوي) | BQ1: سعر المتر بناءً على فترة الاسترداد - (التأجير اليومي) | BV1: اسم المشروع | BW1: =E1 -> 0 | CA1: حالة المشروع | CB1: تاريخ الانتهاء المتوقع
C2: Disclaimer This Excel model is intended exclusively for internal use by Rasf Investment. Unauthorized use or distribution for any other purpose is strictly prohibited | E2: اسم المشروع | AE2: المكون | AF2: توزيع تكاليف الأرض | AG2: تكاليف البناء | AH2: نسبة توزيع تكاليف اللاند سكيب | AI2: توزيع تكاليف اللاندسكيب | AJ2: توزيع تكاليف البوديم و القبو | AK2: توزيع تكاليف الحفر والمسح و الاختبار | AL2: توزيع تكاليف المساحات الحركية والخدمية | AM2: نسب التكاليف السابقة من التكاليف الموجودة بالجدول | AN2: نسب التكاليف السابقة من التكاليف الكلية | AO2: نسب المكون من البيع المباشر أو المخارجة من الإجمالي | AP2: توزيع التكاليف الأخرى | AQ2: توزيع تكاليف أخرى إضافية | AR2: توزيع تكاليف التمويل | AS2: توزيع تكاليف الصندوق | AT2: توزيع التكاليف التشغيلية | AU2: إجمالي تكاليف كل مكون | AV2: توزيع التكلفة على الأمتار البيعية | AW2: نسبة تكاليف كل مكون من إجمالي المشروع | AX2: إجمالي إيراد كل مكون | AY2: صافي العائد لكل م² بيعي | AZ2: صافي دخل كل مكون | BA2: العائد النسبي للمكون | BB2: هامش الربح من إجمالي الإرادات | BC2: نسبة صافي دخل كل مكون من إجمالي صافي دخل المشروع | BD2: نسبة صافي دخل كل مكون | BN2: المكون (Component) | BO2: سعر المتر | BP2: فترة الأسترداد - بالسنوات | BQ2: المكون (Component) | BR2: سعر المتر | BS2: فترة الأسترداد - بالسنوات | BV2: اسم الصندوق | BW2: ? | CA2: مرحلة توقيع العقود | CB2: ?
E3: موقع المشروع | AE3: سكني | AF3: =((F61/$J$59)*$I$49)*AO3 -> 1.2635729e+08 | AG3: =J61*AO3 -> 63987456 | AI3: =($J$73*AH3)*AO3 -> 0 | AJ3: =((K61/$L$76)*($J$74+$J$75))*AO3 -> 12710294 | AK3: =((K61/$L$76)*$C$87)*AO3 -> 1286917.2 | AL3: =(((D61-F61)/$H$59)*$J$71)*AO3 -> 0 | AM3: =SUM(AF3:AG3,AI3:AL3)/$AM$13 -> 0.40476872 | AN3: =SUM(AF3:AG3,AI3:AL3)/$AN$13 -> 0.31875422 | AO3: =D129 -> 0.6 | AP3: =(AN3*SUM($C$86,$C$88:$C$90,$C$96:$C$97,$C$101))+((H147+X147)/($H$157+$X$157))*$C$99+(SUM($D$93:$D$95)*H61*AO3) -> 12471106 | AQ3: =(($A$92+$C$98)*AM3) -> 2877525.7 | AR3: =AM3*$C$119 -> 4584973.6 | AS3: =AN3*$C$107 -> 15468726 | AT3: =SUM(I147,Y147) -> 0 | AU3: =SUM(AF3:AG3,AI3:AL3,AP3:AT3) -> 2.3974429e+08 | AV3: =IFERROR((AU3-AT3)/E129, "0") -> 14105.37 | AW3: =(AU3-AT3)/($C$24) -> 0.31430824 | AX3: =SUM(J129,H147,O129,X147) -> 2.1245835e+08 | AY3: =IFERROR(AZ3/E129, "0") -> -1605.37 | AZ3: =AX3-AU3 -> -27285941 | BA3: =IFERROR(BD3/AW3, "0.00") -> -0.36210531 | BB3: =IFERROR(AZ3/AX3, "0.00%") -> -0.1284296 | BC3: =AZ3/$C$26 -> -0.10119479 | BD3: =IFERROR(AZ3/(AU3-AT3), "0.00%") -> -0.11381268 | BN3: سكني (Apartments) | BO3: =IFERROR((AU3-AT3) / (C147 * D147 * G147 * (1 - $I$158) * BP3), 0) -> 0 | BQ3: سكني (Apartments) | BR3: =IFERROR((AU3-AT3) / ((R147 * S147 * (1 - $Y$158) * 365 * BS3) * (1 + W147)), 0) -> 0 | BV3: إجمالي تكاليف البناء | BW3: =J76 -> 286502320
AE4: فلل | AF4: =((F62/$J$59)*$I$49)*AO4 -> 0 | AG4: =J62*AO4 -> 0 | AI4: =($J$73*AH4)*AO4 -> 0 | AJ4: =((K62/$L$76)*($J$74+$J$75))*AO4 -> 0 | AK4: =((K62/$L$76)*$C$87)*AO4 -> 0 | AL4: =(((D62-F62)/$H$59)*$J$71)*AO4 -> 0 | AM4: =SUM(AF4:AG4,AI4:AL4)/$AM$13 -> 0 | AN4: =SUM(AF4:AG4,AI4:AL4)/$AN$13 -> 0 | AO4: =D130 -> 1 | AP4: =(AN4*SUM($C$86,$C$88:$C$90,$C$96:$C$97,$C$101))+((H148+X148)/($H$157+$X$157))*$C$99+(SUM($D$93:$D$95)*H62*AO4) -> 0 | AQ4: =(($A$92+$C$98)*AM4) -> 0 | AR4: =AM4*$C$119 -> 0 | AS4: =AN4*$C$107 -> 0 | AT4: =SUM(I148,Y148) -> 0 | AU4: =SUM(AF4:AG4,AI4:AL4,AP4:AT4) -> 0 | AV4: =IFERROR((AU4-AT4)/E130, "0") -> 0 | AW4: =(AU4-AT4)/($C$24) -> 0 | AX4: =SUM(J130,H148,O130,X148) -> 0 | AY4: =IFERROR(AZ4/E130, "0") -> 0 | AZ4: =AX4-AU4 -> 0 | BA4: =IFERROR(BD4/AW4, "0.00") -> 0.00 | BB4: =IFERROR(AZ4/AX4, "0.00%") -> 0.00% | BC4: =AZ4/$C$26 -> 0 | BD4: =IFERROR(AZ4/(AU4-AT4), "0.00%") -> 0.00% | BH4: مؤشرات التكاليف والكفاءة (Costs & Efficiency Indicators) | BN4: فلل (Villas) | BO4: =IFERROR((AU4-AT4) / (C148 * D148 * G148 * (1 - $I$158) * BP4), 0) -> 0 | BQ4: فلل (Villas) | BR4: =IFERROR((AU4-AT4) / ((R148 * S148 * (1 - $Y$158) * 365 * BS4) * (1 + W148)), 0) -> 0 | BV4: تكلفة اجمالي المشروع | BW4: =C24 -> 7.6276806e+08
AE5: تاون هاوس | AF5: =((F63/$J$59)*$I$49)*AO5 -> 0 | AG5: =J63*AO5 -> 0 | AI5: =($J$73*AH5)*AO5 -> 0 | AJ5: =((K63/$L$76)*($J$74+$J$75))*AO5 -> 0 | AK5: =((K63/$L$76)*$C$87)*AO5 -> 0 | AL5: =(((D63-F63)/$H$59)*$J$71)*AO5 -> 0 | AM5: =SUM(AF5:AG5,AI5:AL5)/$AM$13 -> 0 | AN5: =SUM(AF5:AG5,AI5:AL5)/$AN$13 -> 0 | AO5: =D131 -> 1 | AP5: =(AN5*SUM($C$86,$C$88:$C$90,$C$96:$C$97,$C$101))+((H149+X149)/($H$157+$X$157))*$C$99+(SUM($D$93:$D$95)*H63*AO5) -> 0 | AQ5: =(($A$92+$C$98)*AM5) -> 0 | AR5: =AM5*$C$119 -> 0 | AS5: =AN5*$C$107 -> 0 | AT5: =SUM(I149,Y149) -> 0 | AU5: =SUM(AF5:AG5,AI5:AL5,AP5:AT5) -> 0 | AV5: =IFERROR((AU5-AT5)/E131, "0") -> 0 | AW5: =(AU5-AT5)/($C$24) -> 0 | AX5: =SUM(J131,H149,O131,X149) -> 0 | AY5: =IFERROR(AZ5/E131, "0") -> 0 | AZ5: =AX5-AU5 -> 0 | BA5: =IFERROR(BD5/AW5, "0.00") -> 0.00 | BB5: =IFERROR(AZ5/AX5, "0.00%") -> 0.00% | BC5: =AZ5/$C$26 -> 0 | BD5: =IFERROR(AZ5/(AU5-AT5), "0.00%") -> 0.00% | BE5: تاون هاوس | BH5: التكلفة لكل م² من إجمالي المساحات التطويرية (Cost per m² of Total Built-Up Area) | BI5: =C24/E59 -> 7649.8653 | BK5: - | BN5: تاون هاوس (Townhouse) | BO5: =IFERROR((AU5-AT5) / (C149 * D149 * G149 * (1 - $I$158) * BP5), 0) -> 0 | BQ5: تاون هاوس (Townhouse) | BR5: =IFERROR((AU5-AT5) / ((R149 * S149 * (1 - $Y$158) * 365 * BS5) * (1 + W149)), 0) -> 0 | BV5: ايرادات المشروع | BW5: =SUM(J139,O139,AC139) -> 9.7915176e+08
AE6: أدوار | AF6: =((F64/$J$59)*$I$49)*AO6 -> 0 | AG6: =J64*AO6 -> 0 | AI6: =($J$73*AH6)*AO6 -> 0 | AJ6: =((K64/$L$76)*($J$74+$J$75))*AO6 -> 0 | AK6: =((K64/$L$76)*$C$87)*AO6 -> 0 | AL6: =(((D64-F64)/$H$59)*$J$71)*AO6 -> 0 | AM6: =SUM(AF6:AG6,AI6:AL6)/$AM$13 -> 0 | AN6: =SUM(AF6:AG6,AI6:AL6)/$AN$13 -> 0 | AO6: =D132 -> 1 | AP6: =(AN6*SUM($C$86,$C$88:$C$90,$C$96:$C$97,$C$101))+((H150+X150)/($H$157+$X$157))*$C$99+(SUM($D$93:$D$95)*H64*AO6) -> 0 | AQ6: =(($A$92+$C$98)*AM6) -> 0 | AR6: =AM6*$C$119 -> 0 | AS6: =AN6*$C$107 -> 0 | AT6: =SUM(I150,Y150) -> 0 | AU6: =SUM(AF6:AG6,AI6:AL6,AP6:AT6) -> 0 | AV6: =IFERROR((AU6-AT6)/E132, "0") -> 0 | AW6: =(AU6-AT6)/($C$24) -> 0 | AX6: =SUM(J132,H150,O132,X150) -> 0 | AY6: =IFERROR(AZ6/E132, "0") -> 0 | AZ6: =AX6-AU6 -> 0 | BA6: =IFERROR(BD6/AW6, "0.00") -> 0.00 | BB6: =IFERROR(AZ6/AX6, "0.00%") -> 0.00% | BC6: =AZ6/$C$26 -> 0 | BD6: =IFERROR(AZ6/(AU6-AT6), "0.00%") -> 0.00% | BE6: أدوار | BH6: التكلفة لكل م² من إجمالي المساحات القابلة للبيع (Cost per m² of Saleable Area) | BI6: =C24/J59 -> 16308.067 | BK6: - | BN6: أدوار (Floors) | BO6: =IFERROR((AU6-AT6) / (C150 * D150 * G150 * (1 - $I$158) * BP6), 0) -> 0 | BQ6: أدوار (Floors) | BR6: =IFERROR((AU6-AT6) / ((R150 * S150 * (1 - $Y$158) * 365 * BS6) * (1 + W150)), 0) -> 0 | BV6: العائد على الملكية | BW6: =C32 -> 0.64943213
AE7: أستوديوهات | AF7: =((F65/$J$59)*$I$49)*AO7 -> 0 | AG7: =J65*AO7 -> 0 | AI7: =($J$73*AH7)*AO7 -> 0 | AJ7: =((K65/$L$76)*($J$74+$J$75))*AO7 -> 0 | AK7: =((K65/$L$76)*$C$87)*AO7 -> 0 | AL7: =(((D65-F65)/$H$59)*$J$71)*AO7 -> 0 | AM7: =SUM(AF7:AG7,AI7:AL7)/$AM$13 -> 0 | AN7: =SUM(AF7:AG7,AI7:AL7)/$AN$13 -> 0 | AO7: =D133 -> 1 | AP7: =(AN7*SUM($C$86,$C$88:$C$90,$C$96:$C$97,$C$101))+((H151+X151)/($H$157+$X$157))*$C$99+(SUM($D$93:$D$95)*H65*AO7) -> 0 | AQ7: =(($A$92+$C$98)*AM7) -> 0 | AR7: =AM7*$C$119 -> 0 | AS7: =AN7*$C$107 -> 0 | AT7: =SUM(I151,Y151) -> 0 | AU7: =SUM(AF7:AG7,AI7:AL7,AP7:AT7) -> 0 | AV7: =IFERROR((AU7-AT7)/E133, "0") -> 0 | AW7: =(AU7-AT7)/($C$24) -> 0 | AX7: =SUM(J133,H151,O133,X151) -> 0 | AY7: =IFERROR(AZ7/E133, "0") -> 0 | AZ7: =AX7-AU7 -> 0 | BA7: =IFERROR(BD7/AW7, "0.00") -> 0.00 | BB7: =IFERROR(AZ7/AX7, "0.00%") -> 0.00% | BC7: =AZ7/$C$26 -> 0 | BD7: =IFERROR(AZ7/(AU7-AT7), "0.00%") -> 0.00% | BE7: أستوديوهات | BH7: إجمالي التكاليف المباشرة (Total Direct Costs) | BI7: =-SUM(C196,C194) -> 624502320 | BJ7: =BI7/$C$24 -> 0.8187316 | BK7: غالبًا تمثل 70% – 85% من إجمالي التكاليف | BN7: أستوديوهات (Studios) | BO7: =IFERROR((AU7-AT7) / (C151 * D151 * G151 * (1 - $I$158) * BP7), 0) -> 0 | BQ7: أستوديوهات (Studios) | BR7: =IFERROR((AU7-AT7) / ((R151 * S151 * (1 - $Y$158) * 365 * BS7) * (1 + W151)), 0) -> 0
AE8: مكتبي | AF8: =((F66/$J$59)*$I$49)*AO8 -> 50833394 | AG8: =J66*AO8 -> 19306560 | AI8: =($J$73*AH8)*AO8 -> 0 | AJ8: =((K66/$L$76)*($J$74+$J$75))*AO8 -> 26336267 | AK8: =((K66/$L$76)*$C$87)*AO8 -> 2666547.1 | AL8: =(((D66-F66)/$H$59)*$J$71)*AO8 -> 0 | AM8: =SUM(AF8:AG8,AI8:AL8)/$AM$13 -> 0.19638596 | AN8: =SUM(AF8:AG8,AI8:AL8)/$AN$13 -> 0.15465339 | AO8: =D134 -> 1 | AP8: =(AN8*SUM($C$86,$C$88:$C$90,$C$96:$C$97,$C$101))+((H152+X152)/($H$157+$X$157))*$C$99+(SUM($D$93:$D$95)*H66*AO8) -> 5731009.9 | AQ8: =(($A$92+$C$98)*AM8) -> 1396119.8 | AR8: =AM8*$C$119 -> 2224540.5 | AS8: =AN8*$C$107 -> 7505126.8 | AT8: =SUM(I152,Y152) -> 697449.48 | AU8: =SUM(AF8:AG8,AI8:AL8,AP8:AT8) -> 1.1669701e+08 | AV8: =IFERROR((AU8-AT8)/E134, "0") -> 16964.606 | AW8: =(AU8-AT8)/($C$24) -> 0.15207711 | AX8: =SUM(J134,H152,O134,X152) -> 1.7959324e+08 | AY8: =IFERROR(AZ8/E134, "0") -> 9198.394 | AZ8: =AX8-AU8 -> 62896226 | BA8: =IFERROR(BD8/AW8, "0.00") -> 3.5653681 | BB8: =IFERROR(AZ8/AX8, "0.00%") -> 0.35021489 | BC8: =AZ8/$C$26 -> 0.23326189 | BD8: =IFERROR(AZ8/(AU8-AT8), "0.00%") -> 0.54221088 | BE8: مكتبي | BH8: إجمالي التكاليف غير المباشرة (Total Indirect Costs) | BI8: =-SUM(E192:E193,E195,E197:E212,E214:E216) -> 1.3826574e+08 | BJ8: =BI8/$C$24 -> 0.1812684 | BK8: من 15% إلى 25% من إجمالي التكاليف غالبًا | BN8: مكتبي (Office) | BO8: =IFERROR((AU8-AT8) / (C152 * D152 * G152 * (1 - $I$158) * BP8), 0) -> 0 | BQ8: مكتبي (Office) | BR8: =IFERROR((AU8-AT8) / ((R152 * S152 * (1 - $Y$158) * 365 * BS8) * (1 + W152)), 0) -> 0 | BV8: اشتراكات رصف | BW8: نسبة الحصة | BX8: مبلغ الاشتراك | BY8: الآلية | BZ8: مبلغ الربح | CA8: الإجمالي | CB8: ملاحظات
AE9: تجاري | AF9: =((F67/$J$59)*$I$49)*AO9 -> 36309567 | AG9: =J67*AO9 -> 13790400 | AH9: 0.4 | AI9: =($J$73*AH9)*AO9 -> 2704000 | AJ9: =((K67/$L$76)*($J$74+$J$75))*AO9 -> 10450900 | AK9: =((K67/$L$76)*$C$87)*AO9 -> 1058153.6 | AL9: =(((D67-F67)/$H$59)*$J$71)*AO9 -> 0 | AM9: =SUM(AF9:AG9,AI9:AL9)/$AM$13 -> 0.1273938 | AN9: =SUM(AF9:AG9,AI9:AL9)/$AN$13 -> 0.10032226 | AO9: =D135 -> 1 | AP9: =(AN9*SUM($C$86,$C$88:$C$90,$C$96:$C$97,$C$101))+((H153+X153)/($H$157+$X$157))*$C$99+(SUM($D$93:$D$95)*H67*AO9) -> 4040531.1 | AQ9: =(($A$92+$C$98)*AM9) -> 905650.36 | AR9: =AM9*$C$119 -> 1443039.4 | AS9: =AN9*$C$107 -> 4868508.1 | AT9: =SUM(I153,Y153) -> 498178.2 | AU9: =SUM(AF9:AG9,AI9:AL9,AP9:AT9) -> 76068927 | AV9: =IFERROR((AU9-AT9)/E135, "0") -> 15472.81 | AW9: =(AU9-AT9)/($C$24) -> 0.099074349 | AX9: =SUM(J135,H153,O135,X153) -> 1.2828089e+08 | AY9: =IFERROR(AZ9/E135, "0") -> 10690.19 | AZ9: =AX9-AU9 -> 52211959 | BA9: =IFERROR(BD9/AW9, "0.00") -> 6.9735679 | BB9: =IFERROR(AZ9/AX9, "0.00%") -> 0.40701277 | BC9: =AZ9/$C$26 -> 0.19363738 | BD9: =IFERROR(AZ9/(AU9-AT9), "0.00%") -> 0.6909017 | BE9: تجاري | BH9: إجمالي التكاليف التشغيلية (Total Operating Costs) | BI9: =C25 -> 10776878 | BJ9: =BI9/SUM(C24:C25) -> 0.013931806 | BK9: - | BN9: تجاري (Retail) | BO9: =IFERROR((AU9-AT9) / (C153 * D153 * G153 * (1 - $I$158) * BP9), 0) -> 0 | BQ9: تجاري (Retail) | BR9: =IFERROR((AU9-AT9) / ((R153 * S153 * (1 - $Y$158) * 365 * BS9) * (1 + W153)), 0) -> 0 | BV9: الحصة العينية من التطوير | BW9: 1 | BX9: =H22*BW9 -> 17190139 | BY9: استثمار عيني | BZ9: =BX9*BW6 -> 11163829 | CA9: =BZ9+BX9 -> 28353968
AE10: فندقي | AF10: =((F68/$J$59)*$I$49)*AO10 -> 49979051 | AG10: =J68*AO10 -> 72399600 | AH10: 0.6 | AI10: =($J$73*AH10)*AO10 -> 4056000 | AJ10: =((K68/$L$76)*($J$74+$J$75))*AO10 -> 9629010.3 | AK10: =((K68/$L$76)*$C$87)*AO10 -> 974937.29 | AL10: =(((D68-F68)/$H$59)*$J$71)*AO10 -> 0 | AM10: =SUM(AF10:AG10,AI10:AL10)/$AM$13 -> 0.27145153 | AN10: =SUM(AF10:AG10,AI10:AL10)/$AN$13 -> 0.21376732 | AO10: =D136 -> 1 | AP10: =(AN10*SUM($C$86,$C$88:$C$90,$C$96:$C$97,$C$101))+((H154+X154)/($H$157+$X$157))*$C$99+((SUM($D$94:$D$95)*H68*AO10)+(D93*H68/2*AO10)) -> 10140899 | AQ10: =((($C$98)*AM10))+C91 -> 12272566 | AR10: =AM10*$C$119 -> 3074837.6 | AS10: =AN10*$C$107 -> 10373848 | AT10: =SUM(I154,Y154) -> 9581250 | AU10: =SUM(AF10:AG10,AI10:AL10,AP10:AT10) -> 1.82482e+08 | AV10: =IFERROR((AU10-AT10)/E136, "0") -> 25718.486 | AW10: =(AU10-AT10)/($C$24) -> 0.22667539 | AX10: =SUM(J136,H154,O136,X154) -> 3.7648676e+08 | AY10: =IFERROR(AZ10/E136, "0") -> 28857.647 | AZ10: =AX10-AU10 -> 1.9400477e+08 | BA10: =IFERROR(BD10/AW10, "0.00") -> 4.9500679 | BB10: =IFERROR(AZ10/AX10, "0.00%") -> 0.51530302 | BC10: =AZ10/$C$26 -> 0.71950132 | BD10: =IFERROR(AZ10/(AU10-AT10), "0.00%") -> 1.1220586 | BE10: فندقي | BH10: إجمالي قيمة ونسبة تكاليف الأرض من إجمالي تكاليف المشروع (Land Cost as Value and % of Total Project Cost) | BI10: =I49 -> 347717500 | BJ10: =BI10/$C$24 -> 0.45586269 | BK10: من 10% إلى 25% غالبًا | BN10: فندقي (Hotel) | BO10: =IFERROR((AU10-AT10) / (C154 * D154 * G154 * (1 - $I$158) * BP10), 0) -> 0 | BQ10: فندقي (Hotel) | BR10: =IFERROR((AU10-AT10) / ((R154 * S154 * (1 - $Y$158) * 365 * BS10) * (1 + W154)), 0) -> 0 | BV10: الحصة من التطوير | BW10: 0 | BX10: =H22*BW10 -> 0 | BZ10: =BX10*BW7 -> 0 | CA10: =BZ10+BX10 -> 0
AE11: صحي | AF11: =((F69/$J$59)*$I$49)*AO11 -> 0 | AG11: =J69*AO11 -> 0 | AI11: =($J$73*AH11)*AO11 -> 0 | AJ11: =((K69/$L$76)*($J$74+$J$75))*AO11 -> 0 | AK11: =((K69/$L$76)*$C$87)*AO11 -> 0 | AL11: =(((D69-F69)/$H$59)*$J$71)*AO11 -> 0 | AM11: =SUM(AF11:AG11,AI11:AL11)/$AM$13 -> 0 | AN11: =SUM(AF11:AG11,AI11:AL11)/$AN$13 -> 0 | AO11: =D137 -> 1 | AP11: =(AN11*SUM($C$86,$C$88:$C$90,$C$96:$C$97,$C$101))+((H155+X155)/($H$157+$X$157))*$C$99+(SUM($D$93:$D$95)*H69*AO11) -> 0 | AQ11: =(($A$92+$C$98)*AM11) -> 0 | AR11: =AM11*$C$119 -> 0 | AS11: =AN11*$C$107 -> 0 | AT11: =SUM(I155,Y155) -> 0 | AU11: =SUM(AF11:AG11,AI11:AL11,AP11:AT11) -> 0 | AV11: =IFERROR((AU11-AT11)/E137, "0") -> 0 | AW11: =(AU11-AT11)/($C$24) -> 0 | AX11: =SUM(J137,H155,O137,X155) -> 0 | AY11: =IFERROR(AZ11/E137, "0") -> 0 | AZ11: =AX11-AU11 -> 0 | BA11: =IFERROR(BD11/AW11, "0.00") -> 0.00 | BB11: =IFERROR(AZ11/AX11, "0.00%") -> 0.00% | BC11: =AZ11/$C$26 -> 0 | BD11: =IFERROR(AZ11/(AU11-AT11), "0.00%") -> 0.00% | BE11: صحي | BH11: إجمالي قيمة ونسبة تكاليف البناء من إجمالي تكاليف المشروع (Construction Cost as Value and % of Total Project Cost) | BI11: =J76 -> 286502320 | BJ11: =BI11/$C$24 -> 0.3756087 | BK11: غالبًا بين 45% إلى 65% | BN11: صحي (health) | BO11: =IFERROR((AU11-AT11) / (C155 * D155 * G155 * (1 - $I$158) * BP11), 0) -> 0 | BQ11: صحي (health) | BR11: =IFERROR((AU11-AT11) / ((R155 * S155 * (1 - $Y$158) * 365 * BS11) * (1 + W155)), 0) -> 0 | BV11: الحصة العينية من المقاولات | BW11: 1 | BX11: =E104*C196*BW11 -> 0 | BZ11: =BW6*$C$7 -> 0 | CA11: =BZ11+BX11 -> 0
AE12: أخرى (Other) | AF12: =((F70/$J$59)*$I$49)*AO12 -> 0 | AG12: =J70*AO12 -> 0 | AI12: =($J$73*AH12)*AO12 -> 0 | AJ12: =((K70/$L$76)*($J$74+$J$75))*AO12 -> 0 | AK12: =((K70/$L$76)*$C$87)*AO12 -> 0 | AL12: =(((D70-F70)/$H$59)*$J$71)*AO12 -> 0 | AM12: =SUM(AF12:AG12,AI12:AL12)/$AM$13 -> 0 | AN12: =SUM(AF12:AG12,AI12:AL12)/$AN$13 -> 0 | AO12: =D138 -> 1 | AP12: =(AN12*SUM($C$86,$C$88:$C$90,$C$96:$C$97,$C$101))+((H156+X156)/($H$157+$X$157))*$C$99+(SUM($D$93:$D$95)*H70*AO12) -> 26901.623 | AQ12: =(($A$92+$C$98)*AM12) -> 0 | AR12: =AM12*$C$119 -> 0 | AS12: =AN12*$C$107 -> 0 | AT12: =SUM(I156,Y156) -> 0 | AU12: =SUM(AF12:AG12,AI12:AL12,AP12:AT12) -> 26901.623 | AV12: =IFERROR((AU12-AT12)/E138, "0") -> 0 | AW12: =(AU12-AT12)/($C$24) -> 3.5268418e-05 | AX12: =SUM(J138,H156,O138,X156) -> 27414035 | AY12: =IFERROR(AZ12/E138, "0") -> 0 | AZ12: =AX12-AU12 -> 27387133 | BA12: =IFERROR(BD12/AW12, "0.00") -> 28865701 | BB12: =IFERROR(AZ12/AX12, "0.00%") -> 0.99901869 | BC12: =AZ12/$C$26 -> 0.10157007 | BD12: =IFERROR(AZ12/(AU12-AT12), "0.00%") -> 1018.0476 | BE12: شاليهات | BH12: إجمالي قيمة ونسبة التكاليف الأخرى من إجمالي تكاليف المشروع (Other Costs as % of Total Project Cost) | BI12: =C102 -> 68692160 | BJ12: =BI12/$C$24 -> 0.090056419 | BK12: غالبًا بين 10% – 20% | BN12: شاليهات (Chalets) | BO12: =IFERROR((AU12-AT12) / (C156 * D156 * G156 * (1 - $I$158) * BP12), 0) -> 0 | BQ12: شاليهات (Chalets) | BR12: =IFERROR((AU12-AT12) / ((R156 * S156 * (1 - $Y$158) * 365 * BS12) * (1 + W156)), 0) -> 0 | BV12: الحصة من المقاولات | BW12: 0 | BX12: =E104*C196*BW12 -> 0 | BZ12: =BW7*$C$7 -> 0 | CA12: =BZ12+BX12 -> 0
AE13: الإجمالي | AF13: =SUMIF(AF3:AF12, "<>#DIV/0!") -> 2.634793e+08 | AG13: =SUMIF(AG3:AG12, "<>#DIV/0!") -> 169484016 | AH13: =SUM(AH3:AH12) -> 1 | AI13: =SUM(AI3:AI12) -> 6760000 | AJ13: =SUMIF(AJ3:AJ12, "<>#DIV/0!") -> 59126471 | AK13: =SUMIF(AK3:AK12, "<>#DIV/0!") -> 5986555.2 | AL13: =SUM(AL3:AL12) -> 0 | AM13: =SUM(AF13:AG13,AI13:AL13) -> 5.0483635e+08 | AN13: =SUM(AF3:AG12,AI3:AL12,AF21:AG30,AI21:AL30) -> 641064320 | AO13: - | AP13: =SUM(AP3:AQ12) -> 49862309 | AR13: =SUMIF(AR3:AR12, "<>#DIV/0!") -> 11327391 | AS13: =SUMIF(AS3:AS12, "<>#DIV/0!") -> 38216209 | AT13: =SUM(AT3:AT12) -> 10776878 | AU13: =SUM(AU3:AU12) -> 6.1501913e+08 | AV13: =IFERROR(AU13/E139, "0") -> 17353.163 | AW13: =SUMIF(AW3:AW12, "<>#DIV/0!") -> 0.79217037 | AX13: =SUMIF(AX3:AX12, "<>#DIV/0!") -> 9.2423328e+08 | AY13: =AZ13/E139 -> 8724.6771 | AZ13: =SUMIF(AZ3:AZ12, "<>#DIV/0!") -> 3.0921414e+08 | BB13: =IFERROR(AZ13/AX13, "0.00%") -> 0.33456288 | BC13: - | BD13: =IFERROR(AZ13/AU13, "0.00%") -> 0.50277158 | BH13: إجمالي قيمة ونسبة تكاليف فوائد التمويل من إجمالي تكاليف المشروع (Financing Interest as Value and % of Total Project Cost) | BI13: =C119 -> 11327391 | BJ13: =BI13/$C$24 -> 0.014850374 | BK13: من 5% – 12% حسب مدة التمويل والفوائد | BV13: العمولات 2.5% من المبيعات | BW13: لا ينطبق | BX13: - | BY13: مخارجة | BZ13: =(SUM(C184,C187,C188)*2.5%) -> 24478794 | CA13: =BZ13 -> 24478794
AE14: T & F | AF14: =(AF13+AF31)=I49 -> TRUE | AG14: =(AG13+AG31)=SUM(J61:J71) -> TRUE | AH14: =AH13=100% -> TRUE | AI14: =(AI13+AI31)=SUM(J73) -> TRUE | AJ14: =(AJ13+AJ31)=SUM(J74:J75) -> TRUE | AK14: =(AK13+AK31)=SUM(C87) -> TRUE | AL14: =(AL13+AL31)=SUM(J71) -> TRUE | AM14: =SUM(AM3:AM12)=100% -> TRUE | AN14: =SUM(AN3:AN12,AN21:AN30)=100% -> FALSE | AO14: =SUM(AO3:AO12,AO21:AO30)=1000% -> TRUE | AP14: =(C102-C87)=(AP13+AP31) -> FALSE | AR14: =IF(ABS(C119-AR13) < MAX(0.00001, C119 * 0.00001), TRUE, FALSE) -> TRUE | AS14: =(AS13+AS31)=SUM(C107) -> FALSE | AT14: =AT13=C25 -> TRUE | AU14: =IF(ABS(AU13+AU31 - C24+C25) < MAX(0.0001, AU13+AU31 * 0.0001), TRUE, FALSE) -> TRUE | AV14: =AV13=AV13 -> TRUE | AW14: =AW31+AW13=100% -> FALSE | AX14: =ABS((AX13 + AX31) - (C17 + AT31)) < 0.1 -> TRUE | AY14: =AY13=AY13 -> TRUE | AZ14: =IF(ABS(AZ13+AZ31 - C26) < MAX(0.0001, AZ13+AZ31 * 0.0001), TRUE, FALSE) -> TRUE | BA14: =BA13=BA13 -> TRUE | BB14: =BB13=BB13 -> TRUE | BC14: =BC13=BC13 -> TRUE | BD14: =BD13=BD13 -> TRUE | BH14: إجمالي قيمة ونسبة تكاليف الصندوق من إجمالي تكاليف المشروع (Fund Management Cost as Value and % of Total Project Cost) | BI14: =C107 -> 48528693 | BJ14: =BI14/$C$24 -> 0.063621821 | BK14: تتراوح من 1% – 7% حسب شروط الصندوق | BV14: نسبة رصف من المستثمرين | BW14: لا ينطبق | BX14: 0 | BZ14: =BX18*BW6*(1-BY18) -> 0
B15: Feasibility Study Summary | ملخص دراسة الجدوى | G15: Financial Structuring | الهيكلة المالية | BH15: مؤشرات الإيرادات والربحية | Revenue & Profitability Indicators | BK15: - | BV15: الحصة من فارق قيمة الأرض | BW15: 1 | BX15: =K23*BW15 -> 0 | BY15: × | BZ15: =BX15*BW6 -> 0 | CA15: =BZ15+BX15 -> 0
B16: البند (Item) | C16: القيمة (Value) | G16: رأس المال - (capital) | BH16: متوسط سعر بيع المتر البيعي (Average Selling Price per Sellable m²) | BI16: =SUM(C184,C187:C188)/J59 -> 20934.374 | BK16: - | BV16: اشتراكات نقدية / مصاريف سابقة | BW16: 1 | BX16: 0 | BY16: × | BZ16: =BX16*$C$7 -> 0 | CA16: =BZ16+BX16 -> 0
B17: إجمالي الإيرادات (Total Revenue) | C17: =SUM(C184:C188) -> 1.0431828e+09 | G17: المصدر (Source) | H17: SAR | I17: % | BH17: متوسط قيمة و نسبة الربح لكل م² (Average Profit Value and % per m²) | BI17: =BI16-BI6 -> 4626.3077 | BJ17: =BI17/BI6 -> 0.28368217 | BK17: - | BV17: اجمالي رصف | BX17: =SUM(BX9:BX16) -> 17190139 | BZ17: =SUM(BZ9:BZ16) -> 35642623 | CA17: =SUM(CA9:CA16) -> 52832762
B18: إجمالي تكلفة الأرض (Total Land Cost) | C18: =I49 -> 347717500 | G18: (Equity) - الملكية | BH18: العائد على المتر البيعي (شامل عوائد الإيجار) (Total Return per Saleable m² including Rental Income) | BI18: =C26/F76 -> 5764.8867 | BJ18: =BI18/BI6 -> 0.35349909 | BK18: - | BV18: مستثمرين رصف | BX18: 0 | BY18: 0.7 | BZ18: =BX18*BW6*BY18 -> 0 | CA18: =BZ18+BX18 -> 0
B19: إجمالي تكلفة البناء (Total Construction Cost) | C19: =J76 -> 286502320 | G19: الاشتراكات النقدية (Cash Subscription) | H19: 60000000 | I19: =H19/$H$34 -> 0.078660871 | AE19: توزيع تكاليف مكونات البيع على الخارطة | BH19: نسبة صافي الربح من الإيرادات (Net Profit as % of Revenues) | BI19: =C26/C17 -> 0.2584761 | BK19: مثالي إن كان بين 20% إلى 35% (أقل من 15% يُعد ضعيف، وأكثر من 40% نادر وممتاز) | BV19: الاجمالي | BX19: =SUM(BX17:BX18) -> 17190139 | BZ19: =SUM(BZ17:BZ18) -> 35642623 | CA19: =BZ19+BX19 -> 52832762
B20: إجمالي التكاليف الأخرى (Total Other cost) | C20: =C102 -> 68692160 | G20: الاشتراك من مدير الصندوق (fund manager's Subscription) | I20: =H20/$H$34 -> 0 | AE20: المكون | AF20: توزيع تكاليف الأرض | AG20: تكاليف البناء | AH20: نسبة تزيع تكاليف اللاند سكيب | AI20: توزيع تكاليف اللاندسكيب | AJ20: توزيع تكاليف البوديم و القبو | AK20: توزيع تكاليف الحفر والمسح و الاختبار | AL20: توزيع تكاليف المساحات الحركية والخدمية | AM20: نسب التكاليف السابقة من التكاليف الموجودة بالجدول | AN20: نسب التكاليف السابقة من التكاليف الكلية | AO20: نسبة بيع المكون على الخارطة من الإجمالي | AP20: توزيع التكاليف الأخرى | AQ20: توزيع تكاليف أخرى إضافية | AR20: توزيع تكاليف التمويل | AS20: توزيع تكاليف الصندوق | AT20: تكاليف بيع الخارطة | AU20: إجمالي تكاليف كل مكون | AV20: توزيع التكلفة على الأمتار البيعية | AW20: نسبة تكاليف كل مكون من إجمالي المشروع | AX20: إجمالي إيراد كل مكون | AY20: صافي العائد لكل م² بيعي | AZ20: صافي دخل كل مكون | BA20: العائد النسبي للمكون | BB20: هامش الربح من إجمالي الإرادات | BC20: نسبة صافي دخل كل مكون من إجمالي صافي دخل المشروع | BD20: نسبة صافي دخل كل مكون | BH20: نقطة التعادل - عدد الأمتار البيعية اللازمة لتغطية التكاليف (Sellable Area Required for Cost Recovery) | BI20: =C24/BI16 -> 36436.153 | BJ20: =BI20/F76 -> 0.77900903 | BK20: -
B21: إجمالي رسوم الصندوق (Total Fund Fees) | C21: =C107 -> 48528693 | G21: الأشتراك النقدي من المطور (Cash Subscription from Developer) | I21: =H21/$H$34 -> 0 | AE21: سكني (بيع على الخارطة) | AF21: =((F61/$J$59)*$I$49)*AO21 -> 84238195 | AG21: =J61*AO21 -> 42658304 | AH21: =AH3 -> 0 | AI21: =($J$73*AH21)*AO21 -> 0 | AJ21: =((K61/$L$76)*($J$74+$J$75))*AO21 -> 8473529 | AK21: =((K61/$L$76)*$C$87)*AO21 -> 857944.81 | AL21: =(((D61-F61)/$H$59)*$J$71)*AO21 -> 0 | AM21: =SUM(AF21:AG21,AI21:AL21)/$AM$31 -> 1 | AN21: =SUM(AF21:AG21,AI21:AL21)/$AN$31 -> 0.21250282 | AO21: =S129 -> 0.4 | AP21: =(AN21*SUM($C$86,$C$88:$C$90,$C$96:$C$97,$C$101))+(SUM($D$93:$D$95)*H61*AO21) -> 8314070.9 | AQ21: =(($A$92+$C$100)*AM21) -> 3671280.3 | AR21: لا يــــنــطــبــق | AS21: =AN21*$C$107 -> 10312484 | AT21: لا يــــنــطــبــق | AU21: =SUM(AF21:AG21,AI21:AL21,AP21:AS21) -> 1.5852581e+08 | AV21: =IFERROR((AU21)/T129, "0") -> 13990.313 | AW21: =(AU21)/($C$24) -> 0.20782963 | AX21: =AC129 -> 1.1894948e+08 | AY21: =IFERROR(AZ21/T129, "0") -> -3492.7134 | AZ21: =AX21-AU21 -> -39576327 | BA21: =IFERROR(BD21/AW21, "0.00") -> -1.2012352 | BB21: =IFERROR(AZ21/AX21, "0.00%") -> -0.33271542 | BC21: =AZ21/$C$26 -> -0.14677588 | BD21: =IFERROR(AZ21/(AU21), "0.00%") -> -0.24965226 | BE21: سكني | BH21: مؤشرات التمويل والمخاطر | Financing & Risk Indicators | BJ21: 0 | BK21: -
B22: فوائد التمويل (Interest) | C22: =C119 -> 11327391 | G22: الأشتراك العيني من المطور (In-Kind Subscription from Developer) | H22: =J22*((D104+E104)*-E196) -> 17190139 | I22: =H22/$H$34 -> 0.022536522 | J22: 0.5 | AE22: فلل (بيع على الخارطة) | AF22: =((F62/$J$59)*$I$49)*AO22 -> 0 | AG22: =J62*AO22 -> 0 | AH22: =AH4 -> 0 | AI22: =($J$73*AH22)*AO22 -> 0 | AJ22: =((K62/$L$76)*($J$74+$J$75))*AO22 -> 0 | AK22: =((K62/$L$76)*$C$87)*AO22 -> 0 | AL22: =(((D62-F62)/$H$59)*$J$71)*AO22 -> 0 | AM22: =SUM(AF22:AG22,AI22:AL22)/$AM$31 -> 0 | AN22: =SUM(AF22:AL22)/$AN$31 -> 0 | AO22: =S130 -> 0.00% | AP22: =(AN22*SUM($C$86,$C$88:$C$90,$C$96:$C$97,$C$101))+(SUM($D$93:$D$95)*H62*AO22) -> 0 | AQ22: =(($A$92+$C$100)*AM22) -> 0 | AR22: لا يــــنــطــبــق | AS22: =AN22*$C$107 -> 0 | AT22: لا يــــنــطــبــق | AU22: =SUM(AF22:AG22,AI22:AL22,AP22:AS22) -> 0 | AV22: =IFERROR((AU22-AT22)/T130, "0") -> 0 | AW22: =(AU22)/($C$24) -> 0 | AX22: =AC130 -> 0 | AY22: =IFERROR(AZ22/T130, "0") -> 0 | AZ22: =AX22-AU22 -> 0 | BA22: =IFERROR(BD22/AW22, "0.00") -> 0.00 | BB22: =IFERROR(AZ22/AX22, "0.00%") -> 0.00% | BC22: =AZ22/$C$26 -> 0 | BD22: =IFERROR(AZ22/(AU22), "0.00%") -> 0.00% | BE22: فلل | BH22: القيم والنسب الخاصة بالتمويل البنكي (Bank Financing Limits & Conditions) | BI22: =(BJ24+BJ23)-H26 -> 2.8761164e+08 | BJ22: =H26/(BJ24+BJ23) -> 0.28206869 | BK22: -
B23: التمويل البنكي (Bank Financing) | C23: =H26 -> 113000000 | G23: الإشتراك العيني من مالك الأرض (In-Kind Subscription from Landowner) | H23: =(J23*E49)+K23 -> 338000000 | I23: =H23/$H$34 -> 0.4431229 | J23: 1 | AE23: تاون هاوس (بيع على الخارطة) | AF23: =((F63/$J$59)*$I$49)*AO23 -> 0 | AG23: =J63*AO23 -> 0 | AH23: =AH5 -> 0 | AI23: =($J$73*AH23)*AO23 -> 0 | AJ23: =((K63/$L$76)*($J$74+$J$75))*AO23 -> 0 | AK23: =((K63/$L$76)*$C$87)*AO23 -> 0 | AL23: =(((D63-F63)/$H$59)*$J$71)*AO23 -> 0 | AM23: =SUM(AF23:AG23,AI23:AL23)/$AM$31 -> 0 | AN23: =SUM(AF23:AL23)/$AN$31 -> 0 | AO23: =S131 -> 0.00% | AP23: =(AN23*SUM($C$86,$C$88:$C$90,$C$96:$C$97,$C$101))+(SUM($D$93:$D$95)*H63*AO23) -> 0 | AQ23: =(($A$92+$C$100)*AM23) -> 0 | AR23: لا يــــنــطــبــق | AS23: =AN23*$C$107 -> 0 | AT23: لا يــــنــطــبــق | AU23: =SUM(AF23:AG23,AI23:AL23,AP23:AS23) -> 0 | AV23: =IFERROR((AU23-AT23)/T131, "0") -> 0 | AW23: =(AU23)/($C$24) -> 0 | AX23: =AC131 -> 0 | AY23: =IFERROR(AZ23/T131, "0") -> 0 | AZ23: =AX23-AU23 -> 0 | BA23: =IFERROR(BD23/AW23, "0.00") -> 0.00 | BB23: =IFERROR(AZ23/AX23, "0.00%") -> 0.00% | BC23: =AZ23/$C$26 -> 0 | BD23: =IFERROR(AZ23/(AU23), "0.00%") -> 0.00% | BE23: تاون هاوس | BG23: =H26/SUM(C109:D111) -> 0.16075982 | BI23: 0.66 | BJ23: =(I49*80%)*BI23 -> 183594840 | BK23: -
B24: إجمالي التكاليف الرأسمالية للمشروع (Total Capital Expenditures) | C24: =SUM(C18:C22) -> 7.6276806e+08 | G24: إجمالي الملكية (Total Equity) | H24: =SUM(H19:H23) -> 4.1519014e+08 | I24: =H24/$H$34 -> 0.5443203 | AE24: أدوار (بيع على الخارطة) | AF24: =((F64/$J$59)*$I$49)*AO24 -> 0 | AG24: =J64*AO24 -> 0 | AH24: =AH6 -> 0 | AI24: =($J$73*AH24)*AO24 -> 0 | AJ24: =((K64/$L$76)*($J$74+$J$75))*AO24 -> 0 | AK24: =((K64/$L$76)*$C$87)*AO24 -> 0 | AL24: =(((D64-F64)/$H$59)*$J$71)*AO24 -> 0 | AM24: =SUM(AF24:AG24,AI24:AL24)/$AM$31 -> 0 | AN24: =SUM(AF24:AL24)/$AN$31 -> 0 | AO24: =S132 -> 0.00% | AP24: =(AN24*SUM($C$86,$C$88:$C$90,$C$96:$C$97,$C$101))+(SUM($D$93:$D$95)*H64*AO24) -> 0 | AQ24: =(($A$92+$C$100)*AM24) -> 0 | AR24: لا يــــنــطــبــق | AS24: =AN24*$C$107 -> 0 | AT24: لا يــــنــطــبــق | AU24: =SUM(AF24:AG24,AI24:AL24,AP24:AS24) -> 0 | AV24: =IFERROR((AU24-AT24)/T132, "0") -> 0 | AW24: =(AU24)/($C$24) -> 0 | AX24: =AC132 -> 0 | AY24: =IFERROR(AZ24/T132, "0") -> 0 | AZ24: =AX24-AU24 -> 0 | BA24: =IFERROR(BD24/AW24, "0.00") -> 0.00 | BB24: =IFERROR(AZ24/AX24, "0.00%") -> 0.00% | BC24: =AZ24/$C$26 -> 0 | BD24: =IFERROR(AZ24/(AU24), "0.00%") -> 0.00% | BE24: أدوار | BI24: 0.66 | BJ24: =SUM(J76,C86:C90,C93:C95,C96:C96,C101)*BI24 -> 2.170168e+08 | BK24: -
B25: إجمالي التكاليف التشغيلية (Total Operating Expenses) | C25: =-SUM(E213) -> 10776878 | G25: التمويل البنكي - (Bank Financing) | AE25: استديوهات (بيع على الخارطة) | AF25: =((F65/$J$59)*$I$49)*AO25 -> 0 | AG25: =J65*AO25 -> 0 | AH25: =AH7 -> 0 | AI25: =($J$73*AH25)*AO25 -> 0 | AJ25: =((K65/$L$76)*($J$74+$J$75))*AO25 -> 0 | AK25: =((K65/$L$76)*$C$87)*AO25 -> 0 | AL25: =(((D65-F65)/$H$59)*$J$71)*AO25 -> 0 | AM25: =SUM(AF25:AG25,AI25:AL25)/$AM$31 -> 0 | AN25: =SUM(AF25:AL25)/$AN$31 -> 0 | AO25: =S133 -> 0.00% | AP25: =(AN25*SUM($C$86,$C$88:$C$90,$C$96:$C$97,$C$101))+(SUM($D$93:$D$95)*H65*AO25) -> 0 | AQ25: =(($A$92+$C$100)*AM25) -> 0 | AR25: لا يــــنــطــبــق | AS25: =AN25*$C$107 -> 0 | AT25: لا يــــنــطــبــق | AU25: =SUM(AF25:AG25,AI25:AL25,AP25:AS25) -> 0 | AV25: =IFERROR((AU25-AT25)/T133, "0") -> 0 | AW25: =(AU25)/($C$24) -> 0 | AX25: =AC133 -> 0 | AY25: =IFERROR(AZ25/T133, "0") -> 0 | AZ25: =AX25-AU25 -> 0 | BA25: =IFERROR(BD25/AW25, "0.00") -> 0.00 | BB25: =IFERROR(AZ25/AX25, "0.00%") -> 0.00% | BC25: =AZ25/$C$26 -> 0 | BD25: =IFERROR(AZ25/(AU25), "0.00%") -> 0.00% | BE25: أستوديوهات | BI25: =BJ25/E119 -> 0.033383646 | BJ25: =BI26/H26 -> 0.1002424 | BK25: -
B26: صافي الدخل (Net Income) | C26: =C17-(C24+C25) -> 2.6963782e+08 | G26: إجمالي التمويل البنكي (Total Bank Financing) | H26: =E189 -> 113000000 | I26: =H26/$H$34 -> 0.14814464 | AE26: مكتبي (بيع على الخارطة) | AF26: =((F66/$J$59)*$I$49)*AO26 -> 0 | AG26: =J66*AO26 -> 0 | AH26: =AH8 -> 0 | AI26: =($J$73*AH26)*AO26 -> 0 | AJ26: =((K66/$L$76)*($J$74+$J$75))*AO26 -> 0 | AK26: =((K66/$L$76)*$C$87)*AO26 -> 0 | AL26: =(((D66-F66)/$H$59)*$J$71)*AO26 -> 0 | AM26: =SUM(AF26:AG26,AI26:AL26)/$AM$31 -> 0 | AN26: =SUM(AF26:AL26)/$AN$31 -> 0 | AO26: =S134 -> 0 | AP26: =(AN26*SUM($C$86,$C$88:$C$90,$C$96:$C$97,$C$101))+(SUM($D$93:$D$95)*H66*AO26) -> 0 | AQ26: =(($A$92+$C$100)*AM26) -> 0 | AR26: لا يــــنــطــبــق | AS26: =AN26*$C$107 -> 0 | AT26: لا يــــنــطــبــق | AU26: =SUM(AF26:AG26,AI26:AL26,AP26:AS26) -> 0 | AV26: =IFERROR((AU26-AT26)/T134, "0") -> 0 | AW26: =(AU26)/($C$24) -> 0 | AX26: =AC134 -> 0 | AY26: =IFERROR(AZ26/T134, "0") -> 0 | AZ26: =AX26-AU26 -> 0 | BA26: =IFERROR(BD26/AW26, "0.00") -> 0.00 | BB26: =IFERROR(AZ26/AX26, "0.00%") -> 0.00% | BC26: =AZ26/$C$26 -> 0 | BD26: =IFERROR(AZ26/(AU26), "0.00%") -> 0.00% | BE26: مكتبي | BI26: =C22 -> 11327391 | BK26: -
B27: مدة المشروع المتوقعة - سنوي (Estimated Project Duration - Years) | C27: =D122 -> 3.830137 | AE27: تجاري (بيع على الخارطة) | AF27: =((F67/$J$59)*$I$49)*AO27 -> 0 | AG27: =J67*AO27 -> 0 | AH27: =AH9 -> 0.4 | AI27: =($J$73*AH27)*AO27 -> 0 | AJ27: =((K67/$L$76)*($J$74+$J$75))*AO27 -> 0 | AK27: =((K67/$L$76)*$C$87)*AO27 -> 0 | AL27: =(((D67-F67)/$H$59)*$J$71)*AO27 -> 0 | AM27: =SUM(AF27:AG27,AI27:AL27)/$AM$31 -> 0 | AN27: =SUM(AF27:AL27)/$AN$31 -> 6.2396235e-10 | AO27: =S135 -> 0 | AP27: =(AN27*SUM($C$86,$C$88:$C$90,$C$96:$C$97,$C$101))+(SUM($D$93:$D$95)*H67*AO27) -> 0.018727639 | AQ27: =(($A$92+$C$100)*AM27) -> 0 | AR27: لا يــــنــطــبــق | AS27: =AN27*$C$107 -> 0.030280077 | AT27: لا يــــنــطــبــق | AU27: =SUM(AF27:AG27,AI27:AL27,AP27:AS27) -> 0.049007717 | AV27: =IFERROR((AU27-AT27)/T135, "0") -> 0 | AW27: =(AU27)/($C$24) -> 6.4249828e-11 | AX27: =AC135 -> 0 | AY27: =IFERROR(AZ27/T135, "0") -> 0 | AZ27: =AX27-AU27 -> -0.049007717 | BA27: =IFERROR(BD27/AW27, "0.00") -> -1.5564244e+10 | BB27: =IFERROR(AZ27/AX27, "0.00%") -> 0.00% | BC27: =AZ27/$C$26 -> -1.8175387e-10 | BD27: =IFERROR(AZ27/(AU27), "0.00%") -> -1 | BE27: تجاري | BH27: نسبة المخاطرة التمويلية Loan to Value Ratio (LTV)) | BI27: =H26/(SUM(C184:C188)) -> 0.10832234 | BJ27: =1-BI27 -> 0.89167766 | BK27: بين (50%) و (70%) = طبيعي أقل من (50%) = منخفض (اعتماد كبير على تمويل ذاتي) أكثر من (70%) = مرتفع (مخاطرة عالية على البنك)
B28: معدل العائد الداخلي (IRR) | C28: =C223 -> 0.14199981 | G28: تمويل تشغيلي خارج هيكل رأس المال - (Off-Capital-Structure Operational Financing) | AE28: فندقي (بيع على الخارطة) | AF28: =((F68/$J$59)*$I$49)*AO28 -> 0 | AG28: =J68*AO28 -> 0 | AH28: =AH10 -> 0.6 | AI28: =($J$73*AH28)*AO28 -> 0 | AJ28: =((K68/$L$76)*($J$74+$J$75))*AO28 -> 0 | AK28: =((K68/$L$76)*$C$87)*AO28 -> 0 | AL28: =(((D68-F68)/$H$59)*$J$71)*AO28 -> 0 | AM28: =SUM(AF28:AG28,AI28:AL28)/$AM$31 -> 0 | AN28: =SUM(AF28:AL28)/$AN$31 -> 9.3594353e-10 | AO28: =S136 -> 0 | AP28: =(AN28*SUM($C$86,$C$88:$C$90,$C$96:$C$97,$C$101))+((SUM($D$94:$D$95)*H68*AO28)+(D93*H68/2*AO28)) -> 0.028091459 | AQ28: =(($A$92+$C$100)*AM28) -> 0 | AR28: لا يــــنــطــبــق | AS28: =AN28*$C$107 -> 0.045420116 | AT28: لا يــــنــطــبــق | AU28: =SUM(AF28:AG28,AI28:AL28,AP28:AS28) -> 0.073511575 | AV28: =IFERROR((AU28-AT28)/T136, "0") -> 0 | AW28: =(AU28)/($C$24) -> 9.6374742e-11 | AX28: =AC136 -> 0 | AY28: =IFERROR(AZ28/T136, "0") -> 0 | AZ28: =AX28-AU28 -> -0.073511575 | BA28: =IFERROR(BD28/AW28, "0.00") -> -1.0376163e+10 | BB28: =IFERROR(AZ28/AX28, "0.00%") -> 0.00% | BC28: =AZ28/$C$26 -> -2.7263081e-10 | BD28: =IFERROR(AZ28/(AU28), "0.00%") -> -1 | BE28: فندقي | BH28: مؤشر المخاطر التمويلية (Leverage Risk Indicator) | BI28: =H26/H24 -> 0.27216446 | BK28: يفضل أن يكون ≤ 1.5 (كلما ارتفع زادت المخاطرة)
G29: البيع على الخارطة (Off-Plan Sales) | H29: =K29*J29 -> 1.1894948e+08 | I29: =H29/$H$34 -> 0.1559445 | J29: =AC139 -> 1.1894948e+08 | K29: 1 | L29: =-H35/J29 -> 0 | AE29: صحي (بيع على الخارطة) | AF29: =((F69/$J$59)*$I$49)*AO29 -> 0 | AG29: =J69*AO29 -> 0 | AH29: =AH11 -> 0 | AI29: =($J$73*AH29)*AO29 -> 0 | AJ29: =((K69/$L$76)*($J$74+$J$75))*AO29 -> 0 | AK29: =((K69/$L$76)*$C$87)*AO29 -> 0 | AL29: =(((D69-F69)/$H$59)*$J$71)*AO29 -> 0 | AM29: =SUM(AF29:AG29,AI29:AL29)/$AM$31 -> 0 | AN29: =SUM(AF29:AL29)/$AN$31 -> 0 | AO29: =S137 -> 0.00% | AP29: =(AN29*SUM($C$86,$C$88:$C$90,$C$96:$C$97,$C$101))+(SUM($D$93:$D$95)*H69*AO29) -> 0 | AQ29: =(($A$92+$C$100)*AM29) -> 0 | AR29: لا يــــنــطــبــق | AS29: =AN29*$C$107 -> 0 | AT29: لا يــــنــطــبــق | AU29: =SUM(AF29:AG29,AI29:AL29,AP29:AS29) -> 0 | AV29: =IFERROR((AU29-AT29)/T137, "0") -> 0 | AW29: =(AU29)/($C$24) -> 0 | AX29: =AC137 -> 0 | AY29: =IFERROR(AZ29/T137, "0") -> 0 | AZ29: =AX29-AU29 -> 0 | BA29: =IFERROR(BD29/AW29, "0.00") -> 0.00 | BB29: =IFERROR(AZ29/AX29, "0.00%") -> 0.00% | BC29: =AZ29/$C$26 -> 0 | BD29: =IFERROR(AZ29/(AU29), "0.00%") -> 0.00% | BE29: صحي | BH29: قيمة ونسبة تمويل مبيعات الخارطة من تكاليف المشروع خلال فترة البيع (Value and % of Off-Plan Sales Financing for Project Costs During Sales Period) | BI29: =AX21 -> 1.1894948e+08 | BJ29: =C184/-(SUM(G192:S216)) -> 0.31688043 | BK29: من 30% إلى 60% من التكاليف أثناء البيع يعتبر جيد جداً
B30: العائد على الإستثمار (ROI) | C30: =C26/C24 -> 0.35349909 | G30: مصادر أخرى (Other Sources) | H30: =K30*J30 -> 1.1562844e+08 | I30: =H30/$H$34 -> 0.15159057 | J30: =SUM(J139,M157,AC157) -> 2.6571247e+08 | K30: 0.43516379 | L30: =-H35/J30 -> 0 | AE30: أخرى (Other) (بيع على الخارطة) | AF30: =((F70/$J$59)*$I$49)*AO30 -> 0 | AG30: =J70*AO30 -> 0 | AH30: =AH12 -> 0 | AI30: =($J$73*AH30)*AO30 -> 0 | AJ30: =((K70/$L$76)*($J$74+$J$75))*AO30 -> 0 | AK30: =((K70/$L$76)*$C$87)*AO30 -> 0 | AL30: =(((D70-F70)/$H$59)*$J$71)*AO30 -> 0 | AM30: =SUM(AF30:AG30,AI30:AL30)/$AM$31 -> 0 | AN30: =SUM(AF30:AL30)/$AN$31 -> 0 | AO30: =S138 -> 0.00% | AP30: =(AN30*SUM($C$86,$C$88:$C$90,$C$96:$C$97,$C$101))+(SUM($D$93:$D$95)*H70*AO30) -> 0 | AQ30: =(($A$92+$C$100)*AM30) -> 0 | AR30: لا يــــنــطــبــق | AS30: =AN30*$C$107 -> 0 | AT30: لا يــــنــطــبــق | AU30: =SUM(AF30:AG30,AI30:AL30,AP30:AS30) -> 0 | AV30: =IFERROR((AU30-AT30)/T138, "0") -> 0 | AW30: =(AU30)/($C$24) -> 0 | AX30: =AC138 -> 0 | AY30: =IFERROR(AZ30/T138, "0") -> 0 | AZ30: =AX30-AU30 -> 0 | BA30: =IFERROR(BD30/AW30, "0.00") -> 0.00 | BB30: =IFERROR(AZ30/AX30, "0.00%") -> 0.00% | BC30: =AZ30/$C$26 -> 0 | BD30: =IFERROR(AZ30/(AU30), "0.00%") -> 0.00% | BE30: شاليهات | BH30: هامش الأمان (Safety Margin) | BI30: =(C17-C24)/C17 -> 0.26880687 | BK30: المستهدف الجيد ≥ 20% (بمعنى أن القيمة السوقية أعلى بـ 20% من التكلفة)
G31: إجمالي التمويل التشغيلي (Total Operational Financing) | H31: =SUM(H29:H30) -> 2.3457793e+08 | I31: =H31/$H$34 -> 0.30753506 | AE31: الإجمالي | AF31: =SUM(AF21:AF30) -> 84238195 | AG31: =SUM(AG21:AG30) -> 42658304 | AH31: =SUM(AH21:AH30) -> 1 | AI31: =SUM(AI21:AI30) -> 0 | AJ31: =SUM(AJ21:AJ30) -> 8473529 | AK31: =SUM(AK21:AK30) -> 857944.81 | AL31: =SUM(AL21:AL30) -> 0 | AM31: =SUM(AF31:AG31,AI31:AL31) -> 1.3622797e+08 | AN31: =SUM(AF3:AG12,AI3:AL12,AF21:AG30,AI21:AL30) -> 641064320 | AO31: - | AP31: =SUM(AP21:AQ30) -> 11985351 | AR31: - | AS31: =SUM(AS21:AS30) -> 10312484 | AT31: =SUM(AT21:AT30) -> 0 | AU31: =SUM(AU21:AU30) -> 1.5852581e+08 | AV31: =IFERROR(AU31/T139, "0") -> 13990.313 | AW31: =SUM(AW21:AW30) -> 0.20782963 | AX31: =SUM(AX21:AX30) -> 1.1894948e+08 | AY31: =AZ31/T139 -> -3492.7134 | AZ31: =SUMIF(AZ21:AZ30, "<>#DIV/0!") -> -39576327 | BA31: - | BB31: =IFERROR(AZ31/AX31, "0.00%") -> -0.33271542 | BC31: - | BD31: =IFERROR(AZ31/AU31, "0.00%") -> -0.24965226 | BH31: مؤشرات الأرض والزمن | Land & Time Indicators | BJ31: 0 | BK31: -
B32: العائد على الملكية (ROE) | C32: =(C26/H24) -> 0.64943213 | G32: الإجمالي - (Total) | AE32: T & F | AF32: =I49-AF13=AF31 -> TRUE | AG32: =SUM(J61:J71)-AG13=AG31 -> TRUE | AH32: =SUM(AH21:AH30)=AH31 -> TRUE | AI32: =J73-AI13=AI31 -> TRUE | AJ32: =(J74+J75)-AJ13=AJ31 -> FALSE | AK32: =C87-AK13=AK31 -> TRUE | AL32: =J71-AL13=AL31 -> TRUE | AM32: =SUM(AF21:AG30,AI21:AL30)=AM31 -> TRUE | AN32: =SUM(AI21:AL30,AF21:AG30,AF3:AG12,AI3:AL12)=AN31 -> TRUE | AO32: =SUM(AO3:AO12,AO21:AO30)=1000% -> TRUE | AP32: =C102-C87=AP13+AP31 -> FALSE | AR32: =AR31=AR31 -> TRUE | AS32: =C107-AS13=AS31 -> FALSE | AT32: =AT31=AT31 -> TRUE | AU32: =AU13+AU31=C24+C25+AT31 -> FALSE | AV32: =AV31=AV31 -> TRUE | AW32: =AW31+AW13=100% -> FALSE | AX32: =AX31=AC139 -> TRUE | AY32: =AY31=AY31 -> TRUE | AZ32: =AZ31=AZ31 -> TRUE | BA32: =BA31=BA31 -> TRUE | BB32: =BB31=BB31 -> TRUE | BC32: =BC31=BC31 -> TRUE | BD32: =BD31=BD31 -> TRUE | BH32: تكلفة متر الأرض شاملة الضريبة والسعي (Land Cost per m² - Including Tax and Commission) | BI32: =I49/C49 -> 20575 | BJ32: =D49 -> 20000 | BK32: -
G33: إجمالي مصادر التمويل (Total Financing Sources) | H33: =H24+H26+H31 -> 7.6276806e+08 | I33: =SUM(I24,I26,I31,M35)=100% -> TRUE | BH33: سعر متر الأرض عند البيع (Land Price per m² at Sale) | BI33: =((I49/C24)*C17)/C49 -> 28138.941 | BK33: -
B34: العائد على الملكية السنوي (ROE Annually) | C34: =C32/C27 -> 0.16955846 | G34: إجمالي التكاليف الرأسمالية للمشروع (Total Capital Expenditures) | H34: =C24 -> 7.6276806e+08 | BH34: قيمة ارتفاع سعر متر الأرض عند البيع (Land Price Appreciation Value) | BI34: =BI33-BI32 -> 7563.9406 | BK34: -
G35: الفرق (Difference) | H35: =H33-H34 -> 0 | BH35: نسبة ارتفاع سعر متر الأرض (Land Price Appreciation Rate) | BI35: =BI34/BI32 -> 0.36762773 | BK35: من 10% إلى 40% خلال 3–5 سنوات يعتبر جيد
BH36: كفاءة المساحة البيعية من المساحات المبنية فوق الأرض (Saleable Efficiency Ratio of Above-Ground Built-Up Area) | BI36: =F76/H59 -> 0.814 | BK36: المستهدف المثالي ≥ 70% (الممتاز يتجاوز 75–80%)
AE37: إجمالي توزيع التكاليف على جميع المكونات | BH37: مدة البيع - بالسنوات (غير شامل بيع الخارطة) (Sales Duration – Years) | BI37: =COUNTIFS(F187:AC187,">500")/4 -> 1 | BJ37: =BI37/D122 -> 0.26108727 | BK37: الطبيعي من 1 إلى 1.5 سنوات
AE38: المكون | AF38: توزيع تكاليف الأرض | AG38: تكاليف البناء | AH38: نسبة تزيع تكاليف اللاند سكيب | AI38: توزيع تكاليف اللاندسكيب | AJ38: توزيع تكاليف البوديم و القبو | AK38: توزيع تكاليف الحفر والمسح و الاختبار | AL38: توزيع تكاليف المساحات الحركية والخدمية | AM38: نسب التكاليف السابقة من التكاليف الموجودة بالجدول | AN38: نسب التكاليف السابقة من التكاليف الكلية | AO38: نسب المكونات من البيع المباشر أو المخارجة من الإجمالي | AP38: توزيع التكاليف الأخرى | AQ38: توزيع تكاليف أخرى إضافية | AR38: توزيع تكاليف التمويل | AS38: توزيع تكاليف الصندوق | AT38: توزيع التكاليف التشغيلية | AU38: إجمالي تكاليف كل مكون | AV38: توزيع التكلفة على المساحات الصافية القابلة للبيع | AW38: نسبة تكاليف كل مكون من إجمالي المشروع | AX38: إجمالي إيراد كل مكون | AY38: صافي العائد لكل م² بيعي | AZ38: صافي دخل كل مكون | BA38: العائد النسبي للمكون | BB38: هامش الربح من إجمالي الإرادات | BC38: نسبة صافي دخل كل مكون من إجمالي صافي دخل المشروع | BD38: نسبة صافي دخل كل مكون | BH38: توزيع الأرباح | Profit Distribution | BK38: -
AE39: سكني | AF39: =SUM(AF3,AF21) -> 2.1059549e+08 | AG39: =SUM(AG3,AG21) -> 1.0664576e+08 | AH39: =AH3 -> 0 | AI39: =SUM(AI3,AI21) -> 0 | AJ39: =SUM(AJ3,AJ21) -> 21183823 | AK39: =SUM(AK3,AK21) -> 2144862 | AL39: =SUM(AL3,AL21) -> 0 | AM39: - | AN39: =SUM(AN3,AN21) -> 0.53125704 | AO39: =SUM(AO3,AO21) -> 1 | AP39: =SUM(AP3,AP21) -> 20785177 | AQ39: =SUM(AQ3,AQ21) -> 6548806 | AR39: =SUM(AR3,AR21) -> 4584973.6 | AS39: =SUM(AS3,AS21) -> 25781210 | AT39: =SUM(AT3,AT21) -> 0 | AU39: =SUM(AU3,AU21) -> 3.982701e+08 | AV39: =IFERROR((AU39-AT39)/F61, "0") -> 14059.347 | AW39: =SUM(AW3,AW21) -> 0.52213788 | AX39: =SUM(AX21,AX3) -> 3.3140783e+08 | AY39: =IFERROR(AZ39/F61, "0") -> -2360.3074 | AZ39: =SUM(AZ21,AZ3) -> -66862268 | BA39: =IFERROR(BD39/AW39, "0.00") -> -0.32152756 | BB39: =IFERROR(AZ39/AX39, "0.00%") -> -0.20175223 | BC39: =AZ39/$C$26 -> -0.24797066 | BD39: =IFERROR(AZ39/(AU39-AT39), "0.00%") -> -0.16788172 | BE39: سكني | BH39: المستفيد (Beneficiaries) | BI39: نسبة المساهمة من إجمالي الملكية (Equity Ownership Percentage) | BJ39: صافي الربح للمستفيدين (Net Profit for Beneficiaries) | BK39: -
AE40: فلل | AF40: =SUM(AF4,AF22) -> 0 | AG40: =SUM(AG4,AG22) -> 0 | AH40: =AH4 -> 0 | AI40: =SUM(AI4,AI22) -> 0 | AJ40: =SUM(AJ4,AJ22) -> 0 | AK40: =SUM(AK4,AK22) -> 0 | AL40: =SUM(AL4,AL22) -> 0 | AM40: - | AN40: =SUM(AN4,AN22) -> 0 | AO40: =SUM(AO4,AO22) -> 1 | AP40: =SUM(AP4,AP22) -> 0 | AQ40: =SUM(AQ4,AQ22) -> 0 | AR40: =SUM(AR4,AR22) -> 0 | AS40: =SUM(AS4,AS22) -> 0 | AT40: =SUM(AT4,AT22) -> 0 | AU40: =SUM(AU4,AU22) -> 0 | AV40: =IFERROR((AU40-AT40)/F62, "0") -> 0 | AW40: =SUM(AW4,AW22) -> 0 | AX40: =SUM(AX22,AX4) -> 0 | AY40: =IFERROR(AZ40/F62, "0") -> 0 | AZ40: =SUM(AZ22,AZ4) -> 0 | BA40: =IFERROR(BD40/AW40, "0.00") -> 0.00 | BB40: =IFERROR(AZ40/AX40, "0.00%") -> 0.00% | BC40: =AZ40/$C$26 -> 0 | BD40: =IFERROR(AZ40/(AU40-AT40), "0.00%") -> 0.00% | BE40: فلل | BH40: الاشتراكات النقدية (Cash Subscription) | BI40: =H19/$H$24 -> 0.1445121 | BJ40: =BI40*$C$26 -> 38965928 | BK40: -
...

Sheet Summary
B2: شركة رصف للاستثمار | J2: RASF Investment Co.
B3: =Study!F2 -> 0 | I3: =Study!F2 -> 0
B4: Units shown are SAR except where stated | الوحدات المعروضة هي بالريال سعودي باستثناء ما هو مذكور | D4: GLA.m² : Net Sellable Area|BUA.m² : Total Development Area|PA.m² : Total Land Area GLA.m² | المساحات الصافية القابلة للبيع | BUA.m² : إجمالي المساحة التطويرية | PA.m² : مساحة الأرض الإجمالية
B8: Summary | ملخص
H9: (Area) - المساحة | I9: (SR/m²) - ر.س/م² | J9: الإجمالي - (Total)
B10: Land purchase cost - base price (excl. taxes & commissions) - تكلفة شراء الأرض - السعر الأساسي (باستثناء الضرائب والعمولات) | H10: =Study!C49 -> 16900 | I10: =Study!D49 -> 20000 | J10: =Study!E49 -> 338000000
B11: (Total project cost - including land, works, overheads and fees) - التكلفة الإجمالية للمشروع - بما في ذلك الأرض والأعمال والنفقات العامة والرسوم | H11: =Study!E59 -> 99710 | I11: =J11/H11 -> 7649.8653 | J11: =Study!C24 -> 7.6276806e+08
B12: إجمالي الإيرادات - (Total Revenue) | H12: =Study!J59 -> 46772.44 | I12: =J12/H12 -> 22303.364 | J12: =Study!C17 -> 1.0431828e+09
B14: نمو قيمة الأرض - Land Value Uplift | H14: وقت الشراء | I14: وقت البيع | J14: الفارق
H16: =J82/H10 -> 20575 | I16: =((J82/J129)*J12)/H10 -> 28138.941 | J16: =I16-H16 -> 7563.9406
B18: المؤشرات المالية | Financial Indicators | C18: معدل العائد الداخلي IRR | E18: العائد على الإستثمار ROI | G18: العائد على الملكية ROE | I18: العائد على الملكية سنوياَ ROE Annualy
C21: =Study!C28 -> 0.14199981 | E21: =Study!C30 -> 0.35349909 | G21: =Study!C32 -> 0.64943213 | I21: =Study!C34 -> 0.16955846
C24: عدد الوحدات (Number of Units) | D24: مساحة الوحدة (Unit Area) | G24: =Study!AU2 -> إجمالي تكاليف كل مكون | H24: =Study!AY2 -> صافي العائد لكل م² بيعي | I24: صافي دخل كل مكون (Net Income per Component) | J24: نسبة عائد كل مكون (Return % per Component)
B25: التفاصيل الفنية و المالية لجميع للمكونات | Technical and Financial Details For All Components
B26: (Apartments) - سكني | C26: =Study!H61 -> 220 | D26: =Study!G61 -> 128.76264 | G26: =Study!AU39 -> 3.982701e+08 | H26: =Study!AY3 -> -1605.37 | I26: =Study!AZ3 -> -27285941 | J26: =Study!BD3 -> -0.11381268
B27: فلل - (Villas) | C27: =Study!H62 -> 0 | D27: =Study!G62 -> 0 | G27: =Study!AU40 -> 0 | H27: =Study!AY4 -> 0 | I27: =Study!AZ4 -> 0 | J27: =Study!BD4 -> 0.00%
B28: تاون هاوس - (Townhouse) | C28: =Study!H63 -> 0 | D28: =Study!G63 -> 0 | G28: =Study!AU41 -> 0 | H28: =Study!AY5 -> 0 | I28: =Study!AZ5 -> 0 | J28: =Study!BD5 -> 0.00%
B29: أدوار - (Floors) | C29: =Study!H64 -> 0 | D29: =Study!G64 -> 0 | G29: =Study!AU42 -> 0 | H29: =Study!AY6 -> 0 | I29: =Study!AZ6 -> 0 | J29: =Study!BD6 -> 0.00%
B30: أستوديوهات - (Studios) | C30: =Study!H65 -> 0 | D30: =Study!G65 -> 0 | G30: =Study!AU43 -> 0 | H30: =Study!AY7 -> 0 | I30: =Study!AZ7 -> 0 | J30: =Study!BD7 -> 0.00%
B31: مكتبي - (Office) | C31: =Study!H66 -> 40 | D31: =Study!G66 -> 170.9435 | G31: =Study!AU44 -> 1.1669701e+08 | H31: =Study!AY8 -> 9198.394 | I31: =Study!AZ8 -> 62896226 | J31: =Study!BD8 -> 0.54221088
B32: تجاري - (Retail) | C32: =Study!H67 -> 40 | D32: =Study!G67 -> 122.1025 | G32: =Study!AU9 -> 76068927 | H32: =Study!AY9 -> 10690.19 | I32: =Study!AZ9 -> 52211959 | J32: =Study!BD9 -> 0.6909017
B33: فندقي - (Hotel) | C33: =Study!H68 -> 200 | D33: =Study!G68 -> 33.6141 | G33: =Study!AU10 -> 1.82482e+08 | H33: =Study!AY10 -> 28857.647 | I33: =Study!AZ10 -> 1.9400477e+08 | J33: =Study!BD10 -> 1.1220586
B34: صحي - (health) | C34: =Study!H69 -> 0 | D34: =Study!G69 -> 0 | G34: =Study!AU47 -> 0 | H34: =Study!AY11 -> 0 | I34: =Study!AZ11 -> 0 | J34: =Study!BD11 -> 0.00%
B35: أخرى - (Other) | C35: =Study!H70 -> 0 | D35: =Study!G70 -> 0 | G35: =Study!AU48 -> 26901.623 | H35: =Study!AY12 -> 0 | I35: =Study!AZ12 -> 27387133 | J35: =Study!BD12 -> 1018.0476
B38: الإطار الزمني (بالسنوات) - Time frame (Years) | J38: =Study!D122 -> 3.830137
B51: Capital Structure | هيكل رأس المال | I51: % | J51: SR
B52: الاشتراكات النقدية - (Cash Subscription) | I52: =J52/$J$60 -> 0.078660871 | J52: =Study!H19 -> 60000000
B53: الاشتراك من مدير الصندوق - (Fund Manager's Subscription) | I53: =J53/$J$60 -> 0 | J53: =Study!H20 -> 0
B54: الأشتراك النقدي من المطور - (Cash Subscription from Developer) | I54: =J54/$J$60 -> 0 | J54: =Study!H21 -> 0
B55: الأشتراك العيني من المطور - (In-Kind Subscription from Developer) | I55: =J55/$J$60 -> 0.022536522 | J55: =Study!H22 -> 17190139
B56: الإشتراك العيني من مالك الأرض - (In-Kind Subscription from Landowner) | I56: =J56/$J$60 -> 0.4431229 | J56: =Study!H23 -> 338000000
B57: التمويل البنكي - (Bank Financing) | I57: =J57/$J$60 -> 0.14814464 | J57: =Study!H26 -> 113000000
B58: البيع على الخارطة - (Off-Plan Sales) | I58: =J58/$J$60 -> 0.1559445 | J58: =Study!H29 -> 1.1894948e+08
B59: مصادر أخرى - (Other Sources) | I59: =J59/$J$60 -> 0.15159057 | J59: =Study!H30 -> 1.1562844e+08
B60: Total Funding الإجمالي | I60: =SUM(I52:I59) -> 1 | J60: =SUM(J52:J59) -> 7.6276806e+08
B81: Cost Breakdown | توزيع التكلفة | I81: SR/B.sqm | J81: SR
B82: إجمالي تكلفة الأرض بعد الضرائب - (Tota Land Cost After TAX) | I82: =I83+I84+I85+I86 -> 6051.4706 | J82: =J83+J84+J85+J86 -> 347717500
B83: (Land Cost Before TAX) - تكلفة الأرض قبل الضرائب | I83: =J83/Study!$H$59 -> 5882.3529 | J83: =Study!E44 -> 338000000
B84: (Commissions) - العمولة | I84: =J84/Study!$H$59 -> 147.05882 | J84: =Study!G44 -> 8450000
B85: (Commission Tax) - ضريبة العمولة | I85: =J85/Study!$H$59 -> 22.058824 | J85: =Study!H44 -> 1267500
...

Sheet Indicators
E3: جدول المؤشرات العامة للمشروع | General Project Indicators Table
C7: =Study!F2 -> 0
C9: مؤشرات التكاليف والكفاءة (Costs & Efficiency Indicators)
C26: مؤشرات الإيرادات والربحية | Revenue & Profitability Indicators
C42: مؤشرات التمويل والمخاطر | Financing & Risk Indicators
C58: مؤشرات الأرض والزمن | Land & Time Indicators
U88: =NOW() -> 46153.645

Sheet Sheet1
S1: تكلفة الأرض (Land Cost) | T1: =-Study!C194 -> 338000000
B2: جدول المؤشرات العامة للمشروع | General Project Indicators Table | E2: الحدود المرجعية أو المثلى للمؤشرات (Reference Ranges for Indicators) | S2: المساحة الأرض (Land Area) | T2: =Study!C49 -> 16900
S3: تكاليف مسطحات البناء (Construction Costs) | T3: =-Study!C196 -> 286502320
S4: إجمالي مسطحات البناء فوق الأرض (Above Grade Gross Building Area) | T4: =Study!L49 -> 57460
B5: مؤشرات التكاليف والكفاءة (Costs & Efficiency Indicators) | S5: (Other Cost) التكاليف الأخرى | T5: =Study!C102 -> 68692160
B6: =Study!BH5 -> التكلفة لكل م² من إجمالي المساحات التطويرية (Cost per m² of Total Built-Up Area) | C6: =Study!BI5 -> 7649.8653 | E6: - | S6: البيع المباشر | Direct Sale | T6: =Study!J139 -> 2.1245835e+08
B7: التكلفة لكل م² من إجمالي المساحات القابلة للبيع (Cost per m² of Saleable Area) | C7: =Study!BI6 -> 16308.067 | E7: - | S7: البيع على الخارطة | Off-Plan Sale | T7: =Study!AC139 -> 1.1894948e+08
B8: إجمالي التكاليف المباشرة (Total Direct Costs) | C8: =Study!BI7 -> 624502320 | D8: =Study!BJ7 -> 0.8187316 | E8: غالبًا تمثل 70% – 85% من إجمالي التكاليف | S8: التأجير السنوي | Annual Leasing | T8: =Study!M157 -> 24510367
B9: إجمالي التكاليف غير المباشرة (Total Indirect Costs) | C9: =Study!BI8 -> 1.3826574e+08 | D9: =Study!BJ8 -> 0.1812684 | E9: من 15% إلى 25% من إجمالي التكاليف غالبًا | S9: التأجير اليومي | Daily leasing | T9: =Study!AC157 -> 28743750
B10: إجمالي التكاليف التشغيلية (Total Operating Costs) | C10: =Study!BI9 -> 10776878 | D10: =Study!BJ9 -> 0.013931806 | E10: - | S10: المخارجة (Buyout) | T10: =Study!O139 -> 6.4774393e+08
B11: إجمالي قيمة ونسبة تكاليف الأرض من إجمالي تكاليف المشروع (Land Cost as Value and % of Total Project Cost) | C11: =Study!BI10 -> 347717500 | D11: =Study!BJ10 -> 0.45586269 | E11: من 10% إلى 25% غالبًا | M11: مصادر أخرى | N11: =SUM(Summary!J58:J59) -> 2.3457793e+08 | O11: =N11/Summary!$J$60 -> 0.30753506 | P11: =Study!B194 -> تكلفة الأرض (Land Cost) | Q11: =-Study!C194 -> 338000000
B12: إجمالي قيمة ونسبة تكاليف البناء من إجمالي تكاليف المشروع (Construction Cost as Value and % of Total Project Cost) | C12: =Study!BI11 -> 286502320 | D12: =Study!BJ11 -> 0.3756087 | E12: غالبًا بين 45% إلى 65% | M12: التمويل | N12: =Summary!J57 -> 113000000 | O12: =N12/Summary!$J$60 -> 0.14814464 | P12: =Study!B196 -> تكاليف مسطحات البناء (Construction Costs) | Q12: =-Study!C196 -> 286502320
B13: إجمالي قيمة ونسبة التكاليف الأخرى من إجمالي تكاليف المشروع (Other Costs as % of Total Project Cost) | C13: =Study!BI12 -> 68692160 | D13: =Study!BJ12 -> 0.090056419 | E13: غالبًا بين 10% – 20% | M13: اشتراكات المطور | N13: =Summary!J54+Summary!J55 -> 17190139 | O13: =N13/Summary!J60 -> 0.022536522 | P13: =Study!B197 -> التسوير (Fence - surrounding the land) | Q13: =-Study!C197 -> 676000
B14: إجمالي قيمة ونسبة تكاليف فوائد التمويل من إجمالي تكاليف المشروع (Financing Interest as Value and % of Total Project Cost) | C14: =Study!BI13 -> 11327391 | D14: =Study!BJ13 -> 0.014850374 | E14: من 5% – 12% حسب مدة التمويل والفوائد | M14: اشتراكات نقدية | N14: =Summary!J52+Summary!J53+Summary!J56 -> 398000000 | O14: =N14/Summary!J60 -> 0.52178377 | P14: =Study!B198 -> الحفر والمسح والاختبار (Excavation, surveying, and testing) | Q14: =-Study!C198 -> 6844500
B15: إجمالي قيمة ونسبة تكاليف الصندوق من إجمالي تكاليف المشروع (Fund Management Cost as Value and % of Total Project Cost) | C15: =Study!BI14 -> 48528693 | D15: =Study!BJ14 -> 0.063621821 | E15: تتراوح من 1% – 7% حسب شروط الصندوق | P15: =Study!B199 -> التأمين (Insurance) | Q15: =-Study!C199 -> 4870539.4
B16: مؤشرات الإيرادات والربحية | Revenue & Profitability Indicators | E16: - | P16: =Study!B200 -> الرخصة (License) | Q16: =-Study!C200 -> 229840
B17: متوسط سعر بيع المتر البيعي (Average Selling Price per Sellable m²) | C17: =Study!BI16 -> 20934.374 | E17: - | P17: =Study!B201 -> التصميم (Design) | Q17: =-Study!C201 -> 8595069.6
B18: متوسط قيمة و نسبة الربح لكل م² (Average Profit Value and % per m²) | C18: =Study!BI17 -> 4626.3077 | D18: =Study!BJ17 -> 0.28368217 | E18: - | M18: =M11 -> مصادر أخرى | N18: =N11 -> 2.3457793e+08 | P18: =Study!B202 -> أثاث الوحدات الفندقية (Apartment furniture) | Q18: =-Study!C202 -> 10342800
B19: العائد على المتر البيعي (شامل عوائد الإيجار) (Total Return per Saleable m² including Rental Income) | C19: =Study!BI18 -> 5764.8867 | D19: =Study!BJ18 -> 0.35349909 | E19: - | M19: =M12 -> التمويل | N19: =N12 -> 113000000 | P19: =Study!B203 -> أثاث الوحدات (Apartment furniture) | Q19: =-Study!C203 -> 0
B20: نسبة صافي الربح من الإيرادات (Net Profit as % of Revenues) | C20: =Study!BI19 -> 0.2584761 | E20: مثالي إن كان بين 20% إلى 35% (أقل من 15% يُعد ضعيف، وأكثر من 40% نادر وممتاز) | M20: الملكية | N20: =N13+N14 -> 4.1519014e+08 | P20: =Study!B204 -> رسوم كهرباء (Electricity fees) | Q20: =-Study!C204 -> 5000000
B21: نقطة التعادل - عدد الأمتار البيعية اللازمة لتغطية التكاليف (Sellable Area Required for Cost Recovery) | C21: =Study!BI20 -> 36436.153 | D21: =Study!BJ20 -> 0.77900903 | E21: - | P21: =Study!B205 -> رسوم الماء وصرف الصحي (Water and sewer fees) | Q21: =-Study!C205 -> 4000000
B22: مؤشرات التمويل والمخاطر | Financing & Risk Indicators | D22: 0 | E22: - | P22: =Study!B206 -> الفرز (Sorting) | Q22: =-Study!C206 -> 750000
B23: القيم والنسب الخاصة بالتمويل البنكي (Bank Financing Limits & Conditions) | C23: =Study!BI22 -> 2.8761164e+08 | D23: =Study!BJ22 -> 0.28206869 | E23: - | P23: =Study!B207 -> الصيانة و التشغيل (Maintenance and Operation) | Q23: =-Study!C207 -> 2750000
C24: =Study!BI23 -> 0.66 | D24: =Study!BJ23 -> 183594840 | E24: - | P24: =Study!B208 -> الاحتياطي (Contingency) | Q24: =-Study!C208 -> 4297534.8
C25: =Study!BI24 -> 0.66 | D25: =Study!BJ24 -> 2.170168e+08 | E25: - | P25: =Study!B209 -> تسويق المبيعات (Sales Marketing) | Q25: =-Study!C209 -> 7109061.5
C26: =Study!BI25 -> 0.033383646 | D26: =Study!BJ25 -> 0.1002424 | E26: - | P26: =Study!B211 -> تسويق البيع على الخارطة (Off-Plan Sales Marketing) | Q26: =-Study!C211 -> 3671280.3
C27: =Study!BI26 -> 11327391 | E27: - | P27: =Study!B212 -> الإشراف الهندسي (Engineering Supervision) | Q27: =-Study!C212 -> 8595069.6
B28: نسبة المخاطرة التمويلية Loan to Value Ratio (LTV)) | C28: =Study!BI27 -> 0.10832234 | D28: =Study!BJ27 -> 0.89167766 | E28: بين (50%) و (70%) = طبيعي أقل من (50%) = منخفض (اعتماد كبير على تمويل ذاتي) أكثر من (70%) = مرتفع (مخاطرة عالية على البنك)
B29: مؤشر المخاطر التمويلية (Leverage Risk Indicator) | C29: =Study!BI26 -> 11327391 | E29: يفضل أن يكون ≤ 1.5 (كلما ارتفع زادت المخاطرة)
B30: قيمة ونسبة تمويل مبيعات الخارطة من تكاليف المشروع خلال فترة البيع (Value and % of Off-Plan Sales Financing for Project Costs During Sales Period) | C30: =Study!BI29 -> 1.1894948e+08 | D30: =Study!BJ29 -> 0.31688043 | E30: من 30% إلى 60% من التكاليف أثناء البيع يعتبر جيد جداً
B31: هامش الأمان (Safety Margin) | C31: =Study!BI30 -> 0.26880687 | E31: المستهدف الجيد ≥ 20% (بمعنى أن القيمة السوقية أعلى بـ 20% من التكلفة)
B32: مؤشرات الأرض والزمن | Land & Time Indicators | D32: 0 | E32: -
B33: تكلفة متر الأرض شاملة الضريبة والسعي (Land Cost per m² - Including Tax and Commission) | C33: =Study!BI32 -> 20575 | D33: =Study!BJ32 -> 20000 | E33: -
B34: سعر متر الأرض عند البيع (Land Price per m² at Sale) | C34: =Study!BI33 -> 28138.941 | E34: -
B35: قيمة ارتفاع سعر متر الأرض عند البيع (Land Price Appreciation Value) | C35: =Study!BI34 -> 7563.9406 | E35: -
B36: نسبة ارتفاع سعر متر الأرض (Land Price Appreciation Rate) | C36: =Study!BI35 -> 0.36762773 | E36: من 10% إلى 40% خلال 3–5 سنوات يعتبر جيد
B37: كفاءة المساحة البيعية من المساحات المبنية فوق الأرض (Saleable Efficiency Ratio of Above-Ground Built-Up Area) | C37: =Study!BI36 -> 0.814 | E37: المستهدف المثالي ≥ 70% (الممتاز يتجاوز 75–80%)
B38: مدة البيع - بالسنوات (غير شامل بيع الخارطة) (Sales Duration – Years) | C38: =Study!BI37 -> 1 | D38: =Study!BJ37 -> 0.26108727 | E38: الطبيعي من 1 إلى 1.5 سنوات
B39: توزيع الأرباح | Profit Distribution | E39: -
B40: المستفيد (Beneficiaries) | C40: نسبة المساهمة من إجمالي الملكية (Equity Ownership Percentage) | D40: صافي الربح للمستفيدين (Net Profit for Beneficiaries) | E40: -
...
