Workbook
Name AuditFailsCommercial: [1]Audit!$G$12
Name AuditFailsStructural: [1]Audit!$G$11
Name AuditOK: [1]Audit!$G$13

Sheet Cover Page
H1: Legal Disclaimer and Warning: This financial model is confidential property of Rasf Investment, and all rights are fully reserved. It has been shared with you for a specific and authorized purpose only. Any copying, sharing, modification, or use of this file for any other purpose without prior written consent from Rasf Investment is strictly prohibited. If such unauthorized use occurs, legal action will be taken against you in a court of law.
A16: تفاصيل الدراسة (Study Details) | I16: درة الغدير - مشروع مختلط (Mix Use Development - RASF - Alghadeer)
D19: ------------------------------------ | L19: ------------------------------------
A20: التاريخ (Date) | I20: 46147
D23: ------------------------------------ | L23: ------------------------------------
A24: محتويات الدراسة (Study Contents) | I24: Study

Sheet Study
AE2: توزيع تكاليف المشروع على مكونات البيع المباشر و التأجير السنوي و اليومي | BH2: جدول المؤشرات العامة للمشروع | General Project Indicators Table | BL2: الحدود المرجعية أو المثلى للمؤشرات (Reference Ranges for Indicators) | BN2: سعر المتر بناءً على فترة الاسترداد - (التأجير السنوي) | BQ2: سعر المتر بناءً على فترة الاسترداد - (التأجير اليومي) | BV2: اسم المشروع | BW2: برج جدة | CA2: حالة المشروع | CB2: تاريخ الانتهاء المتوقع
AE3: المكون | AF3: توزيع تكاليف الأرض | AG3: جزء من تكاليف البناء | AH3: نسبة توزيع تكاليف اللاندسكيب | AI3: توزيع تكاليف اللاندسكيب | AJ3: توزيع تكاليف البوديم و القبو | AK3: توزيع تكاليف الحفر والمسح و الاختبار | AL3: توزيع تكاليف المساحات الحركية والخدمية | AM3: نسب التكاليف السابقة من التكاليف الموجودة بالجدول | AN3: نسب التكاليف السابقة من التكاليف الكلية | AO3: نسب المكون من البيع المباشر أو المخارجة من الإجمالي | AP3: توزيع التكاليف الأخرى | AQ3: توزيع تكاليف أخرى إضافية | AR3: توزيع تكاليف التمويل | AS3: توزيع تكاليف الصندوق | AT3: توزيع التكاليف التشغيلية | AU3: إجمالي تكاليف كل مكون | AV3: توزيع التكلفة على الأمتار البيعية | AW3: نسبة تكاليف كل مكون من إجمالي المشروع | AX3: إجمالي إيراد كل مكون | AY3: صافي العائد لكل م² بيعي | AZ3: صافي دخل كل مكون | BA3: العائد النسبي للمكون | BB3: هامش الربح من إجمالي الإرادات | BC3: نسبة صافي دخل كل مكون من إجمالي صافي دخل المشروع | BD3: نسبة صافي دخل كل مكون | BN3: المكون (Component) | BO3: سعر المتر | BP3: فترة الأسترداد - بالسنوات | BQ3: المكون (Component) | BR3: سعر المتر | BS3: فترة الأسترداد - بالسنوات | BV3: اسم الصندوق (fund Name) | BW3: إتقان | CA3: مرحلة توقيع العقود | CB3: ?
AE4: سكني | AF4: =I41 -> 15362564 | AG4: =J57*AO4 -> 7800408 | AH4: 0 | AI4: =($J$69*AH4)*AO4 -> 0 | AL4: =(((D57-F57)/$I$55)*$J$67)*AO4 -> 0 | AM4: =SUM(AF4:AG4,AI4:AL4)/$AM$14 -> 0.14502019 | AN4: =SUM(AF4:AG4,AI4:AL4)/$AN$14 -> 0.11361589 | AO4: =D125 -> 1 | AP4: =(AN4*SUM($C$82,$C$84:$C$85,$C$92:$C$93))+((H143+X143)/($H$153+$X$153))*$C$95+(SUM($D$89:$D$91)*G57*AO4) -> 749188.5 | AQ4: =(($A$88+$C$94)*AM4)+((C86+C97)*15%) -> 887297.5 | AR4: =AM4*$C$115 -> 1035720.2 | AS4: =AN4*$C$103 -> 2535299.6 | AT4: =SUM(I143,Y143) -> 123565.55 | AU4: =SUM(AF4:AG4,AI4:AL4,AP4:AT4) -> 28494043 | AV4: =IFERROR((AU4-AT4)/E125, "0") -> 9413.5425 | AW4: =(AU4-AT4)/($C$19) -> 0.12852438 | AX4: =SUM(J125,H143,O125,X143) -> 31818130 | AY4: =IFERROR(AZ4/E125, "0.00") -> 1102.9575 | AZ4: =AX4-AU4 -> 3324086.8 | BA4: =IFERROR(BD4/AW4, "0.00") -> 0.91163333 | BB4: =IFERROR(AZ4/AX4, "0.00%") -> 0.10447147 | BC4: =AZ4/$C$21 -> 0.038691214 | BD4: =IFERROR(AZ4/(AU4-AT4), "0.00%") -> 0.11716711 | BE4: سكني | BN4: سكني (Apartments) | BO4: =IFERROR((AU4-AT4) / (C143 * D143 * G143 * (1 - $I$154) * BP4), 0) -> 0 | BQ4: سكني (Apartments) | BR4: =IFERROR((AU4-AT4) / ((R143 * S143 * (1 - $Y$154) * 365 * BS4) * (1 + W143)), 0) -> 0 | BV4: =B15 -> إجمالي تكلفة البناء (Total Construction Cost) | BW4: =J72 -> 78265608
AE5: فلل | AF5: =I42 -> 27351260 | AG5: =J58*AO5 -> 0 | AH5: 0 | AI5: =($J$69*AH5)*AO5 -> 0 | AJ5: =((K58/$L$72)*($J$70+$J$71))*AO5 -> 0 | AK5: =((K58/$L$72)*$C$83)*AO5 -> 0 | AL5: =(((D58-F58)/$I$55)*$J$67)*AO5 -> 0 | AM5: =SUM(AF5:AG5,AI5:AL5)/$AM$14 -> 0.17124249 | AN5: =SUM(AF5:AG5,AI5:AL5)/$AN$14 -> 0.13415971 | AO5: =D126 -> 0 | AP5: =(AN5*SUM($C$82,$C$84:$C$85,$C$92:$C$93))+((H144+X144)/($H$153+$X$153))*$C$95+(SUM($D$89:$D$91)*G58*AO5) -> 456192.67 | AQ5: =(($A$88+$C$94)*AM5)+((C86+C97)*15%) -> 888528.77 | AR5: =AM5*$C$115 -> 1222997.3 | AS5: =AN5*$C$103 -> 2993728 | AT5: =SUM(I144,Y144) -> 0 | AU5: =SUM(AF5:AG5,AI5:AL5,AP5:AT5) -> 32912707 | AV5: =IFERROR((AU5-AT5)/E126, "0") -> 9854.1038 | AW5: =(AU5-AT5)/($C$19) -> 0.14910165 | AX5: =SUM(J126,H144,O126,X144) -> 0 | AY5: =IFERROR(AZ5/E126, "0.00") -> -9854.1038 | AZ5: =AX5-AU5 -> -32912707 | BA5: =IFERROR(BD5/AW5, "0.00") -> -6.7068337 | BB5: =IFERROR(AZ5/AX5, "0.00%") -> 0.00% | BC5: =AZ5/$C$21 -> -0.38309246 | BD5: =IFERROR(AZ5/(AU5-AT5), "0.00%") -> -1 | BE5: فلل | BH5: مؤشرات التكاليف والكفاءة (Costs & Efficiency Indicators) | BN5: فلل (Villas) | BO5: =IFERROR((AU5-AT5) / (C144 * D144 * G144 * (1 - $I$154) * BP5), 0) -> 0 | BQ5: فلل (Villas) | BR5: =IFERROR((AU5-AT5) / ((R144 * S144 * (1 - $Y$154) * 365 * BS5) * (1 + W144)), 0) -> 0 | BV5: =B19 -> إجمالي التكاليف الرأسمالية للمشروع (Total Capital Expenditures) | BW5: =C19 -> 2.2074005e+08
AE6: تاون هاوس | AF6: =((F59/$J$55)*$I$45)*AO6 -> 0 | AG6: =J59*AO6 -> 0 | AH6: 0 | AI6: =($J$69*AH6)*AO6 -> 0 | AJ6: =((K59/$L$72)*($J$70+$J$71))*AO6 -> 0 | AK6: =((K59/$L$72)*$C$83)*AO6 -> 0 | AL6: =(((D59-F59)/$I$55)*$J$67)*AO6 -> 0 | AM6: =SUM(AF6:AG6,AI6:AL6)/$AM$14 -> 0 | AN6: =SUM(AF6:AG6,AI6:AL6)/$AN$14 -> 0 | AO6: =D127 -> 1 | AP6: =(AN6*SUM($C$82,$C$84:$C$86,$C$92:$C$93,$C$97))+((H145+X145)/($H$153+$X$153))*$C$95+(SUM($D$89:$D$91)*G59*AO6) -> 0 | AQ6: =(($A$88+$C$94)*AM6) -> 0 | AR6: =AM6*$C$115 -> 0 | AS6: =AN6*$C$103 -> 0 | AT6: =SUM(I145,Y145) -> 0 | AU6: =SUM(AF6:AG6,AI6:AL6,AP6:AT6) -> 0 | AV6: =IFERROR((AU6-AT6)/E127, "0") -> 0 | AW6: =(AU6-AT6)/($C$19) -> 0 | AX6: =SUM(J127,H145,O127,X145) -> 0 | AY6: =IFERROR(AZ6/E127, "0.00") -> 0.00 | AZ6: =AX6-AU6 -> 0 | BA6: =IFERROR(BD6/AW6, "0.00") -> 0.00 | BB6: =IFERROR(AZ6/AX6, "0.00%") -> 0.00% | BC6: =AZ6/$C$21 -> 0 | BD6: =IFERROR(AZ6/(AU6-AT6), "0.00%") -> 0.00% | BE6: تاون هاوس | BH6: التكلفة لكل م² من إجمالي المساحات التطويرية (Cost per m² of Total Built-Up Area) | BI6: =C19/G55 -> 6941.5896 | BL6: - | BN6: تاون هاوس (Townhouse) | BO6: =IFERROR((AU6-AT6) / (C145 * D145 * G145 * (1 - $I$154) * BP6), 0) -> 0 | BQ6: تاون هاوس (Townhouse) | BR6: =IFERROR((AU6-AT6) / ((R145 * S145 * (1 - $Y$154) * 365 * BS6) * (1 + W145)), 0) -> 0 | BV6: =B13 -> إجمالي الإيرادات (Total Revenue) | BW6: =C13 -> 3.1318259e+08
AE7: أدوار | AF7: =((F60/$J$55)*$I$45)*AO7 -> 0 | AG7: =J60*AO7 -> 0 | AH7: 0 | AI7: =($J$69*AH7)*AO7 -> 0 | AJ7: =((K60/$L$72)*($J$70+$J$71))*AO7 -> 0 | AK7: =((K60/$L$72)*$C$83)*AO7 -> 0 | AL7: =(((D60-F60)/$I$55)*$J$67)*AO7 -> 0 | AM7: =SUM(AF7:AG7,AI7:AL7)/$AM$14 -> 0 | AN7: =SUM(AF7:AG7,AI7:AL7)/$AN$14 -> 0 | AO7: =D128 -> 1 | AP7: =(AN7*SUM($C$82,$C$84:$C$86,$C$92:$C$93,$C$97))+((H146+X146)/($H$153+$X$153))*$C$95+(SUM($D$89:$D$91)*G60*AO7) -> 0 | AQ7: =(($A$88+$C$94)*AM7) -> 0 | AR7: =AM7*$C$115 -> 0 | AS7: =AN7*$C$103 -> 0 | AT7: =SUM(I146,Y146) -> 0 | AU7: =SUM(AF7:AG7,AI7:AL7,AP7:AT7) -> 0 | AV7: =IFERROR((AU7-AT7)/E128, "0") -> 0 | AW7: =(AU7-AT7)/($C$19) -> 0 | AX7: =SUM(J128,H146,O128,X146) -> 0 | AY7: =IFERROR(AZ7/E128, "0.00") -> 0.00 | AZ7: =AX7-AU7 -> 0 | BA7: =IFERROR(BD7/AW7, "0.00") -> 0.00 | BB7: =IFERROR(AZ7/AX7, "0.00%") -> 0.00% | BC7: =AZ7/$C$21 -> 0 | BD7: =IFERROR(AZ7/(AU7-AT7), "0.00%") -> 0.00% | BE7: أدوار | BH7: التكلفة لكل م² من إجمالي المساحات القابلة للبيع (Cost per m² of Saleable Area) | BI7: =C19/J55 -> 22250.24 | BL7: - | BN7: أدوار (Floors) | BO7: =IFERROR((AU7-AT7) / (C146 * D146 * G146 * (1 - $I$154) * BP7), 0) -> 0 | BQ7: أدوار (Floors) | BR7: =IFERROR((AU7-AT7) / ((R146 * S146 * (1 - $Y$154) * 365 * BS7) * (1 + W146)), 0) -> 0 | BV7: =B30 -> العائد على الملكية السنوي (ROE Annually) | BW7: =C28 -> 0.7924872
AE8: أستوديوهات | AF8: =((F61/$J$55)*$I$45)*AO8 -> 0 | AG8: =J61*AO8 -> 0 | AH8: 0 | AI8: =($J$69*AH8)*AO8 -> 0 | AJ8: =((K61/$L$72)*($J$70+$J$71))*AO8 -> 0 | AK8: =((K61/$L$72)*$C$83)*AO8 -> 0 | AL8: =(((D61-F61)/$I$55)*$J$67)*AO8 -> 0 | AM8: =SUM(AF8:AG8,AI8:AL8)/$AM$14 -> 0 | AN8: =SUM(AF8:AG8,AI8:AL8)/$AN$14 -> 0 | AO8: =D129 -> 1 | AP8: =(AN8*SUM($C$82,$C$84:$C$86,$C$92:$C$93,$C$97))+((H147+X147)/($H$153+$X$153))*$C$95+(SUM($D$89:$D$91)*G61*AO8) -> 0 | AQ8: =(($A$88+$C$94)*AM8) -> 0 | AR8: =AM8*$C$115 -> 0 | AS8: =AN8*$C$103 -> 0 | AT8: =SUM(I147,Y147) -> 0 | AU8: =SUM(AF8:AG8,AI8:AL8,AP8:AT8) -> 0 | AV8: =IFERROR((AU8-AT8)/E129, "0") -> 0 | AW8: =(AU8-AT8)/($C$19) -> 0 | AX8: =SUM(J129,H147,O129,X147) -> 0 | AY8: =IFERROR(AZ8/E129, "0.00") -> 0.00 | AZ8: =AX8-AU8 -> 0 | BA8: =IFERROR(BD8/AW8, "0.00") -> 0.00 | BB8: =IFERROR(AZ8/AX8, "0.00%") -> 0.00% | BC8: =AZ8/$C$21 -> 0 | BD8: =IFERROR(AZ8/(AU8-AT8), "0.00%") -> 0.00% | BE8: أستوديوهات | BH8: إجمالي التكاليف الصلبة (Total Hard Costs) | BI8: =-SUM(C192:C194,C198:C199) -> 87785008 | BJ8: =BI8/($C$19+$C$20) -> 0.38625975 | BL8: - | BN8: أستوديوهات (Studios) | BO8: =IFERROR((AU8-AT8) / (C147 * D147 * G147 * (1 - $I$154) * BP8), 0) -> 0 | BQ8: أستوديوهات (Studios) | BR8: =IFERROR((AU8-AT8) / ((R147 * S147 * (1 - $Y$154) * 365 * BS8) * (1 + W147)), 0) -> 0 | CA8: -
AE9: مكتبي | AF9: =((F62/$J$55)*$I$45)*AO9 -> 0 | AG9: =J62*AO9 -> 0 | AI9: =($J$69*AH9)*AO9 -> 0 | AJ9: =((K62/$L$72)*($J$70+$J$71))*AO9 -> 0 | AK9: =((K62/$L$72)*$C$83)*AO9 -> 0 | AL9: =(((D62-F62)/$I$55)*$J$67)*AO9 -> 0 | AM9: =SUM(AF9:AG9,AI9:AL9)/$AM$14 -> 0 | AN9: =SUM(AF9:AG9,AI9:AL9)/$AN$14 -> 0 | AO9: =D130 -> 1 | AP9: =(AN9*SUM($C$82,$C$84:$C$86,$C$92:$C$93,$C$97))+((H148+X148)/($H$153+$X$153))*$C$95+(SUM($D$89:$D$91)*G62*AO9) -> 0 | AQ9: =(($A$88+$C$94)*AM9) -> 0 | AR9: =AM9*$C$115 -> 0 | AS9: =AN9*$C$103 -> 0 | AT9: =SUM(I148,Y148) -> 0 | AU9: =SUM(AF9:AG9,AI9:AL9,AP9:AT9) -> 0 | AV9: =IFERROR((AU9-AT9)/E130, "0") -> 0 | AW9: =(AU9-AT9)/($C$19) -> 0 | AX9: =SUM(J130,H148,O130,X148) -> 0 | AY9: =IFERROR(AZ9/E130, "0.00") -> 0.00 | AZ9: =AX9-AU9 -> 0 | BA9: =IFERROR(BD9/AW9, "0.00") -> 0.00 | BB9: =IFERROR(AZ9/AX9, "0.00%") -> 0.00% | BC9: =AZ9/$C$21 -> 0 | BD9: =IFERROR(AZ9/(AU9-AT9), "0.00%") -> 0.00% | BE9: مكتبي | BH9: إجمالي التكاليف اللينة (Total Soft Costs) | BI9: =-SUM(C195:C197,C200:C203,C205:C208,C210:C212) -> 32791331 | BJ9: =BI9/($C$19+$C$20) -> 0.14428399 | BL9: - | BN9: مكتبي (Office) | BO9: =IFERROR((AU9-AT9) / (C148 * D148 * G148 * (1 - $I$154) * BP9), 0) -> 0 | BQ9: مكتبي (Office) | BR9: =IFERROR((AU9-AT9) / ((R148 * S148 * (1 - $Y$154) * 365 * BS9) * (1 + W148)), 0) -> 0 | BV9: اشتراكات رصف | BW9: نسبة الحصة | BX9: مبلغ الاشتراك | BY9: الآلية | BZ9: صافي الربح | CA9: مبلغ الاشتراك + صافي الربح | CB9: ملاحظات
AE10: تجاري | AF10: =((F63/$J$55)*$I$45)*AO10 -> 0 | AG10: =J63*AO10 -> 0 | AI10: =($J$69*AH10)*AO10 -> 0 | AJ10: =((K63/$L$72)*($J$70+$J$71))*AO10 -> 0 | AK10: =((K63/$L$72)*$C$83)*AO10 -> 0 | AL10: =(((D63-F63)/$I$55)*$J$67)*AO10 -> 0 | AM10: =SUM(AF10:AG10,AI10:AL10)/$AM$14 -> 0 | AN10: =SUM(AF10:AG10,AI10:AL10)/$AN$14 -> 0 | AO10: =D131 -> 1 | AP10: =(AN10*SUM($C$82,$C$84:$C$86,$C$92:$C$93,$C$97))+((H149+X149)/($H$153+$X$153))*$C$95+(SUM($D$89:$D$91)*G63*AO10) -> 0 | AQ10: =(($A$88+$C$94)*AM10) -> 0 | AR10: =AM10*$C$115 -> 0 | AS10: =AN10*$C$103 -> 0 | AT10: =SUM(I149,Y149) -> 0 | AU10: =SUM(AF10:AG10,AI10:AL10,AP10:AT10) -> 0 | AV10: =IFERROR((AU10-AT10)/E131, "0") -> 0 | AW10: =(AU10-AT10)/($C$19) -> 0 | AX10: =SUM(J131,H149,O131,X149) -> 0 | AY10: =IFERROR(AZ10/E131, "0.00") -> 0.00 | AZ10: =AX10-AU10 -> 0 | BA10: =IFERROR(BD10/AW10, "0.00") -> 0.00 | BB10: =IFERROR(AZ10/AX10, "0.00%") -> 0.00% | BC10: =AZ10/$C$21 -> 0 | BD10: =IFERROR(AZ10/(AU10-AT10), "0.00%") -> 0.00% | BE10: تجاري | BH10: إجمالي التكاليف التي لا تندرج كصلبة أو لينة (Total costs that do not fall under hard or soft costs) | BI10: =-SUM(E188:E189,C190:C191,C204,C209) -> 1.0669303e+08 | BJ10: =BI10/($C$19+$C$20) -> 0.46945626 | BL10: - | BN10: تجاري (Retail) | BO10: =IFERROR((AU10-AT10) / (C149 * D149 * G149 * (1 - $I$154) * BP10), 0) -> 0 | BQ10: تجاري (Retail) | BR10: =IFERROR((AU10-AT10) / ((R149 * S149 * (1 - $Y$154) * 365 * BS10) * (1 + W149)), 0) -> 0 | BV10: الحصة العينية من التطوير | BW10: 1 | BX10: =H18*BW10 -> 0 | BY10: استثمار عيني | BZ10: =BX10*$BW$7 -> 0 | CA10: =BZ10+BX10 -> 0 | CB10: -
B11: Feasibility Study Summary | ملخص دراسة الجدوى | G11: Financial Structuring | الهيكلة المالية | AE11: فندقي | AF11: =I40 -> 49134000 | AG11: =J64*AO11 -> 36900000 | AH11: 1 | AI11: =($J$69*AH11)*AO11 -> 6162000 | AJ11: =J70 -> 14176800 | AK11: =C83 -> 2835360 | AL11: =(((D64-F64)/$I$55)*$J$67)*AO11 -> 0 | AM11: =SUM(AF11:AG11,AI11:AL11)/$AM$14 -> 0.68373732 | AN11: =SUM(AF11:AG11,AI11:AL11)/$AN$14 -> 0.53567315 | AO11: =D132 -> 1 | AP11: =(AN11*SUM($C$82,$C$84:$C$85,$C$92:$C$93))+((H150+X150)/($H$153+$X$153))*$C$95+((SUM($D$90:$D$91)*G64*AO11)+(D89*G64/2*AO11)) -> 4250586.9 | AQ11: =(((($C$94)*AM11))+C87)+((C86+C97)*70%) -> 10291049 | AR11: =AM11*$C$115 -> 4883185.8 | AS11: =AN11*$C$103 -> 11953363 | AT11: =SUM(I150,Y150) -> 6405750 | AU11: =SUM(AF11:AG11,AI11:AL11,AP11:AT11) -> 1.4699209e+08 | AV11: =IFERROR((AU11-AT11)/E132, "0") -> 39413.049 | AW11: =(AU11-AT11)/($C$19) -> 0.63688644 | AX11: =SUM(J132,H150,O132,X150) -> 2.348775e+08 | AY11: =IFERROR(AZ11/E132, "0.00") -> 24638.465 | AZ11: =AX11-AU11 -> 87885405 | BA11: =IFERROR(BD11/AW11, "0.00") -> 0.98154817 | BB11: =IFERROR(AZ11/AX11, "0.00%") -> 0.3741755 | BC11: =AZ11/$C$21 -> 1.0229555 | BD11: =IFERROR(AZ11/(AU11-AT11), "0.00%") -> 0.62513472 | BE11: فندقي | BH11: إجمالي التكاليف المباشرة (Total Direct Costs) | BI11: =-SUM(C190:C194,C198:C202,C209) -> 1.8807665e+08 | BJ11: =BI11/($C$19+$C$20) -> 0.82754949 | BL11: غالبًا تمثل 70% – 85% من إجمالي التكاليف | BN11: فندقي (Hotel) | BO11: =IFERROR((AU11-AT11) / (C150 * D150 * G150 * (1 - $I$154) * BP11), 0) -> 0 | BQ11: فندقي (Hotel) | BR11: =IFERROR((AU11-AT11) / ((R150 * S150 * (1 - $Y$154) * 365 * BS11) * (1 + W150)), 0) -> 0 | BV11: الحصة من التطوير | BW11: 0 | BX11: - | BY11: - | BZ11: =H18*BW11 -> 0 | CA11: =BZ11 -> 0 | CB11: -
B12: البند (Item) | C12: القيمة (Value) | G12: رأس المال - (capital) | AE12: صحي | AF12: =((F65/$J$55)*$I$45)*AO12 -> 0 | AG12: =J65*AO12 -> 0 | AI12: =($J$69*AH12)*AO12 -> 0 | AJ12: =((K65/$L$72)*($J$70+$J$71))*AO12 -> 0 | AK12: =((K65/$L$72)*$C$83)*AO12 -> 0 | AL12: =(((D65-F65)/$I$55)*$J$67)*AO12 -> 0 | AM12: =SUM(AF12:AG12,AI12:AL12)/$AM$14 -> 0 | AN12: =SUM(AF12:AG12,AI12:AL12)/$AN$14 -> 0 | AO12: =D133 -> 1 | AP12: =(AN12*SUM($C$82,$C$84:$C$86,$C$92:$C$93,$C$97))+((H151+X151)/($H$153+$X$153))*$C$95+(SUM($D$89:$D$91)*G65*AO12) -> 0 | AQ12: =(($A$88+$C$94)*AM12) -> 0 | AR12: =AM12*$C$115 -> 0 | AS12: =AN12*$C$103 -> 0 | AT12: =SUM(I151,Y151) -> 0 | AU12: =SUM(AF12:AG12,AI12:AL12,AP12:AT12) -> 0 | AV12: =IFERROR((AU12-AT12)/E133, "0") -> 0 | AW12: =(AU12-AT12)/($C$19) -> 0 | AX12: =SUM(J133,H151,O133,X151) -> 0 | AY12: =IFERROR(AZ12/E133, "0.00") -> 0.00 | AZ12: =AX12-AU12 -> 0 | BA12: =IFERROR(BD12/AW12, "0.00") -> 0.00 | BB12: =IFERROR(AZ12/AX12, "0.00%") -> 0.00% | BC12: =AZ12/$C$21 -> 0 | BD12: =IFERROR(AZ12/(AU12-AT12), "0.00%") -> 0.00% | BE12: صحي | BH12: إجمالي التكاليف غير المباشرة (Total Indirect Costs) | BI12: =-SUM(E188:E189,C195:C197,C203:C208,C210:C212) -> 39192718 | BJ12: =BI12/($C$19+$C$20) -> 0.17245051 | BL12: من 15% إلى 25% من إجمالي التكاليف غالبًا | BN12: صحي (health) | BO12: =IFERROR((AU12-AT12) / (C151 * D151 * G151 * (1 - $I$154) * BP12), 0) -> 0 | BQ12: صحي (health) | BR12: =IFERROR((AU12-AT12) / ((R151 * S151 * (1 - $Y$154) * 365 * BS12) * (1 + W151)), 0) -> 0 | BV12: الحصة العينية من المقاولات | BW12: 1 | BX12: =(E99*C191)*BW12 -> 0 | BY12: - | BZ12: =BX12*$BW$7 -> 0 | CA12: =BZ12+BX12 -> 0 | CB12: -
B13: إجمالي الإيرادات (Total Revenue) | C13: =SUM(C180:C184) -> 3.1318259e+08 | G13: المصدر (Source) | H13: SAR | I13: % | AE13: شاليهات | AF13: =((F66/$J$55)*$I$45)*AO13 -> 0 | AG13: =J66*AO13 -> 0 | AI13: =($J$69*AH13)*AO13 -> 0 | AJ13: =((K66/$L$72)*($J$70+$J$71))*AO13 -> 0 | AK13: =((K66/$L$72)*$C$83)*AO13 -> 0 | AL13: =(((D66-F66)/$I$55)*$J$67)*AO13 -> 0 | AM13: =SUM(AF13:AG13,AI13:AL13)/$AM$14 -> 0 | AN13: =SUM(AF13:AG13,AI13:AL13)/$AN$14 -> 0 | AO13: =D134 -> 1 | AP13: =(AN13*SUM($C$82,$C$84:$C$86,$C$92:$C$93,$C$97))+((H152+X152)/($H$153+$X$153))*$C$95+(SUM($D$89:$D$91)*G66*AO13) -> 0 | AQ13: =(($A$88+$C$94)*AM13) -> 0 | AR13: =AM13*$C$115 -> 0 | AS13: =AN13*$C$103 -> 0 | AT13: =SUM(I152,Y152) -> 0 | AU13: =SUM(AF13:AG13,AI13:AL13,AP13:AT13) -> 0 | AV13: =IFERROR((AU13-AT13)/E134, "0") -> 0 | AW13: =(AU13-AT13)/($C$19) -> 0 | AX13: =SUM(J134,H152,O134,X152) -> 0 | AY13: =IFERROR(AZ13/E134, "0.00") -> 0.00 | AZ13: =AX13-AU13 -> 0 | BA13: =IFERROR(BD13/AW13, "0.00") -> 0.00 | BB13: =IFERROR(AZ13/AX13, "0.00%") -> 0.00% | BC13: =AZ13/$C$21 -> 0 | BD13: =IFERROR(AZ13/(AU13-AT13), "0.00%") -> 0.00% | BE13: شاليهات | BH13: إجمالي التكاليف التشغيلية (Total Operating Costs) | BI13: =C20 -> 6529315.6 | BJ13: =BI13/SUM(C19:C20) -> 0.028729413 | BL13: - | BN13: شاليهات (Chalets) | BO13: =IFERROR((AU13-AT13) / (C152 * D152 * G152 * (1 - $I$154) * BP13), 0) -> 0 | BQ13: شاليهات (Chalets) | BR13: =IFERROR((AU13-AT13) / ((R152 * S152 * (1 - $Y$154) * 365 * BS13) * (1 + W152)), 0) -> 0 | BV13: الحصة من المقاولات | BW13: 0 | BX13: - | BY13: - | BZ13: =(E100*C192)*BW13 -> 0 | CA13: =BZ13 -> 0 | CB13: -
B14: إجمالي تكلفة الأرض (Total Land Cost) | C14: =I45 -> 91847824 | G14: (Equity) - الملكية | AE14: الإجمالي | AF14: =SUMIF(AF4:AF13, "<>#DIV/0!") -> 91847824 | AG14: =SUMIF(AG4:AG13, "<>#DIV/0!") -> 44700408 | AH14: =SUM(AH4:AH13) -> 1 | AI14: =SUM(AI4:AI13) -> 6162000 | AJ14: =SUMIF(AJ4:AJ13, "<>#DIV/0!") -> 14176800 | AK14: =SUMIF(AK4:AK13, "<>#DIV/0!") -> 2835360 | AL14: =SUM(AL4:AL13) -> 0 | AM14: =SUM(AF14:AG14,AI14:AL14) -> 159722392 | AN14: =SUM(AF4:AG13,AI4:AL13,AF22:AG31,AI22:AL31) -> 2.0387089e+08 | AO14: - | AP14: =SUM(AP4:AQ13) -> 17522844 | AR14: =SUMIF(AR4:AR13, "<>#DIV/0!") -> 7141903.3 | AS14: =SUMIF(AS4:AS13, "<>#DIV/0!") -> 17482390 | AT14: =SUM(AT4:AT13) -> 6529315.6 | AU14: =SUM(AU4:AU13) -> 2.0839884e+08 | AV14: =IFERROR(AU14/E135, "0") -> 21006.267 | AW14: =SUMIF(AW4:AW13, "<>#DIV/0!") -> 0.91451247 | AX14: =SUMIF(AX4:AX13, "<>#DIV/0!") -> 2.6669563e+08 | AY14: =AZ14/E135 -> 5876.2217 | AZ14: =SUMIF(AZ4:AZ13, "<>#DIV/0!") -> 58296785 | BA14: - | BB14: =IFERROR(AZ14/AX14, "0.00%") -> 0.2185892 | BC14: =SUM(BC4:BC13) -> 0.6785543 | BD14: =IFERROR(AZ14/AU14, "0.00%") -> 0.27973661 | BH14: إجمالي قيمة ونسبة تكاليف الأرض من إجمالي تكاليف المشروع (Land Cost as Value and % of Total Project Cost) | BI14: =I45 -> 91847824 | BJ14: =BI14/$C$19 -> 0.41609044 | BL14: من 10% إلى 25% غالبًا | BV14: العمولات 2.5% من المبيعات | BW14: 0.025 | BX14: - | BY14: بيع على الخارطة + بيع مباشر + مخارجة | BZ14: =BW14*(J135+AC135+O135) -> 7233969.4 | CA14: =BZ14 -> 7233969.4 | CB14: -
B15: إجمالي تكلفة البناء (Total Construction Cost) | C15: =J72 -> 78265608 | G15: الاشتراكات النقدية (Cash Subscription) | H15: 34500000 | I15: =H15/$H$30 -> 0.15629244 | AF15: =IF(ABS(SUM(Study!AF14,Study!AF32)-SUM(Study!I45))<=0.00000001,"TRUE",SUM(Study!AF14,Study!AF32)-SUM(Study!I45)) -> 30922095 | AG15: =IF(ABS(SUM(Study!AG14,Study!AG32)-SUM(J57:J67))<=0.00000001,"TRUE",SUM(Study!AG14,Study!AG32)-SUM(J57:J67)) -> TRUE | AH15: =IF(ABS(SUM(Study!AH14)-SUM(1))<=0.00000001,"TRUE",SUM(Study!AH14)-SUM(1)) -> TRUE | AI15: =IF(ABS(SUM(Study!AI14,Study!AI32)-SUM(Study!J69))<=0.00000001,"TRUE",SUM(Study!AI14,Study!AI32)-SUM(Study!J69)) -> TRUE | AJ15: =IF(ABS(SUM(Study!AJ14,Study!AJ32)-SUM(J70:J71))<=0.00000001,"TRUE",SUM(Study!AJ14,Study!AJ32)-SUM(J70:J71)) -> TRUE | AK15: =IF(ABS(SUM(Study!AK14,Study!AK32)-SUM(Study!C83))<=0.00000001,"TRUE",SUM(Study!AK14,Study!AK32)-SUM(Study!C83)) -> TRUE | AL15: =IF(ABS(SUM(Study!AL14,Study!AL32)-SUM(Study!J67))<=0.00000001,"TRUE",SUM(Study!AL14,Study!AL32)-SUM(Study!J67)) -> TRUE | AM15: =IF(ABS(SUM(Study!AM4:AM13)-SUM(1))<=0.00000001,"TRUE",SUM(Study!AM4:AM13)-SUM(1)) -> TRUE | AN15: =IF(ABS(SUM(Study!AN4:AN13,Study!AN22:AN31)-SUM(1))<=0.00000001,"TRUE",SUM(Study!AN4:AN13,Study!AN22:AN31)-SUM(1)) -> TRUE | AO15: =IF(ABS(SUM(Study!AO4:AO13,Study!AO22:AO31)-SUM(10))<=0.00000001,"TRUE",SUM(Study!AO4:AO13,Study!AO22:AO31)-SUM(10)) -> TRUE | AP15: =IF(ABS(SUM(Study!AP4:AQ13,Study!AP22:AQ31)-SUM(Study!C82,Study!C84:C97))<=0.1,"TRUE",SUM(Study!AP4:AQ13,Study!AP22:AQ31)-SUM(Study!C82,Study!C84:C97)) -> 1437638.7 | AR15: =IF(ABS(SUM(Study!AR14)-SUM(Study!C115))<=0.00000001,"TRUE",SUM(Study!AR14)-SUM(Study!C115)) -> TRUE | AS15: =IF(ABS(SUM(Study!AS14,Study!AS32)-SUM(Study!C103))<=1,"TRUE",SUM(Study!AS14,Study!AS32)-SUM(Study!C103)) -> TRUE | AT15: =IF(ABS(SUM(Study!AT14)-SUM(Study!C20))<=0.01,"TRUE",SUM(Study!AT14)-SUM(Study!C20)) -> TRUE | AU15: =IF(ABS(SUM(Study!AU14,Study!AU32)-SUM(Study!C19:C20))<=0.25,"TRUE",SUM(Study!AU14,Study!AU32)-SUM(Study!C19:C20)) -> -18870521 | AV15: =AV14=AV14 -> TRUE | AW15: =IF(ABS(SUM(Study!AW14,Study!AW32)-SUM(1))<=0.01,"TRUE",SUM(Study!AW14,Study!AW32)-SUM(1)) -> -0.085487528 | AX15: =IF(ABS(SUM(Study!AX14,Study!AX32)-SUM(Study!C13))<=0.01,"TRUE",SUM(Study!AX14,Study!AX32)-SUM(Study!C13)) -> TRUE | AY15: =AY14=AY14 -> TRUE | AZ15: =IF(ABS(SUM(Study!AZ14,Study!AZ32)-SUM(Study!C21))<=0.2,"TRUE",SUM(Study!AZ14,Study!AZ32)-SUM(Study!C21)) -> -27616435 | BA15: =BA14=BA14 -> TRUE | BB15: =BB14=BB14 -> TRUE | BC15: =IF(ABS(SUM(Study!BC14,Study!BC32)-SUM(1))<=0.01,"TRUE",SUM(Study!BC14,Study!BC32)-SUM(1)) -> -0.3214457 | BD15: =BD14=BD14 -> TRUE | BH15: إجمالي قيمة ونسبة تكاليف البناء من إجمالي تكاليف المشروع (Construction Cost as Value and % of Total Project Cost) | BI15: =J72 -> 78265608 | BJ15: =BI15/$C$19 -> 0.35456007 | BL15: المتوسط غالبًا بين 45% إلى 65% | BV15: نسبة رصف من المستثمرين | BW15: 0 | BX15: =BW15*H17 -> 0 | BY15: - | BZ15: =BX15*$BW$7 -> 0 | CA15: =BZ15+BX15 -> 0 | CB15: -
B16: إجمالي التكاليف الأخرى (Total Other cost) | C16: =C98 -> 21170058 | G16: الاشتراك من مدير الصندوق (fund manager's Subscription) | I16: =H16/$H$30 -> 0 | BH16: إجمالي قيمة ونسبة التكاليف الأخرى من إجمالي تكاليف المشروع (Other Costs as % of Total Project Cost) | BI16: =C98 -> 21170058 | BJ16: =BI16/$C$19 -> 0.095904925 | BL16: غالبًا بين 10% – 20% | BV16: الحصة من فارق قيمة الأرض | BW16: 1 | BX16: =K19*BW16 -> 0 | BY16: - | BZ16: =BX16*$BW$7 -> 0 | CA16: =BZ16+BX16 -> 0 | CB16: -
B17: إجمالي رسوم الصندوق (Total Fund Fees) | C17: =C103 -> 22314657 | G17: الأشتراك النقدي من المطور (Cash Subscription from Developer) | H17: 11100000 | I17: =H17/$H$30 -> 0.050285392 | J17: =H30*5% -> 11037003 | BH17: إجمالي قيمة ونسبة تكاليف فوائد التمويل من إجمالي تكاليف المشروع (Financing Interest as Value and % of Total Project Cost) | BI17: =C115 -> 7141903.3 | BJ17: =BI17/$C$19 -> 0.032354361 | BL17: من 5% – 12% حسب مدة التمويل والفوائد | BV17: اشتراكات نقدية / مصاريف سابقة | BW17: 0 | BX17: =H15*BW17 -> 0 | BY17: - | BZ17: =BX17*$BW$7 -> 0 | CA17: =BZ17+BX17 -> 0 | CB17: -
B18: فوائد التمويل (Interest) | C18: =C115 -> 7141903.3 | G18: الأشتراك العيني من المطور (In-Kind Subscription from Developer) | H18: =J18*((D100+E100)*-E192) -> 0 | I18: =H18/$H$30 -> 0 | J18: 0 | BH18: إجمالي قيمة ونسبة تكاليف الصندوق من إجمالي تكاليف المشروع (Fund Management Cost as Value and % of Total Project Cost) | BI18: =C103 -> 22314657 | BJ18: =BI18/$C$19 -> 0.10109021 | BL18: تتراوح من 1% – 7% حسب شروط الصندوق
B19: إجمالي التكاليف الرأسمالية للمشروع (Total Capital Expenditures) | C19: =SUM(C14:C18) -> 2.2074005e+08 | G19: الإشتراك العيني من مالك الأرض (In-Kind Subscription from Landowner) | H19: =(J19*E45)+K19 -> 62809600 | I19: =H19/$H$30 -> 0.28454102 | J19: 0.7 | BH19: مؤشرات الإيرادات والربحية | Revenue & Profitability Indicators | BL19: - | BV19: إجمالي رصف | BX19: =SUM(BX10:BX17) -> 0 | BY19: - | BZ19: =SUM(BZ10:BZ17) -> 7233969.4 | CA19: =SUM(CA10:CA17) -> 7233969.4 | CB19: -
B20: إجمالي التكاليف التشغيلية (Total Operating Expenses) | C20: =-SUM(E209) -> 6529315.6 | G20: إجمالي الملكية (Total Equity) | H20: =SUM(H15:H19) -> 108409600 | I20: =H20/$H$30 -> 0.49111885 | AE20: توزيع تكاليف مكونات البيع على الخارطة | BH20: متوسط سعر بيع الأمتار البيعية (Average Selling Price per Sellable m²) | BI20: =SUM(C180,C183:C184)/J55 -> 29166.897 | BL20: - | BV20: مستثمرين رصف | BX20: 0 | BY20: 0.7 | BZ20: =BX20*BW7*BY20 -> 0 | CA20: =BZ20+BX20 -> 0 | CB20: -
B21: صافي الدخل (Net Income) | C21: =C13-(C19+C20) -> 85913221 | G21: التمويل البنكي - (Bank Financing) | AE21: المكون | AF21: توزيع تكاليف الأرض | AG21: تكاليف البناء | AH21: نسبة تزيع تكاليف اللاند سكيب | AI21: توزيع تكاليف اللاندسكيب | AJ21: توزيع تكاليف البوديم و القبو | AK21: توزيع تكاليف الحفر والمسح و الاختبار | AL21: توزيع تكاليف المساحات الحركية والخدمية | AM21: نسب التكاليف السابقة من التكاليف الموجودة بالجدول | AN21: نسب التكاليف السابقة من التكاليف الكلية | AO21: نسبة بيع المكون على الخارطة من الإجمالي | AP21: توزيع التكاليف الأخرى | AQ21: توزيع تكاليف أخرى إضافية | AR21: توزيع تكاليف التمويل | AS21: توزيع تكاليف الصندوق | AT21: تكاليف بيع الخارطة | AU21: إجمالي تكاليف كل مكون | AV21: توزيع التكلفة على الأمتار البيعية | AW21: نسبة تكاليف كل مكون من إجمالي المشروع | AX21: إجمالي إيراد كل مكون | AY21: صافي العائد لكل م² بيعي | AZ21: صافي دخل كل مكون | BA21: العائد النسبي للمكون | BB21: هامش الربح من إجمالي الإرادات | BC21: نسبة صافي دخل كل مكون من إجمالي صافي دخل المشروع | BD21: نسبة صافي دخل كل مكون | BH21: متوسط قيمة و نسبة الربح لكل م² (Average Profit Value and % per m²) | BI21: =BI20-BI7 -> 6916.6566 | BJ21: =BI21/BI7 -> 0.31085761 | BL21: - | BV21: الاجمالي | BX21: =SUM(BX19:BX20) -> 0 | BY21: - | BZ21: =SUM(BZ19:BZ20) -> 7233969.4 | CA21: =BZ21+BX21 -> 7233969.4 | CB21: -
B22: أهــــــــــــــــــم مؤشــــــــرات الدراســــــــــة | G22: إجمالي التمويل البنكي (Total Bank Financing) | H22: =E185 -> 54352006 | I22: =H22/$H$30 -> 0.2462263 | AE22: سكني (بيع على الخارطة) | AF22: =((F57/$J$55)*$I$45)*AO22 -> 0 | AG22: =J57*AO22 -> 0 | AH22: 0.15 | AI22: =($J$69*AH22)*AO22 -> 0 | AJ22: =((K57/$L$72)*($J$70+$J$71))*AO22 -> 0 | AK22: =((K57/$L$72)*$C$83)*AO22 -> 0 | AL22: =(((D57-F57)/$I$55)*$J$67)*AO22 -> 0 | AN22: =SUM(AF22:AG22,AI22:AL22)/$AN$32 -> 0 | AO22: =S125 -> 0 | AP22: =(AN22*SUM($C$82,$C$84:$C$86,$C$92:$C$93,$C$97))+(SUM($D$89:$D$91)*G57*AO22) -> 0 | AR22: لا يــــنــطــبــق | AS22: =AN22*$C$103 -> 0 | AT22: لا يــــنــطــبــق | AV22: =IFERROR((AU22)/T125, "0") -> 0 | AX22: =AC125 -> 0 | AY22: =IFERROR(AZ22/T125, "0.00") -> 0.00 | BA22: =IFERROR(BD22/AW22, "0.00") -> 0.00 | BB22: =IFERROR(AZ22/AX22, "0.00%") -> 0.00% | BD22: =IFERROR(AZ22/(AU22), "0.00%") -> 0.00% | BE22: سكني | BH22: العائد على المتر البيعي (شامل عوائد الإيجار) (Total Return per Saleable m² including Rental Income) | BI22: =C21/F72 -> 8659.9138 | BJ22: =BI22/BI7 -> 0.3892054 | BL22: -
B23: مدة المشروع المتوقعة - سنوي (Estimated Project Duration - Years) | C23: =B118 -> 5 | AE23: فلل (بيع على الخارطة) | AF23: =((F58/$J$55)*$I$45)*AO23 -> 30922095 | AG23: =J58*AO23 -> 13226400 | AH23: 0 | AI23: =($J$69*AH23)*AO23 -> 0 | AJ23: =((K58/$L$72)*($J$70+$J$71))*AO23 -> 0 | AK23: =((K58/$L$72)*$C$83)*AO23 -> 0 | AL23: =(((D58-F58)/$I$55)*$J$67)*AO23 -> 0 | AN23: =SUM(AF23:AL23)/$AN$32 -> 0.21655125 | AO23: =S126 -> 1 | AP23: =(AN23*SUM($C$82,$C$84:$C$86,$C$92:$C$93,$C$97))+(SUM($D$89:$D$91)*G58*AO23) -> 2249493 | AR23: لا يــــنــطــبــق | AS23: =AN23*$C$103 -> 4832266.8 | AT23: لا يــــنــطــبــق | AV23: =IFERROR((AU23-AT23)/T126, "0") -> 0 | AX23: =AC126 -> 46486957 | AY23: =IFERROR(AZ23/T126, "0.00") -> 0 | BA23: =IFERROR(BD23/AW23, "0.00") -> 0.00 | BB23: =IFERROR(AZ23/AX23, "0.00%") -> 0 | BD23: =IFERROR(AZ23/(AU23), "0.00%") -> 0.00% | BE23: فلل | BH23: نسبة صافي الربح من الإيرادات (Net Profit as % of Revenues) | BI23: =C21/C13 -> 0.27432311 | BL23: مثالي إن كان بين 20% إلى 35% (أقل من 15% يُعد ضعيف، وأكثر من 40% نادر وممتاز)
B24: معدل العائد الداخلي (IRR) | C24: =C219 -> 0.13308131 | G24: تمويل تشغيلي خارج هيكل رأس المال - (Off-Capital-Structure Operational Financing) | AE24: تاون هاوس (بيع على الخارطة) | AF24: =((F59/$J$55)*$I$45)*AO24 -> 0 | AG24: =J59*AO24 -> 0 | AH24: 0 | AI24: =($J$69*AH24)*AO24 -> 0 | AJ24: =((K59/$L$72)*($J$70+$J$71))*AO24 -> 0 | AK24: =((K59/$L$72)*$C$83)*AO24 -> 0 | AL24: =(((D59-F59)/$I$55)*$J$67)*AO24 -> 0 | AN24: =SUM(AF24:AL24)/$AN$32 -> 0 | AO24: =S127 -> 0.00% | AP24: =(AN24*SUM($C$82,$C$84:$C$86,$C$92:$C$93,$C$97))+(SUM($D$89:$D$91)*G59*AO24) -> 0 | AR24: لا يــــنــطــبــق | AS24: =AN24*$C$103 -> 0 | AT24: لا يــــنــطــبــق | AV24: =IFERROR((AU24-AT24)/T127, "0") -> 0 | AX24: =AC127 -> 0 | AY24: =IFERROR(AZ24/T127, "0.00") -> 0.00 | BA24: =IFERROR(BD24/AW24, "0.00") -> 0.00 | BB24: =IFERROR(AZ24/AX24, "0.00%") -> 0.00% | BD24: =IFERROR(AZ24/(AU24), "0.00%") -> 0.00% | BE24: تاون هاوس | BH24: نقطة التعادل - عدد الأمتار البيعية اللازمة لتغطية التكاليف (Sellable Area Required for Cost Recovery) | BI24: =C19/BI20 -> 7568.1706 | BJ24: =BI24/F72 -> 0.76285936 | BL24: -
G25: البيع على الخارطة (Off-Plan Sales) | H25: =K25*J25 -> 46486957 | I25: =H25/$H$30 -> 0.21059593 | J25: =AC135 -> 46486957 | K25: 1 | L25: =-H31/J25 -> 0 | AE25: أدوار (بيع على الخارطة) | AF25: =((F60/$J$55)*$I$45)*AO25 -> 0 | AG25: =J60*AO25 -> 0 | AH25: 0 | AI25: =($J$69*AH25)*AO25 -> 0 | AJ25: =((K60/$L$72)*($J$70+$J$71))*AO25 -> 0 | AK25: =((K60/$L$72)*$C$83)*AO25 -> 0 | AL25: =(((D60-F60)/$I$55)*$J$67)*AO25 -> 0 | AN25: =SUM(AF25:AL25)/$AN$32 -> 0 | AO25: =S128 -> 0.00% | AP25: =(AN25*SUM($C$82,$C$84:$C$86,$C$92:$C$93,$C$97))+(SUM($D$89:$D$91)*G60*AO25) -> 0 | AR25: لا يــــنــطــبــق | AS25: =AN25*$C$103 -> 0 | AT25: لا يــــنــطــبــق | AV25: =IFERROR((AU25-AT25)/T128, "0") -> 0 | AX25: =AC128 -> 0 | AY25: =IFERROR(AZ25/T128, "0.00") -> 0.00 | BA25: =IFERROR(BD25/AW25, "0.00") -> 0.00 | BB25: =IFERROR(AZ25/AX25, "0.00%") -> 0.00% | BD25: =IFERROR(AZ25/(AU25), "0.00%") -> 0.00% | BE25: أدوار | BH25: مؤشرات التمويل والمخاطر | Financing & Risk Indicators | BJ25: 0 | BL25: -
B26: العائد على الإستثمار (ROI) | C26: =C21/C19 -> 0.3892054 | G26: مصادر أخرى (Other Sources) | H26: =K26*J26 -> 11491488 | I26: =H26/$H$30 -> 0.052058917 | J26: =SUM(J135,M153,AC153) -> 17294496 | K26: 0.66445927 | L26: =-H31/J26 -> 0 | AE26: استديوهات (بيع على الخارطة) | AF26: =((F61/$J$55)*$I$45)*AO26 -> 0 | AG26: =J61*AO26 -> 0 | AH26: 0 | AI26: =($J$69*AH26)*AO26 -> 0 | AJ26: =((K61/$L$72)*($J$70+$J$71))*AO26 -> 0 | AK26: =((K61/$L$72)*$C$83)*AO26 -> 0 | AL26: =(((D61-F61)/$I$55)*$J$67)*AO26 -> 0 | AN26: =SUM(AF26:AL26)/$AN$32 -> 0 | AO26: =S129 -> 0.00% | AP26: =(AN26*SUM($C$82,$C$84:$C$86,$C$92:$C$93,$C$97))+(SUM($D$89:$D$91)*G61*AO26) -> 0 | AR26: لا يــــنــطــبــق | AS26: =AN26*$C$103 -> 0 | AT26: لا يــــنــطــبــق | AV26: =IFERROR((AU26-AT26)/T129, "0") -> 0 | AX26: =AC129 -> 0 | AY26: =IFERROR(AZ26/T129, "0.00") -> 0.00 | BA26: =IFERROR(BD26/AW26, "0.00") -> 0.00 | BB26: =IFERROR(AZ26/AX26, "0.00%") -> 0.00% | BD26: =IFERROR(AZ26/(AU26), "0.00%") -> 0.00% | BE26: أستوديوهات | BH26: القيم والنسب الخاصة بالتمويل البنكي (Bank Financing Limits & Conditions) | BI26: =(BJ28+BJ27)-H22 -> 53513192 | BJ26: =H22/(BJ28+BJ27) -> 0.50388825 | BL26: -
G27: إجمالي التمويل التشغيلي (Total Operational Financing) | H27: =SUM(H25:H26) -> 57978444 | I27: =H27/$H$30 -> 0.26265485 | AE27: مكتبي (بيع على الخارطة) | AF27: =((F62/$J$55)*$I$45)*AO27 -> 0 | AG27: =J62*AO27 -> 0 | AH27: 0.35 | AI27: =($J$69*AH27)*AO27 -> 0 | AJ27: =((K62/$L$72)*($J$70+$J$71))*AO27 -> 0 | AK27: =((K62/$L$72)*$C$83)*AO27 -> 0 | AL27: =(((D62-F62)/$I$55)*$J$67)*AO27 -> 0 | AN27: =SUM(AF27:AL27)/$AN$32 -> 1.7167728e-09 | AO27: =S130 -> 0.00% | AP27: =(AN27*SUM($C$82,$C$84:$C$86,$C$92:$C$93,$C$97))+(SUM($D$89:$D$91)*G62*AO27) -> 0.015914983 | AR27: لا يــــنــطــبــق | AS27: =AN27*$C$103 -> 0.038309197 | AT27: لا يــــنــطــبــق | AV27: =IFERROR((AU27-AT27)/T130, "0") -> 0 | AX27: =AC130 -> 0 | AY27: =IFERROR(AZ27/T130, "0.00") -> 0.00 | BA27: =IFERROR(BD27/AW27, "0.00") -> 0.00 | BB27: =IFERROR(AZ27/AX27, "0.00%") -> 0.00% | BD27: =IFERROR(AZ27/(AU27), "0.00%") -> 0.00% | BE27: مكتبي | BI27: 0.6 | BJ27: =(I45*80%)*BI27 -> 44086956 | BL27: -
B28: العائد على الملكية (ROE) | C28: =(C21/H20) -> 0.7924872 | G28: الإجمالي - (Total) | AE28: تجاري (بيع على الخارطة) | AF28: =((F63/$J$55)*$I$45)*AO28 -> 0 | AG28: =J63*AO28 -> 0 | AH28: 0.35 | AI28: =($J$69*AH28)*AO28 -> 0 | AJ28: =((K63/$L$72)*($J$70+$J$71))*AO28 -> 0 | AK28: =((K63/$L$72)*$C$83)*AO28 -> 0 | AL28: =(((D63-F63)/$I$55)*$J$67)*AO28 -> 0 | AN28: =SUM(AF28:AL28)/$AN$32 -> 1.7167728e-09 | AO28: =S131 -> 0.00% | AP28: =(AN28*SUM($C$82,$C$84:$C$86,$C$92:$C$93,$C$97))+(SUM($D$89:$D$91)*G63*AO28) -> 0.015914983 | AR28: لا يــــنــطــبــق | AS28: =AN28*$C$103 -> 0.038309197 | AT28: لا يــــنــطــبــق | AV28: =IFERROR((AU28-AT28)/T131, "0") -> 0 | AX28: =AC131 -> 0 | AY28: =IFERROR(AZ28/T131, "0.00") -> 0.00 | BA28: =IFERROR(BD28/AW28, "0.00") -> 0.00 | BB28: =IFERROR(AZ28/AX28, "0.00%") -> 0.00% | BD28: =IFERROR(AZ28/(AU28), "0.00%") -> 0.00% | BE28: تجاري | BI28: 0.7 | BJ28: =SUM(J72,C82:C86,C89:C91,C92:C92,C97)*BI28 -> 63778242 | BL28: -
G29: إجمالي مصادر التمويل (Total Financing Sources) | H29: =H20+H22+H27 -> 2.2074005e+08 | I29: =IF(ABS(SUM(1)-SUM(Study!I20,Study!I22,Study!I27))<=0.001,"TRUE",SUM(1)-SUM(Study!I20,Study!I22,Study!I27)) -> TRUE | AE29: فندقي (بيع على الخارطة) | AF29: =((F64/$J$55)*$I$45)*AO29 -> 0 | AG29: =J64*AO29 -> 0 | AH29: 0.15 | AI29: =($J$69*AH29)*AO29 -> 0 | AJ29: =((K64/$L$72)*($J$70+$J$71))*AO29 -> 0 | AK29: =((K64/$L$72)*$C$83)*AO29 -> 0 | AL29: =(((D64-F64)/$I$55)*$J$67)*AO29 -> 0 | AN29: =SUM(AF29:AL29)/$AN$32 -> 7.3575979e-10 | AO29: =S132 -> 0 | AP29: =(AN29*SUM($C$82,$C$84:$C$86,$C$92:$C$93,$C$97))+((SUM($D$90:$D$91)*G64*AO29)+(D89*G64/2*AO29)) -> 0.006820707 | AR29: لا يــــنــطــبــق | AS29: =AN29*$C$103 -> 0.016418227 | AT29: لا يــــنــطــبــق | AV29: =IFERROR((AU29-AT29)/T132, "0") -> 0 | AX29: =AC132 -> 0 | AY29: =IFERROR(AZ29/T132, "0.00") -> 0.00 | BA29: =IFERROR(BD29/AW29, "0.00") -> 0.00 | BB29: =IFERROR(AZ29/AX29, "0.00%") -> 0.00% | BD29: =IFERROR(AZ29/(AU29), "0.00%") -> 0.00% | BE29: فندقي | BI29: =BJ29/D115 -> 0.039885606 | BJ29: =BI30/H22 -> 0.13140091 | BL29: -
B30: العائد على الملكية السنوي (ROE Annually) | C30: =C28/C23 -> 0.15849744 | G30: إجمالي التكاليف الرأسمالية للمشروع (Total Capital Expenditures) | H30: =C19 -> 2.2074005e+08 | AE30: صحي (بيع على الخارطة) | AF30: =((F65/$J$55)*$I$45)*AO30 -> 0 | AG30: =J65*AO30 -> 0 | AH30: =AH12 -> 0 | AI30: =($J$69*AH30)*AO30 -> 0 | AJ30: =((K65/$L$72)*($J$70+$J$71))*AO30 -> 0 | AK30: =((K65/$L$72)*$C$83)*AO30 -> 0 | AL30: =(((D65-F65)/$I$55)*$J$67)*AO30 -> 0 | AN30: =SUM(AF30:AL30)/$AN$32 -> 0 | AO30: =S133 -> 0.00% | AP30: =(AN30*SUM($C$82,$C$84:$C$86,$C$92:$C$93,$C$97))+(SUM($D$89:$D$91)*G65*AO30) -> 0 | AR30: لا يــــنــطــبــق | AS30: =AN30*$C$103 -> 0 | AT30: لا يــــنــطــبــق | AV30: =IFERROR((AU30-AT30)/T133, "0") -> 0 | AX30: =AC133 -> 0 | AY30: =IFERROR(AZ30/T133, "0.00") -> 0.00 | BA30: =IFERROR(BD30/AW30, "0.00") -> 0.00 | BB30: =IFERROR(AZ30/AX30, "0.00%") -> 0.00% | BD30: =IFERROR(AZ30/(AU30), "0.00%") -> 0.00% | BE30: صحي | BI30: =C18 -> 7141903.3 | BL30: -
G31: الفرق (Difference) | H31: =H29-H30 -> 0 | AE31: شاليهات (بيع على الخارطة) | AF31: =((F66/$J$55)*$I$45)*AO31 -> 0 | AG31: =J66*AO31 -> 0 | AH31: =AH13 -> 0 | AI31: =($J$69*AH31)*AO31 -> 0 | AJ31: =((K66/$L$72)*($J$70+$J$71))*AO31 -> 0 | AK31: =((K66/$L$72)*$C$83)*AO31 -> 0 | AL31: =(((D66-F66)/$I$55)*$J$67)*AO31 -> 0 | AN31: =SUM(AF31:AL31)/$AN$32 -> 0 | AO31: =S134 -> 0.00% | AP31: =(AN31*SUM($C$82,$C$84:$C$86,$C$92:$C$93,$C$97))+(SUM($D$89:$D$91)*G66*AO31) -> 0 | AR31: لا يــــنــطــبــق | AS31: =AN31*$C$103 -> 0 | AT31: لا يــــنــطــبــق | AV31: =IFERROR((AU31-AT31)/T134, "0") -> 0 | AX31: =AC134 -> 0 | AY31: =IFERROR(AZ31/T134, "0.00") -> 0.00 | BA31: =IFERROR(BD31/AW31, "0.00") -> 0.00 | BB31: =IFERROR(AZ31/AX31, "0.00%") -> 0.00% | BD31: =IFERROR(AZ31/(AU31), "0.00%") -> 0.00% | BE31: شاليهات | BH31: نسبة المخاطرة التمويلية (Loan to Value Ratio - LTV) | BI31: =H22/(SUM(C180:C184)) -> 0.17354734 | BJ31: =1-BI31 -> 0.82645266 | BL31: بين (50%) و (70%) = طبيعي أقل من (50%) = منخفض (اعتماد كبير على تمويل ذاتي) أكثر من (70%) = مرتفع (مخاطرة عالية على البنك)
AE32: الإجمالي | AF32: =SUM(AF22:AF31) -> 30922095 | AG32: =SUM(AG22:AG31) -> 13226400 | AH32: =SUM(AH22:AH31) -> 1 | AI32: =SUM(AI22:AI31) -> 0 | AJ32: =SUM(AJ22:AJ31) -> 0 | AK32: =SUM(AK22:AK31) -> 0 | AL32: =SUM(AL22:AL31) -> 0 | AM32: =SUM(AF32:AG32,AI32:AL32) -> 44148495 | AN32: =SUM(AF4:AG13,AI4:AL13,AF22:AG31,AI22:AL31) -> 2.0387089e+08 | AO32: - | AR32: - | AS32: =SUM(AS22:AS31) -> 4832266.9 | AT32: =SUM(AT22:AT31) -> 0 | AV32: =IFERROR(AU32/T135, "0") -> 0 | AX32: =SUM(AX22:AX31) -> 46486957 | AY32: =AZ32/T135 -> 0 | AZ32: =SUMIF(AZ22:AZ31, "<>#DIV/0!") -> 0 | BA32: - | BB32: =IFERROR(AZ32/AX32, "0.00%") -> 0 | BD32: =IFERROR(AZ32/AU32, "0.00%") -> 0.00% | BH32: مؤشر المخاطر التمويلية (Leverage Risk Indicator) | BI32: =H22/H20 -> 0.50135787 | BL32: يفضل أن يكون ≤ 1.5 (كلما ارتفع زادت المخاطرة)
AF33: =I45-AF14=AF32 -> FALSE | AG33: =SUM(J57:J67)-AG14=AG32 -> TRUE | AH33: =SUM(AH22:AH31)=AH32 -> TRUE | AI33: =ABS((J69 - AI14) - AI32) <= 0.9 -> TRUE | AJ33: =(J70+J71)-AJ14=AJ32 -> TRUE | AK33: =ABS((C83 - AK14) - AK32) <= 0.9 -> TRUE | AL33: =J67-AL14=AL32 -> TRUE | AM33: =SUM(AF22:AG31,AI22:AL31)=AM32 -> TRUE | AN33: =SUM(AI22:AL31,AF22:AG31,AF4:AG13,AI4:AL13)=AN32 -> TRUE | AO33: =SUM(AO4:AO13,AO22:AO31)=1000% -> TRUE | AR33: =AR32=AR32 -> TRUE | AS33: =ABS((C103 - AS14) - AS32) <= 0.9 -> TRUE | AT33: =AT32=AT32 -> TRUE | AV33: =AV32=AV32 -> TRUE | AX33: =AX32=AC135 -> TRUE | AY33: =AY32=AY32 -> TRUE | AZ33: =AZ32=AZ32 -> TRUE | BA33: =BA32=BA32 -> TRUE | BB33: =BB32=BB32 -> TRUE | BD33: =BD32=BD32 -> TRUE | BH33: قيمة ونسبة تمويل مبيعات الخارطة من تكاليف المشروع خلال فترة البيع (Value and % of Off-Plan Sales Financing for Project Costs During Sales Period) | BI33: =AX22 -> 0 | BJ33: =C180/-(SUM(G188:S212)) -> 0.49384503 | BL33: من 30% إلى 60% من التكاليف أثناء البيع يعتبر جيد جداً
BH34: هامش الأمان (Safety Margin) | BI34: =(C13-C19)/C13 -> 0.29517138 | BL34: المستهدف الجيد ≥ 20% (بمعنى أن القيمة السوقية أعلى بـ 20% من التكلفة)
BH35: مؤشرات الأرض والزمن | Land & Time Indicators | BJ35: 0 | BL35: -
BH36: تكلفة متر الأرض شاملة الضريبة والسعي (Land Cost per m² - Including Tax and Commission) | BI36: =I45/C45 -> 11179.141 | BJ36: =D45 -> 10921.13 | BL36: -
BH37: سعر متر الأرض عند البيع (Land Price per m² at Sale) | BI37: =((I45/C19)*C13)/C45 -> 15860.793 | BL37: -
B38: تفاصيل الأرض | Land Details | AE38: إجمالي توزيع التكاليف على جميع المكونات | BH38: قيمة ارتفاع سعر متر الأرض عند البيع (Land Price Appreciation Value) | BI38: =BI37-BI36 -> 4681.6523 | BL38: -
B39: رقم الأرض (Land Number) | C39: المساحة الأرض (Land Area) | D39: التكلفة للمتر (Cost per SQM) | E39: تكلفة الأرض قبل الضرائب (Land Cost Before Taxes) | F39: ضريبة التصرفات العقارية (RETT) | G39: السعي (Commission) | H39: ضريبة السعي (Commission tax) | I39: إجمالي تكلفة الأرض بعد الضرائب (Total Land Cost After Taxes) | K39: معامل البناء (FAR) | L39: إجمالي مسطحات البناء فوق الأرض (Above Grade Gross Building Area) | AE39: المكون | AF39: توزيع تكاليف الأرض | AG39: تكاليف البناء | AH39: نسبة تزيع تكاليف اللاند سكيب | AI39: توزيع تكاليف اللاندسكيب | AJ39: توزيع تكاليف البوديم و القبو | AK39: توزيع تكاليف الحفر والمسح و الاختبار | AL39: توزيع تكاليف المساحات الحركية والخدمية | AM39: نسب التكاليف السابقة من التكاليف الموجودة بالجدول | AN39: نسب التكاليف السابقة من التكاليف الكلية | AO39: نسب المكونات من البيع المباشر أو المخارجة من الإجمالي | AP39: توزيع التكاليف الأخرى | AQ39: توزيع تكاليف أخرى إضافية | AR39: توزيع تكاليف التمويل | AS39: توزيع تكاليف الصندوق | AT39: توزيع التكاليف التشغيلية | AU39: إجمالي تكاليف كل مكون | AV39: توزيع التكلفة على المساحات الصافية القابلة للبيع | AW39: نسبة تكاليف كل مكون من إجمالي المشروع | AX39: إجمالي إيراد كل مكون | AY39: صافي العائد لكل م² بيعي | AZ39: صافي دخل كل مكون | BA39: العائد النسبي للمكون | BB39: هامش الربح من إجمالي الإرادات | BC39: نسبة صافي دخل كل مكون من إجمالي صافي دخل المشروع | BD39: نسبة صافي دخل كل مكون | BH39: نسبة ارتفاع سعر متر الأرض (Land Price Appreciation Rate) | BI39: =BI38/BI36 -> 0.41878461 | BL39: من 10% إلى 40% خلال 3–5 سنوات يعتبر جيد
B40: 1 | C40: 3000 | D40: 16000 | E40: =D40*C40 -> 48000000 | F40: =(E40*$F$46)*$F$47 -> 720000 | G40: =(E40*$G$46)*$G$47 -> 360000 | H40: =(G40*$H$46)*$H$47 -> 54000 | I40: =SUM(E40:H40) -> 49134000 | K40: 2.05 | L40: =K40*C40 -> 6150 | M40: فندقي | AE40: سكني | AF40: =SUM(AF4,AF22) -> 15362564 | AG40: =SUM(AG4,AG22) -> 7800408 | AH40: =AH4 -> 0 | AI40: =SUM(AI4,AI22) -> 0 | AJ40: =SUM(AJ4,AJ22) -> 0 | AK40: =SUM(AK4,AK22) -> 0 | AL40: =SUM(AL4,AL22) -> 0 | AM40: - | AN40: =SUM(AN4,AN22) -> 0.11361589 | AO40: =SUM(AO4,AO22) -> 1 | AP40: =SUM(AP4,AP22) -> 749188.5 | AQ40: =SUM(AQ4,AQ22) -> 887297.5 | AR40: =SUM(AR4,AR22) -> 1035720.2 | AS40: =SUM(AS4,AS22) -> 2535299.6 | AT40: =SUM(AT4,AT22) -> 123565.55 | AU40: =SUM(AU4,AU22) -> 28494043 | AV40: =IFERROR((AU40-AT40)/F57, "0") -> 9413.5425 | AW40: =SUM(AW4,AW22) -> 0.12852438 | AX40: =SUM(AX22,AX4) -> 31818130 | AY40: =IFERROR(AZ40/F57, "0.00") -> 1102.9575 | AZ40: =SUM(AZ22,AZ4) -> 3324086.8 | BA40: =IFERROR(BD40/AW40, "0.00") -> 0.91163333 | BB40: =IFERROR(AZ40/AX40, "0.00%") -> 0.10447147 | BC40: =AZ40/$C$21 -> 0.038691214 | BD40: =IFERROR(AZ40/(AU40-AT40), "0.00%") -> 0.11716711 | BE40: سكني | BH40: كفاءة المساحة البيعية من المساحات المبنية فوق الأرض (Saleable Efficiency Ratio of Above-Ground Built-Up Area) | BI40: =F72/I55 -> 0.63159036 | BL40: المستهدف المثالي ≥ 70% (الممتاز يتجاوز 75–80%)
B41: 2 | C41: 1876 | D41: 8000 | E41: =D41*C41 -> 15008000 | F41: =(E41*$F$46)*$F$47 -> 225120 | G41: =(E41*$G$46)*$G$47 -> 112560 | H41: =(G41*$H$46)*$H$47 -> 16884 | I41: =SUM(E41:H41) -> 15362564 | K41: 1.89 | L41: =K41*C41 -> 3545.64 | M41: شقق | AE41: فلل | AF41: =SUM(AF5,AF23) -> 58273355 | AG41: =SUM(AG5,AG23) -> 13226400 | AH41: =AH5 -> 0 | AI41: =SUM(AI5,AI23) -> 0 | AJ41: =SUM(AJ5,AJ23) -> 0 | AK41: =SUM(AK5,AK23) -> 0 | AL41: =SUM(AL5,AL23) -> 0 | AM41: - | AN41: =SUM(AN5,AN23) -> 0.35071096 | AO41: =SUM(AO5,AO23) -> 1 | AP41: =SUM(AP5,AP23) -> 2705685.7 | AQ41: =SUM(AQ5,AQ23) -> 888528.77 | AR41: =SUM(AR5,AR23) -> 1222997.3 | AS41: =SUM(AS5,AS23) -> 7825994.9 | AT41: =SUM(AT5,AT23) -> 0 | AU41: =SUM(AU5,AU23) -> 32912707 | AV41: =IFERROR((AU41-AT41)/F58, "0") -> 9854.1038 | AW41: =SUM(AW5,AW23) -> 0.14910165 | AX41: =SUM(AX23,AX5) -> 46486957 | AY41: =IFERROR(AZ41/F58, "0.00") -> -9854.1038 | AZ41: =SUM(AZ23,AZ5) -> -32912707 | BA41: =IFERROR(BD41/AW41, "0.00") -> -6.7068337 | BB41: =IFERROR(AZ41/AX41, "0.00%") -> -0.70799874 | BC41: =AZ41/$C$21 -> -0.38309246 | BD41: =IFERROR(AZ41/(AU41-AT41), "0.00%") -> -1 | BE41: فلل | BH41: مدة البيع - بالسنوات (غير شامل بيع الخارطة) (Sales Duration – Years) | BI41: =COUNTIFS(F183:AC183,">500")/4 -> 0 | BJ41: =BI41/B118 -> 0 | BL41: الطبيعي من 1 إلى 1.5 سنوات
...

Sheet Summary
B1: رصف للاستثمار | RASF Investment
B6: Values shown are SAR except where stated | القيم المعروضة هي بالريال سعودي باستثناء ما هو مذكور | E6: NSA.m² | Net Sellable Area|TDA.m² | Total Development Area|LA.m² | Total Land Area NSA.m² | المساحات الصافية القابلة للبيع |TDA.m² | إجمالي المساحة التطويرية | LA.m² | مساحة الأرض الإجمالية
C10: Summary | ملخص
I12: (Area) - المساحة | J12: (SR/m²) - ر.س/م² | K12: الإجمالي - (Total)
C13: تكلفة شراء الأرض - باستثناء الضرائب والعمولات (Land purchase cost - except taxes & commissions) | I13: =Study!C45 -> 8216 | J13: =Study!D45 -> 10921.13 | K13: =I13*J13 -> 89728000
C14: التكلفة الإجمالية للمشروع (Total project cost) | I14: =Study!G55 -> 31799.64 | J14: =K14/I14 -> 6941.5896 | K14: =Study!C19 -> 2.2074005e+08
C15: إجمالي الإيرادات (Total Revenue) | I15: =Study!J55 -> 9920.794 | J15: =K15/I15 -> 31568.299 | K15: =Study!C13 -> 3.1318259e+08
C17: نمو قيمة الأرض للمتر - Land Value Uplift per SQM | I17: وقت الشراء | J17: وقت البيع | K17: الفارق
I19: =K95/I13 -> 5980.2824 | J19: =((K95/K14)*K15)/I13 -> 8484.7326 | K19: =J19-I19 -> 2504.4502
C21: المؤشرات المالية | Financial Indicators | H21: معدل العائد الداخلي IRR | I21: العائد على الإستثمار ROI | J21: العائد على الملكية ROE | K21: العائد على الملكية سنوياَ ROE Annualy
H24: =Study!C24 -> 0.13308131 | I24: =Study!C26 -> 0.3892054 | J24: =Study!C28 -> 0.7924872 | K24: =Study!C30 -> 0.15849744
C27: التفاصيل الفنية و المالية لجميع للمكونات | Technical and Financial Details For All Components | D27: عدد الوحدات (Number of Units) | E27: مساحة الوحدة (One Unit Area) | H27: إجمالي تكاليف كل مكون (Total cost per component) | I27: صافي العائد لكل م² بيعي (Net return per NSA.m²) | J27: صافي دخل كل مكون (Net Income per Component) | K27: نسبة عائد كل مكون (Return % per Component)
C29: سكني (Apartments) | D29: =Study!G57 -> 12 | E29: =Study!H57 -> 251.1495 | H29: =Study!AU40 -> 28494043 | I29: =Study!AY4 -> 1102.9575 | J29: =Study!AZ4 -> 3324086.8 | K29: =Study!BD4 -> 0.11716711
C30: فلل (Villas) | D30: =Study!G58 -> 11 | E30: =Study!H58 -> 303.63636 | H30: =Study!AU41 -> 32912707 | I30: =Study!AY5 -> -9854.1038 | J30: =Study!AZ5 -> -32912707 | K30: =Study!BD5 -> -1
C31: تاون هاوس (Townhouse) | D31: =Study!G59 -> 0 | E31: =Study!H59 -> 0.00 | H31: =Study!AU42 -> 0 | I31: =Study!AY6 -> 0.00 | J31: =Study!AZ6 -> 0 | K31: =Study!BD6 -> 0.00%
C32: أدوار (Floors) | D32: =Study!G60 -> 0 | E32: =Study!H60 -> 0.00 | H32: =Study!AU43 -> 0 | I32: =Study!AY7 -> 0.00 | J32: =Study!AZ7 -> 0 | K32: =Study!BD7 -> 0.00%
C33: أستوديوهات (Studios) | D33: =Study!G61 -> 0 | E33: =Study!H61 -> 0.00 | H33: =Study!AU44 -> 0 | I33: =Study!AY8 -> 0.00 | J33: =Study!AZ8 -> 0 | K33: =Study!BD8 -> 0.00%
C34: مكتبي (Office) | D34: =Study!G62 -> 0 | E34: =Study!H62 -> 0.00 | H34: =Study!AU45 -> 0 | I34: =Study!AY9 -> 0.00 | J34: =Study!AZ9 -> 0 | K34: =Study!BD9 -> 0.00%
C35: تجاري (Retail) | D35: =Study!G63 -> 0 | E35: =Study!H63 -> 0.00 | H35: =Study!AU46 -> 0 | I35: =Study!AY10 -> 0.00 | J35: =Study!AZ10 -> 0 | K35: =Study!BD10 -> 0.00%
C36: فندقي (Hotel) | D36: =Study!G64 -> 100 | E36: =Study!H64 -> 35.67 | H36: =Study!AU47 -> 1.4699209e+08 | I36: =Study!AY11 -> 24638.465 | J36: =Study!AZ11 -> 87885405 | K36: =Study!BD11 -> 0.62513472
C37: صحي (health) | D37: =Study!G65 -> 0 | E37: =Study!H65 -> 0.00 | H37: =Study!AU48 -> 0 | I37: =Study!AY12 -> 0.00 | J37: =Study!AZ12 -> 0 | K37: =Study!BD12 -> 0.00%
C38: شاليهات (Chalets) | D38: =Study!G66 -> 0 | E38: =Study!H66 -> 0.00 | H38: =Study!AU49 -> 0 | I38: =Study!AY13 -> 0.00 | J38: =Study!AZ13 -> 0 | K38: =Study!BD13 -> 0.00%
E40: 1 | F40: 2 | G40: 3 | H40: 4 | I40: 5 | J40: 6 | K40: =Study!B118 -> 5
C42: رخصة البناء و التصميم (Design & License) | D42: =Study!C340 -> 46388 | E42: =IF(ABS(SUM(OFFSET(Study!$F$196,0,(COLUMN()-COLUMN($E$42))*4,2,4)))<0.01,"",SUM(OFFSET(Study!$F$196,0,(COLUMN()-COLUMN($E$42))*4,2,4))) -> -2608853.6 | F42: =IF(ABS(SUM(OFFSET(Study!$F$196,0,(COLUMN()-COLUMN($E$42))*4,2,4)))<0.01,"",SUM(OFFSET(Study!$F$196,0,(COLUMN()-COLUMN($E$42))*4,2,4))) -> -1367257.4 | G42: =IF(ABS(SUM(OFFSET(Study!$F$196,0,(COLUMN()-COLUMN($E$42))*4,2,4)))<0.01,"",SUM(OFFSET(Study!$F$196,0,(COLUMN()-COLUMN($E$42))*4,2,4))) | H42: =IF(ABS(SUM(OFFSET(Study!$F$196,0,(COLUMN()-COLUMN($E$42))*4,2,4)))<0.01,"",SUM(OFFSET(Study!$F$196,0,(COLUMN()-COLUMN($E$42))*4,2,4))) | I42: =IF(ABS(SUM(OFFSET(Study!$F$196,0,(COLUMN()-COLUMN($E$42))*4,2,4)))<0.01,"",SUM(OFFSET(Study!$F$196,0,(COLUMN()-COLUMN($E$42))*4,2,4))) | J42: =IF(ABS(SUM(OFFSET(Study!$F$196,0,(COLUMN()-COLUMN($E$42))*4,2,4)))<0.01,"",SUM(OFFSET(Study!$F$196,0,(COLUMN()-COLUMN($E$42))*4,2,4))) | K42: =Study!H340 -> 46934
C43: -------------------------------------------
C44: فوائد التمويل (Interest) | D44: =Study!C341 -> 47027 | E44: =IF(ABS(SUM(OFFSET(Study!$F$188,0,(COLUMN()-COLUMN($E$44))*4,2,4)))<0.0001,"",SUM(OFFSET(Study!$F$188,0,(COLUMN()-COLUMN($E$44))*4,2,4))) -> -271760.03 | F44: =IF(ABS(SUM(OFFSET(Study!$F$188,0,(COLUMN()-COLUMN($E$44))*4,2,4)))<0.0001,"",SUM(OFFSET(Study!$F$188,0,(COLUMN()-COLUMN($E$44))*4,2,4))) -> -46574.109 | G44: =IF(ABS(SUM(OFFSET(Study!$F$188,0,(COLUMN()-COLUMN($E$44))*4,2,4)))<0.0001,"",SUM(OFFSET(Study!$F$188,0,(COLUMN()-COLUMN($E$44))*4,2,4))) -> -551296.44 | H44: =IF(ABS(SUM(OFFSET(Study!$F$188,0,(COLUMN()-COLUMN($E$44))*4,2,4)))<0.0001,"",SUM(OFFSET(Study!$F$188,0,(COLUMN()-COLUMN($E$44))*4,2,4))) -> -2381771.4 | I44: =IF(ABS(SUM(OFFSET(Study!$F$188,0,(COLUMN()-COLUMN($E$44))*4,2,4)))<0.0001,"",SUM(OFFSET(Study!$F$188,0,(COLUMN()-COLUMN($E$44))*4,2,4))) -> -3890501.3 | J44: =IF(ABS(SUM(OFFSET(Study!$F$188,0,(COLUMN()-COLUMN($E$44))*4,2,4)))<0.0001,"",SUM(OFFSET(Study!$F$188,0,(COLUMN()-COLUMN($E$44))*4,2,4))) | K44: =Study!H341 -> 48213
C45: -------------------------------------------
C46: تكاليف البناء (Construction Costs) | D46: =Study!C342 -> 46844 | E46: =IF(ABS(SUM(OFFSET(Study!$F$192,0,(COLUMN()-COLUMN($E$46))*4,1,4)))<0.0001,"",SUM(OFFSET(Study!$F$192,0,(COLUMN()-COLUMN($E$46))*4,1,4))) | F46: =IF(ABS(SUM(OFFSET(Study!$F$192,0,(COLUMN()-COLUMN($E$46))*4,1,4)))<0.0001,"",SUM(OFFSET(Study!$F$192,0,(COLUMN()-COLUMN($E$46))*4,1,4))) -> -16435778 | G46: =IF(ABS(SUM(OFFSET(Study!$F$192,0,(COLUMN()-COLUMN($E$46))*4,1,4)))<0.0001,"",SUM(OFFSET(Study!$F$192,0,(COLUMN()-COLUMN($E$46))*4,1,4))) -> -39915460 | H46: =IF(ABS(SUM(OFFSET(Study!$F$192,0,(COLUMN()-COLUMN($E$46))*4,1,4)))<0.0001,"",SUM(OFFSET(Study!$F$192,0,(COLUMN()-COLUMN($E$46))*4,1,4))) -> -21914370 | I46: =IF(ABS(SUM(OFFSET(Study!$F$192,0,(COLUMN()-COLUMN($E$46))*4,1,4)))<0.0001,"",SUM(OFFSET(Study!$F$192,0,(COLUMN()-COLUMN($E$46))*4,1,4))) | J46: =IF(ABS(SUM(OFFSET(Study!$F$192,0,(COLUMN()-COLUMN($E$46))*4,1,4)))<0.0001,"",SUM(OFFSET(Study!$F$192,0,(COLUMN()-COLUMN($E$46))*4,1,4))) | K46: =Study!H342 -> 47848
C47: -------------------------------------------
C48: الخدمات (Infrastructure services) | D48: =Study!C343 -> 47757 | E48: =IF(ABS(SUM(OFFSET(Study!$F$200,0,(COLUMN()-COLUMN($E$48))*4,3,4)))<0.0001,"",SUM(OFFSET(Study!$F$200,0,(COLUMN()-COLUMN($E$48))*4,3,4))) | F48: =IF(ABS(SUM(OFFSET(Study!$F$200,0,(COLUMN()-COLUMN($E$48))*4,3,4)))<0.0001,"",SUM(OFFSET(Study!$F$200,0,(COLUMN()-COLUMN($E$48))*4,3,4))) | G48: =IF(ABS(SUM(OFFSET(Study!$F$200,0,(COLUMN()-COLUMN($E$48))*4,3,4)))<0.0001,"",SUM(OFFSET(Study!$F$200,0,(COLUMN()-COLUMN($E$48))*4,3,4))) | H48: =IF(ABS(SUM(OFFSET(Study!$F$200,0,(COLUMN()-COLUMN($E$48))*4,3,4)))<0.0001,"",SUM(OFFSET(Study!$F$200,0,(COLUMN()-COLUMN($E$48))*4,3,4))) -> -1914500 | I48: =IF(ABS(SUM(OFFSET(Study!$F$200,0,(COLUMN()-COLUMN($E$48))*4,3,4)))<0.0001,"",SUM(OFFSET(Study!$F$200,0,(COLUMN()-COLUMN($E$48))*4,3,4))) | J48: =IF(ABS(SUM(OFFSET(Study!$F$200,0,(COLUMN()-COLUMN($E$48))*4,3,4)))<0.0001,"",SUM(OFFSET(Study!$F$200,0,(COLUMN()-COLUMN($E$48))*4,3,4))) | K48: =Study!H343 -> 47848
C49: -------------------------------------------
C50: الأثاث (furniture) | D50: =Study!C344 -> 47849 | E50: =IF(ABS(SUM(OFFSET(Study!$F$198,0,(COLUMN()-COLUMN($E$50))*4,2,4)))<0.0001,"",SUM(OFFSET(Study!$F$198,0,(COLUMN()-COLUMN($E$50))*4,2,4))) | F50: =IF(ABS(SUM(OFFSET(Study!$F$198,0,(COLUMN()-COLUMN($E$50))*4,2,4)))<0.0001,"",SUM(OFFSET(Study!$F$198,0,(COLUMN()-COLUMN($E$50))*4,2,4))) | G50: =IF(ABS(SUM(OFFSET(Study!$F$198,0,(COLUMN()-COLUMN($E$50))*4,2,4)))<0.0001,"",SUM(OFFSET(Study!$F$198,0,(COLUMN()-COLUMN($E$50))*4,2,4))) | H50: =IF(ABS(SUM(OFFSET(Study!$F$198,0,(COLUMN()-COLUMN($E$50))*4,2,4)))<0.0001,"",SUM(OFFSET(Study!$F$198,0,(COLUMN()-COLUMN($E$50))*4,2,4))) | I50: =IF(ABS(SUM(OFFSET(Study!$F$198,0,(COLUMN()-COLUMN($E$50))*4,2,4)))<0.0001,"",SUM(OFFSET(Study!$F$198,0,(COLUMN()-COLUMN($E$50))*4,2,4))) -> -6150000 | J50: =IF(ABS(SUM(OFFSET(Study!$F$198,0,(COLUMN()-COLUMN($E$50))*4,2,4)))<0.0001,"",SUM(OFFSET(Study!$F$198,0,(COLUMN()-COLUMN($E$50))*4,2,4))) | K50: =Study!H344 -> 48029
C51: -------------------------------------------
C52: البيع على الخارطة (Off-Plan Sale) | D52: =Study!C345 -> 46753 | E52: =IF(ABS(SUM(OFFSET(Study!$F$180,0,(COLUMN()-COLUMN($E$52))*4,1,4)))<0.0001,"",SUM(OFFSET(Study!$F$180,0,(COLUMN()-COLUMN($E$52))*4,1,4))) | F52: =IF(ABS(SUM(OFFSET(Study!$F$180,0,(COLUMN()-COLUMN($E$52))*4,1,4)))<0.0001,"",SUM(OFFSET(Study!$F$180,0,(COLUMN()-COLUMN($E$52))*4,1,4))) -> 14273087 | G52: =IF(ABS(SUM(OFFSET(Study!$F$180,0,(COLUMN()-COLUMN($E$52))*4,1,4)))<0.0001,"",SUM(OFFSET(Study!$F$180,0,(COLUMN()-COLUMN($E$52))*4,1,4))) -> 30956330 | H52: =IF(ABS(SUM(OFFSET(Study!$F$180,0,(COLUMN()-COLUMN($E$52))*4,1,4)))<0.0001,"",SUM(OFFSET(Study!$F$180,0,(COLUMN()-COLUMN($E$52))*4,1,4))) -> 1257540.4 | I52: =IF(ABS(SUM(OFFSET(Study!$F$180,0,(COLUMN()-COLUMN($E$52))*4,1,4)))<0.0001,"",SUM(OFFSET(Study!$F$180,0,(COLUMN()-COLUMN($E$52))*4,1,4))) | J52: =IF(ABS(SUM(OFFSET(Study!$F$180,0,(COLUMN()-COLUMN($E$52))*4,1,4)))<0.0001,"",SUM(OFFSET(Study!$F$180,0,(COLUMN()-COLUMN($E$52))*4,1,4))) | K52: =Study!H345 -> 47848
C53: -------------------------------------------
C54: إيرادات التأجير (Rental Revenue) | D54: =Study!C346 -> 47849 | E54: =IF(ABS(SUM(OFFSET(Study!$F$181,0,(COLUMN()-COLUMN($E$54))*4,2,4)))<0.0001,"",SUM(OFFSET(Study!$F$181,0,(COLUMN()-COLUMN($E$54))*4,2,4))) | F54: =IF(ABS(SUM(OFFSET(Study!$F$181,0,(COLUMN()-COLUMN($E$54))*4,2,4)))<0.0001,"",SUM(OFFSET(Study!$F$181,0,(COLUMN()-COLUMN($E$54))*4,2,4))) | G54: =IF(ABS(SUM(OFFSET(Study!$F$181,0,(COLUMN()-COLUMN($E$54))*4,2,4)))<0.0001,"",SUM(OFFSET(Study!$F$181,0,(COLUMN()-COLUMN($E$54))*4,2,4))) | H54: =IF(ABS(SUM(OFFSET(Study!$F$181,0,(COLUMN()-COLUMN($E$54))*4,2,4)))<0.0001,"",SUM(OFFSET(Study!$F$181,0,(COLUMN()-COLUMN($E$54))*4,2,4))) | I54: =IF(ABS(SUM(OFFSET(Study!$F$181,0,(COLUMN()-COLUMN($E$54))*4,2,4)))<0.0001,"",SUM(OFFSET(Study!$F$181,0,(COLUMN()-COLUMN($E$54))*4,2,4))) -> 23823811 | J54: =IF(ABS(SUM(OFFSET(Study!$F$181,0,(COLUMN()-COLUMN($E$54))*4,2,4)))<0.0001,"",SUM(OFFSET(Study!$F$181,0,(COLUMN()-COLUMN($E$54))*4,2,4))) | K54: =Study!H346 -> 48213
C55: -------------------------------------------
C56: البيع المباشر (Direct Sale) | D56: =Study!C347 | E56: =IF(ABS(SUM(OFFSET(Study!$F$183,0,(COLUMN()-COLUMN($E$56))*4,1,4)))<0.0001,"",SUM(OFFSET(Study!$F$183,0,(COLUMN()-COLUMN($E$56))*4,1,4))) | F56: =IF(ABS(SUM(OFFSET(Study!$F$183,0,(COLUMN()-COLUMN($E$56))*4,1,4)))<0.0001,"",SUM(OFFSET(Study!$F$183,0,(COLUMN()-COLUMN($E$56))*4,1,4))) | G56: =IF(ABS(SUM(OFFSET(Study!$F$183,0,(COLUMN()-COLUMN($E$56))*4,1,4)))<0.0001,"",SUM(OFFSET(Study!$F$183,0,(COLUMN()-COLUMN($E$56))*4,1,4))) | H56: =IF(ABS(SUM(OFFSET(Study!$F$183,0,(COLUMN()-COLUMN($E$56))*4,1,4)))<0.0001,"",SUM(OFFSET(Study!$F$183,0,(COLUMN()-COLUMN($E$56))*4,1,4))) | I56: =IF(ABS(SUM(OFFSET(Study!$F$183,0,(COLUMN()-COLUMN($E$56))*4,1,4)))<0.0001,"",SUM(OFFSET(Study!$F$183,0,(COLUMN()-COLUMN($E$56))*4,1,4))) | J56: =IF(ABS(SUM(OFFSET(Study!$F$183,0,(COLUMN()-COLUMN($E$56))*4,1,4)))<0.0001,"",SUM(OFFSET(Study!$F$183,0,(COLUMN()-COLUMN($E$56))*4,1,4))) | K56: =Study!H347
C57: -------------------------------------------
C58: المخارجة (Buyout) | D58: =Study!C348 -> 48122 | E58: =IF(ABS(SUM(OFFSET(Study!$F$184,0,(COLUMN()-COLUMN($E$58))*4,1,4)))<0.0001,"",SUM(OFFSET(Study!$F$184,0,(COLUMN()-COLUMN($E$58))*4,1,4))) | F58: =IF(ABS(SUM(OFFSET(Study!$F$184,0,(COLUMN()-COLUMN($E$58))*4,1,4)))<0.0001,"",SUM(OFFSET(Study!$F$184,0,(COLUMN()-COLUMN($E$58))*4,1,4))) | G58: =IF(ABS(SUM(OFFSET(Study!$F$184,0,(COLUMN()-COLUMN($E$58))*4,1,4)))<0.0001,"",SUM(OFFSET(Study!$F$184,0,(COLUMN()-COLUMN($E$58))*4,1,4))) | H58: =IF(ABS(SUM(OFFSET(Study!$F$184,0,(COLUMN()-COLUMN($E$58))*4,1,4)))<0.0001,"",SUM(OFFSET(Study!$F$184,0,(COLUMN()-COLUMN($E$58))*4,1,4))) | I58: =IF(ABS(SUM(OFFSET(Study!$F$184,0,(COLUMN()-COLUMN($E$58))*4,1,4)))<0.0001,"",SUM(OFFSET(Study!$F$184,0,(COLUMN()-COLUMN($E$58))*4,1,4))) -> 2.4287182e+08 | J58: =IF(ABS(SUM(OFFSET(Study!$F$184,0,(COLUMN()-COLUMN($E$58))*4,1,4)))<0.0001,"",SUM(OFFSET(Study!$F$184,0,(COLUMN()-COLUMN($E$58))*4,1,4))) | K58: =Study!H348 -> 48213
...
